Workbook

Sheet January
B1: 45658 | C1: 45659 | D1: 45660 | E1: 45661 | F1: 45662 | G1: 45663 | H1: 45664 | I1: 45665 | J1: 45666 | K1: 45667 | L1: 45668 | M1: 45669 | N1: 45670 | O1: 45671 | P1: 45672 | Q1: 45673 | R1: 45674 | S1: 45675 | T1: 45676 | U1: 45677 | V1: 45678 | W1: 45679 | X1: 45680 | Y1: 45681 | Z1: 45682 | AA1: 45683 | AB1: 45684 | AC1: 45685 | AD1: 45686 | AE1: 45687 | AF1: 45688
A2: Total Hrs Booked | B2: =B4+B6+B8+B10+B12+B14+B16+B18+B20+B22+B24+B26+B28+B30+B32 -> 0 | C2: =C4+C6+C8+C10+C12+C14+C16+C18+C20+C22+C24+C26+C28+C30+C32 -> 0 | D2: =D4+D6+D8+D10+D12+D14+D16+D18+D20+D22+D24+D26+D28+D30+D32 -> 0 | E2: =E4+E6+E8+E10+E12+E14+E16+E18+E20+E22+E24+E26+E28+E30+E32 -> 0 | F2: =F4+F6+F8+F10+F12+F14+F16+F18+F20+F22+F24+F26+F28+F30+F32 -> 0 | G2: =G4+G6+G8+G10+G12+G14+G16+G18+G20+G22+G24+G26+G28+G30+G32 -> 0 | H2: =H4+H6+H8+H10+H12+H14+H16+H18+H20+H22+H24+H26+H28+H30+H32 -> 0 | I2: =I4+I6+I8+I10+I12+I14+I16+I18+I20+I22+I24+I26+I28+I30+I32 -> 0 | ... AF2: =AF4+AF6+AF8+AF10+AF12+AF14+AF16+AF18+AF20+AF22+AF24+AF26+AF28+AF30+AF32 -> 37.6
A3: Job No# | N3: Kitsets | P3: S-9663 | Q3: S-9893 | R3: S-9460 | U3: Kitsets | V3: S-9806 | W3: S-9966 | X3: 10033 bk | Y3: S-9451 | AC3: 10069 bk | AD3: S-9531 | AE3: Catch up | AF3: Catch up
A4: Time Allowed | N4: 20 | P4: 2.6 | Q4: 5.6 | R4: 2.6 | U4: 20 | V4: 9.2 | W4: 13.8 | X4: 1.2 | Y4: 2.6 | AC4: 3.4 | AD4: 10.4 | AE4: 28.4 | AF4: 28.4
A5: Job No# | N5: Kitset Pck | O5: S-9748 | P5: 9748 bkd | Q5: S-9759 | R5: S-9987 | U5: Kitset Pck | V5: S-9807 | W5: S-9967 | X5: S-10052 | Y5: S-9466 | AC5: Kitsets | AD5: Catch up | AF5: S-9544
A6: Time Allowed | N6: 5 | O6: 3.7 | P6: 1.2 | Q6: 5.2 | R6: 4.9 | U6: 5 | V6: 12.9 | W6: 13.8 | X6: 2.77 | Y6: 2.6 | AC6: 20 | AD6: 11.7 | AF6: 9.2
A7: Job No# | P7: S-9647 | Q7: S-8691 | R7: S-9463 | U7: S-9996 | V7: S-9808 | W7: S-9220 | X7: S-10063 | Y7: S-10072 | AC7: Kitset Pck | AD7: 10069 bk
A8: Time Allowed | P8: 4.2 | Q8: 6.2 | R8: 2.6 | U8: 15.6 | V8: 12.9 | W8: 7.6 | X8: 2.3 | Y8: 6 | AC8: 5 | AD8: 6.3
A9: Job No# | P9: S-9628 | Q9: S-9957 | R9: S-9464 | W9: S-9959 | X9: S-10065 | Y9: S-10082
A10: Time Allowed | P10: 7 | Q10: 3.2 | R10: 2.6 | W10: 3.2 | X10: 2.4 | Y10: 1.3
A11: Job No# | P11: S-9234 | Q11: S-9958 | R11: S-9462 | W11: S-10033 | X11: S-8710 | Y11: S-9591
A12: Time Allowed | P12: 4.3 | Q12: 3 | R12: 2.6 | W12: 1.6 | X12: 18 | Y12: 3.12
A13: Job No# | P13: S-9851 | Q13: S-9974 | R13: S-9472 | X13: S-10082 | Y13: S-10069
A14: Time Allowed | P14: 4 | Q14: 1.7 | R14: 2.6 | X14: 1.7 | Y14: 12.7
A15: Job No# | P15: S-9934 | Q15: S-9819 | R15: S-9471
A16: Time Allowed | P16: 2.6 | Q16: 5.2 | R16: 2.6
A17: Job No# | P17: S-9946 | Q17: S-9982 | R17: S-9473
A18: Time Allowed | P18: 2.8 | Q18: 8.7 | R18: 2.6
A19: Job No# | P19: S-9947 | R19: S-9995
A20: Time Allowed | P20: 5.6 | R20: 15.6
A21: Job No# | P21: S-9459 | R21: S-10073
A22: Time Allowed | P22: 2.6 | R22: 1
A23: Job No# | P23: S-9980
A24: Time Allowed | P24: 2.6
A25: Job No#
A26: Time Allowed
A27: Job No#
A28: Time Allowed
A29: Job No#
A30: Time Allowed
A31: Job No#
A32: Time Allowed
A33: Spare Hours | B33: =40-B4-B6-B8-B10-B12-B14-B16-B18-B20-B22-B24-B26-B28-B30-B32 -> 40 | C33: =40-C4-C6-C8-C10-C12-C14-C16-C18-C20-C22-C24-C26-C28-C30-C32 -> 40 | D33: =40-D4-D6-D8-D10-D12-D14-D16-D18-D20-D22-D24-D26-D28-D30-D32 -> 40 | E33: =40-E4-E6-E8-E10-E12-E14-E16-E18-E20-E22-E24-E26-E28-E30-E32 -> 40 | F33: =40-F4-F6-F8-F10-F12-F14-F16-F18-F20-F22-F24-F26-F28-F30-F32 -> 40 | G33: =40-G4-G6-G8-G10-G12-G14-G16-G18-G20-G22-G24-G26-G28-G30-G32 -> 40 | H33: =40-H4-H6-H8-H10-H12-H14-H16-H18-H20-H22-H24-H26-H28-H30-H32 -> 40 | I33: =40-I4-I6-I8-I10-I12-I14-I16-I18-I20-I22-I24-I26-I28-I30-I32 -> 40 | ... M33: =40-M4-M6-M8-M10-M12-M14-M16-M18-M20-M22-M24-M26-M28-M30-M32 -> 40 | N33: =28.35-N4-N6-N8-N10-N12-N14-N16-N18-N20-N22-N24-N26-N28-N30-N32 -> 3.35 | O33: =28.35-O4-O6-O8-O10-O12-O14-O16-O18-O20-O22-O24-O26-O28-O30-O32 -> 24.65 | P33: =28.35-P4-P6-P8-P10-P12-P14-P16-P18-P20-P22-P24-P26-P28-P30-P32 -> -11.15 | Q33: =28.35-Q4-Q6-Q8-Q10-Q12-Q14-Q16-Q18-Q20-Q22-Q24-Q26-Q28-Q30-Q32 -> -10.45 | R33: =28.35-R4-R6-R8-R10-R12-R14-R16-R18-R20-R22-R24-R26-R28-R30-R32 -> -11.35 | S33: =28.35-S4-S6-S8-S10-S12-S14-S16-S18-S20-S22-S24-S26-S28-S30-S32 -> 28.35 | T33: =28.35-T4-T6-T8-T10-T12-T14-T16-T18-T20-T22-T24-T26-T28-T30-T32 -> 28.35 | U33: =28.35-U4-U6-U8-U10-U12-U14-U16-U18-U20-U22-U24-U26-U28-U30-U32 -> -12.25 | ... AF33: =28.35-AF4-AF6-AF8-AF10-AF12-AF14-AF16-AF18-AF20-AF22-AF24-AF26-AF28-AF30-AF32 -> -9.25
AB35: AKL
AB36: Anniver

Sheet February
B1: 45689 | C1: 45690 | D1: 45691 | E1: 45692 | F1: 45693 | G1: 45694 | H1: 45695 | I1: 45696 | J1: 45697 | K1: 45698 | L1: 45699 | M1: 45700 | N1: 45701 | O1: 45702 | P1: 45703 | Q1: 45704 | R1: 45705 | S1: 45706 | T1: 45707 | U1: 45708 | V1: 45709 | W1: 45710 | X1: 45711 | Y1: 45712 | Z1: 45713 | AA1: 45714 | AB1: 45715 | AC1: 45716
A2: Total Hrs Booked | B2: =B4+B6+B8+B10+B12+B14+B16+B18+B20+B22+B24+B26+B28+B30+B32 -> 0 | C2: =C4+C6+C8+C10+C12+C14+C16+C18+C20+C22+C24+C26+C28+C30+C32 -> 0 | D2: =D4+D6+D8+D10+D12+D14+D16+D18+D20+D22+D24+D26+D28+D30+D32 -> 27 | E2: =E4+E6+E8+E10+E12+E14+E16+E18+E20+E22+E24+E26+E28+E30+E32 -> 26.96 | F2: =F4+F6+F8+F10+F12+F14+F16+F18+F20+F22+F24+F26+F28+F30+F32 -> 26.97 | G2: =G4+G6+G8+G10+G12+G14+G16+G18+G20+G22+G24+G26+G28+G30+G32 -> 0 | H2: =H4+H6+H8+H10+H12+H14+H16+H18+H20+H22+H24+H26+H28+H30+H32 -> 27 | I2: =I4+I6+I8+I10+I12+I14+I16+I18+I20+I22+I24+I26+I28+I30+I32 -> 0 | ... AC2: =AC4+AC6+AC8+AC10+AC12+AC14+AC16+AC18+AC20+AC22+AC24+AC26+AC28+AC30+AC32 -> 39.5
A3: Job No# | D3: Kitsets | E3: S-9664 | F3: S-9816 | H3: S-9882 | K3: Kitsets | L3: S-9812 | M3: S-9665 | N3: 10084 bkd | O3: 9061 bkd | R3: Kitsets | S3: S-10088 | T3: 8470 bkd | U3: S-9885 | Y3: S-10092 | Z3: S-9749 | AA3: S-10184 | AB3: 10215 bkd | AC3: S-9436
A4: Time Allowed | D4: 20 | E4: 5.2 | F4: 8.3 | H4: 5.6 | K4: 20 | L4: 5.5 | M4: 5.2 | N4: 2.5 | O4: 14.8 | R4: 20 | S4: 2.77 | T4: 34.6 | U4: 2.6 | Y4: 13.8 | Z4: 3.2 | AA4: 15 | AB4: 6.9 | AC4: 13
A5: Job No# | D5: Kitset Pck | E5: S-9814 | F5: S-9815 | H5: S-9857 | K5: Kitset Pck | L5: S-9817 | M5: S-9884 | N5: S-9858 | O5: S-9528 | R5: Kitset Pck | S5: S-9438 | T5: S-9050 | U5: S-9997 | V5: S-9939 | Y5: Kitsets | Z5: S-10162 | AA5: 10201 bkd | AB5: S-10216 | AC5: S-10214
A6: Time Allowed | D6: 5 | E6: 5.5 | F6: 2.77 | H6: 21.4 | K6: 5 | L6: 5.5 | M6: 2.6 | N6: 8.32 | O6: 5.2 | R6: 5 | S6: 8.2 | T6: 2.6 | U6: 5.2 | V6: 16.4 | Y6: 20 | Z6: 5.5 | AA6: 9.4 | AB6: 18.4 | AC6: 11.2
A7: Job No# | D7: S-10101 | E7: S-9917 | F7: S-9820 | K7: 9857 bkd | L7: S-9899 | M7: Catch up | N7: S-9061 | O7: S-9898 | R7: S-10283 | S7: 8470 bkd | U7: S-9983 | V7: S-10093 | Y7: Kitset Pck | Z7: S-10187 | AA7: S-10215 | AB7: S-10192 | AC7: S-10217
A8: Time Allowed | D8: 2 | E8: 2.6 | F8: 4.3 | K8: 13 | L8: 5.5 | M8: 9.9 | N8: 21.5 | O8: 3.1 | R8: 2 | S8: 26 | U8: 5.5 | V8: 10.4 | Y8: 5 | Z8: 4.6 | AA8: 15.1 | AB8: 2.6 | AC8: 15.3
A9: Job No# | E9: S-10079 | F9: 10119 bk | L9: 9857 bkd | M9: S-10043 | O9: S-10146 | R9: S-8470 | U9: S-9984 | V9: S-9998 | Z9: S-9518 | AB9: S-9487
A10: Time Allowed | E10: 3.2 | F10: 3.1 | L10: 0.6 | M10: 3.12 | O10: 3.12 | R10: 7.4 | U10: 5.5 | V10: 1.9 | Z10: 6.7 | AB10: 4.8
A11: Job No# | E11: S-9993 | F11: Catch up | M11: S-10190 | N11: S-10136 | O11: S-10145 | U11: S-9985 | Z11: S-10149 | AB11: S-9488
A12: Time Allowed | E12: 2.6 | F12: 8.5 | M12: 2.8 | N12: 2.3 | O12: 2.6 | U12: 5.5 | Z12: 2.8 | AB12: 2.4
A13: Job No# | E13: S-8876 | L13: Catch up | M13: S-9983 | N13: S-10137 | O13: S-10159 | U13: S-10075 | Z13: 9998 bkd | AB13: S-10237
A14: Time Allowed | E14: 3.46 | L14: 17.2 | M14: 5.6 | N14: 3.35 | O14: 2.6 | U14: 6.4 | Z14: 3.3 | AB14: 3.8
A15: Job No# | E15: S-10119 | L15: S-10181 | M15: S-10090 | N15: S-10223 | O15: S-10160 | U15: S-10174 | Z15: S-10201
A16: Time Allowed | E16: 4.4 | L16: 3.7 | M16: 2.4 | N16: 3 | O16: 2.6 | U16: 5.6 | Z16: 6.2
A17: Job No# | M17: S-10110 | O17: S-9934
A18: Time Allowed | M18: 4.6 | O18: 2.6
A19: Job No# | M19: S-10084 | O19: S-10161
A20: Time Allowed | M20: 1.8 | O20: 10.4
A21: Job No#
A22: Time Allowed
A23: Job No#
A24: Time Allowed
A25: Job No#
A26: Time Allowed
A27: Job No#
A28: Time Allowed
A29: Job No#
A30: Time Allowed
A31: Job No#
A32: Time Allowed
A33: Spare Hours | B33: =40-B4-B6-B8-B10-B12-B14-B16-B18-B20-B22-B24-B26-B28-B30-B32 -> 40 | C33: =40-C4-C6-C8-C10-C12-C14-C16-C18-C20-C22-C24-C26-C28-C30-C32 -> 40 | D33: =27-D4-D6-D8-D10-D12-D14-D16-D18-D20-D22-D24-D26-D28-D30-D32 -> 0 | E33: =27-E4-E6-E8-E10-E12-E14-E16-E18-E20-E22-E24-E26-E28-E30-E32 -> 0.04 | F33: =27-F4-F6-F8-F10-F12-F14-F16-F18-F20-F22-F24-F26-F28-F30-F32 -> 0.03 | G33: =27-G4-G6-G8-G10-G12-G14-G16-G18-G20-G22-G24-G26-G28-G30-G32 -> 27 | H33: =27-H4-H6-H8-H10-H12-H14-H16-H18-H20-H22-H24-H26-H28-H30-H32 -> 0 | I33: =40-I4-I6-I8-I10-I12-I14-I16-I18-I20-I22-I24-I26-I28-I30-I32 -> 40 | J33: =40-J4-J6-J8-J10-J12-J14-J16-J18-J20-J22-J24-J26-J28-J30-J32 -> 40 | K33: =38-K4-K6-K8-K10-K12-K14-K16-K18-K20-K22-K24-K26-K28-K30-K32 -> 0 | L33: =38-L4-L6-L8-L10-L12-L14-L16-L18-L20-L22-L24-L26-L28-L30-L32 -> -8.8817842e-16 | M33: =38-M4-M6-M8-M10-M12-M14-M16-M18-M20-M22-M24-M26-M28-M30-M32 -> -0.02 | N33: =38-N4-N6-N8-N10-N12-N14-N16-N18-N20-N22-N24-N26-N28-N30-N32 -> -2.97 | O33: =38-O4-O6-O8-O10-O12-O14-O16-O18-O20-O22-O24-O26-O28-O30-O32 -> -9.02 | P33: =40-P4-P6-P8-P10-P12-P14-P16-P18-P20-P22-P24-P26-P28-P30-P32 -> 40 | Q33: =40-Q4-Q6-Q8-Q10-Q12-Q14-Q16-Q18-Q20-Q22-Q24-Q26-Q28-Q30-Q32 -> 40 | R33: =37-R4-R6-R8-R10-R12-R14-R16-R18-R20-R22-R24-R26-R28-R30-R32 -> 2.6 | S33: =37-S4-S6-S8-S10-S12-S14-S16-S18-S20-S22-S24-S26-S28-S30-S32 -> 0.03 | T33: =37-T4-T6-T8-T10-T12-T14-T16-T18-T20-T22-T24-T26-T28-T30-T32 -> -0.2 | U33: =37-U4-U6-U8-U10-U12-U14-U16-U18-U20-U22-U24-U26-U28-U30-U32 -> 0.7 | V33: =37-V4-V6-V8-V10-V12-V14-V16-V18-V20-V22-V24-V26-V28-V30-V32 -> 8.3 | W33: =28.65-W4-W6-W8-W10-W12-W14-W16-W18-W20-W22-W24-W26-W28-W30-W32 -> 28.65 | X33: =28.65-X4-X6-X8-X10-X12-X14-X16-X18-X20-X22-X24-X26-X28-X30-X32 -> 28.65 | Y33: =39.5-Y4-Y6-Y8-Y10-Y12-Y14-Y16-Y18-Y20-Y22-Y24-Y26-Y28-Y30-Y32 -> 0.7 | Z33: =39.5-Z4-Z6-Z8-Z10-Z12-Z14-Z16-Z18-Z20-Z22-Z24-Z26-Z28-Z30-Z32 -> 7.2 | AA33: =39.5-AA4-AA6-AA8-AA10-AA12-AA14-AA16-AA18-AA20-AA22-AA24-AA26-AA28-AA30-AA32 -> 0 | AB33: =39.5-AB4-AB6-AB8-AB10-AB12-AB14-AB16-AB18-AB20-AB22-AB24-AB26-AB28-AB30-AB32 -> 0.6 | AC33: =39.5-AC4-AC6-AC8-AC10-AC12-AC14-AC16-AC18-AC20-AC22-AC24-AC26-AC28-AC30-AC32 -> 0
G35: Waitangi

Sheet March
B1: 45717 | C1: 45718 | D1: 45719 | E1: 45720 | F1: 45721 | G1: 45722 | H1: 45723 | I1: 45724 | J1: 45725 | K1: 45726 | L1: 45727 | M1: 45728 | N1: 45729 | O1: 45730 | P1: 45731 | Q1: 45732 | R1: 45733 | S1: 45734 | T1: 45735 | U1: 45736 | V1: 45737 | W1: 45738 | X1: 45739 | Y1: 45740 | Z1: 45741 | AA1: 45742 | AB1: 45743 | AC1: 45744 | AD1: 45745 | AE1: 45746 | AF1: 45747
A2: Total Hrs Booked | B2: =B4+B6+B8+B10+B12+B14+B16+B18+B20+B22+B24+B26+B28+B30+B32 -> 0 | C2: =C4+C6+C8+C10+C12+C14+C16+C18+C20+C22+C24+C26+C28+C30+C32 -> 0 | D2: =D4+D6+D8+D10+D12+D14+D16+D18+D20+D22+D24+D26+D28+D30+D32 -> 42.64 | E2: =E4+E6+E8+E10+E12+E14+E16+E18+E20+E22+E24+E26+E28+E30+E32 -> 42.6 | F2: =F4+F6+F8+F10+F12+F14+F16+F18+F20+F22+F24+F26+F28+F30+F32 -> 42.6 | G2: =G4+G6+G8+G10+G12+G14+G16+G18+G20+G22+G24+G26+G28+G30+G32 -> 42.58 | H2: =H4+H6+H8+H10+H12+H14+H16+H18+H20+H22+H24+H26+H28+H30+H32 -> 42.7 | I2: =I4+I6+I8+I10+I12+I14+I16+I18+I20+I22+I24+I26+I28+I30+I32 -> 0 | ... AF2: =AF4+AF6+AF8+AF10+AF12+AF14+AF16+AF18+AF20+AF22+AF24+AF26+AF28+AF30+AF32 -> 37.7
A3: Job No# | D3: Kitsets | E3: S-9311 | F3: S-10117 | G3: 9703 bkd | H3: S-9227 | K3: Kitsets | L3: S-9434 | M3: S-9906 | N3: S-9430 | O3: 9702 kd | R3: Kitsets | S3: S-10318 | T3: S-9994 | U3: S-10175 | V3: S-9527 | Y3: Kitsets | Z3: S-10086 | AA3: S-10173 | AB3: S-10532 | AC3: S-9891 | AF3: Kitsets
A4: Time Allowed | D4: 20 | E4: 2.6 | F4: 11.2 | G4: 20 | H4: 4.1 | K4: 20 | L4: 15.6 | M4: 4.6 | N4: 16.4 | O4: 6.7 | R4: 8 | S4: 9.25 | T4: 5.6 | U4: 5.2 | V4: 5.2 | Y4: 8 | Z4: 8.32 | AA4: 2.6 | AB4: 28.5 | AC4: 2.6 | AF4: 20
A5: Job No# | D5: Kitset Pck | E5: 10217 bkd | F5: S-10153 | G5: S-10222 | H5: S-10249 | K5: Kitset Pck | L5: S-9432 | M5: S-10322 | N5: S-9940 | O5: S-9705 | R5: Kitset Pck | S5: 10422 bkd | T5: S-10303 | U5: 10460 bkd | V5: S-10507 | Y5: Kitset Pck | Z5: S-10529 | AB5: S-10533 | AC5: S-10506 | AF5: Kitset Pck
A6: Time Allowed | D6: 5 | E6: 11.8 | F6: 9.2 | G6: 6.5 | H6: 2.25 | K6: 5 | L6: 10.4 | M6: 2.4 | N6: 4.6 | O6: 10.2 | R6: 5 | S6: 1.8 | T6: 5.2 | U6: 1.9 | Y6: 5 | Z6: 2.4 | AB6: 2.9 | AC6: 2.6 | AF6: 5
A7: Job No# | D7: S-10087 | E7: S-9704 | F7: S-10154 | G7: S-10196 | H7: 10250 bkd | K7: S-10232 | L7: S-10272 | M7: S-10273 | N7: S-9701 | O7: S-10232 | R7: S-9990 | S7: S-10409 | T7: S-10304 | U7: S-10213 | V7: S-9529 | Y7: S-10512 | Z7: S-10459 | AA7: S-10417 | AB7: S-10536 | AC7: S-10553 | AF7: S-10542
A8: Time Allowed | D8: 5.54 | E8: 10.2 | F8: 9.2 | G8: 2.9 | H8: 2.65 | K8: 3.3 | L8: 2.6 | M8: 4.3 | N8: 5 | O8: 10.2 | R8: 11.2 | S8: 4.3 | T8: 5.2 | U8: 3.5 | V8: 2.6 | Y8: 3.64 | Z8: 3.8 | AA8: 6.9 | AB8: 3.9 | AC8: 2.43 | AF8: 2.6
A9: Job No# | D9: 10217 bkd | E9: S-9703 | F9: 9703 bkd | G9: S-9592 | H9: S-10253 | K9: S-7133 | L9: S-10229 | M9: S-9991 | N9: S-9702 | O9: S-9941 | R9: S-10463 | S9: S-10408 | T9: 10441 bkd | U9: S-10461 | V9: S-9530 | Z9: S-10539 | AA9: S-10419 | AB9: S-10552 | AC9: S-10554 | AF9: S-10560
A10: Time Allowed | D10: 12.1 | E10: 18 | F10: 13 | G10: 3.12 | H10: 21.9 | K10: 2.4 | L10: 5.6 | M10: 11.2 | N10: 11.7 | O10: 5.2 | R10: 5.2 | S10: 8.2 | T10: 0.6 | U10: 2.6 | V10: 5.2 | Z10: 3.66 | AA10: 6.6 | AB10: 2.43 | AC10: 12.15 | AF10: 4.9
A11: Job No# | G11: S-9593 | H11: S-10194 | K11: S-7134 | L11: 10232 bkd | M11: S-10325 | O11: S-10363 | R11: S-10368 | S11: S-10424 | T11: S-10444 | U11: S-10475 | AA11: S-10418 | AC11: 9994 bkd | AF11: S-10572
A12: Time Allowed | G12: 3.12 | H12: 2.4 | K12: 2.4 | L12: 2.05 | M12: 2.77 | O12: 6 | R12: 2.6 | S12: 5.2 | T12: 12 | U12: 6.9 | AA12: 7.65 | AC12: 11.8 | AF12: 2.6
A13: Job No# | G13: S-9594 | H13: S-10235 | K13: S-10234 | L13: S-10317 | M13: S-10359 | R13: S-10374 | S13: S-9113 | T13: S-10323 | U13: S-10505 | AA13: S-10472 | AC13: 10533 bkd | AF13: S-10573
A14: Time Allowed | G14: 3.12 | H14: 4.6 | K14: 2.6 | L14: 2.7 | M14: 7.6 | R14: 2.6 | S14: 7 | T14: 7.8 | U14: 3 | AA14: 2.6 | AC14: 2.9 | AF14: 2.6
A15: Job No# | G15: S-9595 | H15: S-10285 | K15: S-10271 | M15: S-10369 | R15: S-10395 | S15: S-10441 | T15: S-10460
A16: Time Allowed | G16: 3.12 | H16: 2 | K16: 2 | M16: 4 | R16: 1.4 | S16: 2 | T16: 1.3
A17: Job No# | G17: S-10250 | H17: S-10244 | R17: S-10422
A18: Time Allowed | G18: 0.7 | H18: 2.8 | R18: 1.7
A19: Job No#
A20: Time Allowed
A21: Job No#
A22: Time Allowed
A23: Job No#
A24: Time Allowed
A25: Job No#
A26: Time Allowed
A27: Job No#
A28: Time Allowed
A29: Job No#
A30: Time Allowed
... A32: Time Allowed
A33: Spare Hours | B33: =40-B4-B6-B8-B10-B12-B14-B16-B18-B20-B22-B24-B26-B28-B30-B32 -> 40 | C33: =40-C4-C6-C8-C10-C12-C14-C16-C18-C20-C22-C24-C26-C28-C30-C32 -> 40 | D33: =42.6-D4-D6-D8-D10-D12-D14-D16-D18-D20-D22-D24-D26-D28-D30-D32 -> -0.04 | E33: =42.6-E4-E6-E8-E10-E12-E14-E16-E18-E20-E22-E24-E26-E28-E30-E32 -> 0 | F33: =42.6-F4-F6-F8-F10-F12-F14-F16-F18-F20-F22-F24-F26-F28-F30-F32 -> 3.5527137e-15 | G33: =42.6-G4-G6-G8-G10-G12-G14-G16-G18-G20-G22-G24-G26-G28-G30-G32 -> 0.02 | H33: =42.6-H4-H6-H8-H10-H12-H14-H16-H18-H20-H22-H24-H26-H28-H30-H32 -> -0.1 | I33: =40.7-I4-I6-I8-I10-I12-I14-I16-I18-I20-I22-I24-I26-I28-I30-I32 -> 40.7 | J33: =40.7-J4-J6-J8-J10-J12-J14-J16-J18-J20-J22-J24-J26-J28-J30-J32 -> 40.7 | K33: =37.7-K4-K6-K8-K10-K12-K14-K16-K18-K20-K22-K24-K26-K28-K30-K32 -> 1.3322676e-15 | L33: =37.7-L4-L6-L8-L10-L12-L14-L16-L18-L20-L22-L24-L26-L28-L30-L32 -> -1.25 | M33: =37.7-M4-M6-M8-M10-M12-M14-M16-M18-M20-M22-M24-M26-M28-M30-M32 -> 0.83 | N33: =37.7-N4-N6-N8-N10-N12-N14-N16-N18-N20-N22-N24-N26-N28-N30-N32 -> 3.5527137e-15 | O33: =37.7-O4-O6-O8-O10-O12-O14-O16-O18-O20-O22-O24-O26-O28-O30-O32 -> -0.6 | P33: =40.7-P4-P6-P8-P10-P12-P14-P16-P18-P20-P22-P24-P26-P28-P30-P32 -> 40.7 | Q33: =40.7-Q4-Q6-Q8-Q10-Q12-Q14-Q16-Q18-Q20-Q22-Q24-Q26-Q28-Q30-Q32 -> 40.7 | R33: =37.7-R4-R6-R8-R10-R12-R14-R16-R18-R20-R22-R24-R26-R28-R30-R32 -> 4.6629367e-15 | S33: =37.7-S4-S6-S8-S10-S12-S14-S16-S18-S20-S22-S24-S26-S28-S30-S32 -> -0.05 | T33: =37.7-T4-T6-T8-T10-T12-T14-T16-T18-T20-T22-T24-T26-T28-T30-T32 -> 1.5543122e-15 | U33: =37.7-U4-U6-U8-U10-U12-U14-U16-U18-U20-U22-U24-U26-U28-U30-U32 -> 14.6 | V33: =37.7-V4-V6-V8-V10-V12-V14-V16-V18-V20-V22-V24-V26-V28-V30-V32 -> 24.7 | W33: =37.7-W4-W6-W8-W10-W12-W14-W16-W18-W20-W22-W24-W26-W28-W30-W32 -> 37.7 | X33: =37.7-X4-X6-X8-X10-X12-X14-X16-X18-X20-X22-X24-X26-X28-X30-X32 -> 37.7 | Y33: =37.7-Y4-Y6-Y8-Y10-Y12-Y14-Y16-Y18-Y20-Y22-Y24-Y26-Y28-Y30-Y32 -> 21.06 | ... AF33: =37.7-AF4-AF6-AF8-AF10-AF12-AF14-AF16-AF18-AF20-AF22-AF24-AF26-AF28-AF30-AF32 -> 2.6645353e-15
R34: Hours set with Christoff Included

Sheet April
B1: 45748 | C1: 45749 | D1: 45750 | E1: 45751 | F1: 45752 | G1: 45753 | H1: 45754 | I1: 45755 | J1: 45756 | K1: 45757 | L1: 45758 | M1: 45759 | N1: 45760 | O1: 45761 | P1: 45762 | Q1: 45763 | R1: 45764 | S1: 45765 | T1: 45766 | U1: 45767 | V1: 45768 | W1: 45769 | X1: 45770 | Y1: 45771 | Z1: 45772 | AA1: 45773 | AB1: 45774 | AC1: 45775 | AD1: 45776 | AE1: 45777
A2: Total Hrs Booked | B2: =B4+B6+B8+B10+B12+B14+B16+B18+B20+B22+B24+B26+B28+B30+B32 -> 32 | C2: =C4+C6+C8+C10+C12+C14+C16+C18+C20+C22+C24+C26+C28+C30+C32 -> 25.4 | D2: =D4+D6+D8+D10+D12+D14+D16+D18+D20+D22+D24+D26+D28+D30+D32 -> 13.2 | E2: =E4+E6+E8+E10+E12+E14+E16+E18+E20+E22+E24+E26+E28+E30+E32 -> 32.8 | F2: =F4+F6+F8+F10+F12+F14+F16+F18+F20+F22+F24+F26+F28+F30+F32 -> 0 | G2: =G4+G6+G8+G10+G12+G14+G16+G18+G20+G22+G24+G26+G28+G30+G32 -> 0 | H2: =H4+H6+H8+H10+H12+H14+H16+H18+H20+H22+H24+H26+H28+H30+H32 -> 11.6 | I2: =I4+I6+I8+I10+I12+I14+I16+I18+I20+I22+I24+I26+I28+I30+I32 -> 32.5 | ... AE2: =AE4+AE6+AE8+AE10+AE12+AE14+AE16+AE18+AE20+AE22+AE24+AE26+AE28+AE30+AE32 -> 6.87
A3: Job No# | B3: Kitsets | C3: S-10581 | D3: S-10172 | E3: S-9730 | H3: Kitsets | I3: S-10220 | J3: S-10595 | K3: S-10276 | O3: Kitsets | P3: 10716 bkd | Q3: S-10717 | R3: S-10647 | W3: Kitsets | X3: 9589 | Y3: S-10773 | AC3: Kitsets | AD3: 10765 Bkd
A4: Time Allowed | B4: 20 | C4: 5.9 | D4: 8.6 | E4: 4.3 | H4: 3 | I4: 3.9 | J4: 4.3 | K4: 2.77 | O4: 19 | P4: 2.6 | Q4: 4.3 | R4: 2.6 | W4: 0 | X4: 3.9 | Y4: 6.65 | AC4: 20 | AD4: 2.2
A5: Job No# | B5: Kitset Pck | C5: S-10564 | D5: S-10523 | E5: S-9992 | H5: Kitset Pck | I5: 10593 bkd | J5: S-10357 | K5: S-10499 | L5: S-10711 | O5: Kitset Pck | W5: Kitset Pck | X5: S-9590 | Y5: S-10761 | AC5: Kitset Pck | AD5: S-10741 | AE5: S-10763
A6: Time Allowed | B6: 5 | C6: 3.5 | D6: 4.6 | E6: 4.3 | H6: 5 | I6: 1.6 | J6: 18.7 | K6: 2.42 | L6: 13.2 | O6: 5 | W6: 5 | X6: 3.9 | Y6: 6.5 | AC6: 5 | AD6: 7 | AE6: 4.1
A7: Job No# | B7: S-9709 | C7: S-10562 | E7: S-9999 | I7: S-10591 | J7: S-10584 | K7: S-9986 | L7: S-10710 | P7: S-10725 | Q7: S-10728 | R7: S-10625 | X7: S-9906 | AC7: S-10765 | AD7: S-10649 | AE7: Q-10884
A8: Time Allowed | B8: 3.6 | C8: 4.1 | E8: 4.3 | I8: 5 | J8: 2.1 | K8: 3.75 | L8: 5.2 | P8: 6 | Q8: 5.6 | R8: 1.6 | X8: 4.6 | AC8: 3.8 | AD8: 3 | AE8: 2.77
A9: Job No# | B9: 10573 bkd | E9: S-9921 | H9: S-10593 | I9: S-10619 | P9: S-10645 | R9: S10626 | X9: S-8691 | Y9: 10165 bkd | AD9: S-10777
A10: Time Allowed | B10: 1.2 | E10: 4.3 | H10: 3.6 | I10: 3 | P10: 2.77 | R10: 4.95 | X10: 6.2 | Y10: 2.4 | AD10: 2.6
A11: Job No# | B11: S-10583 | C11: S-10586 | E11: S-10497 | I11: S-10631 | P11: S-10716 | R11: S-10627 | W11: S-9588 | AD11: S-10779
A12: Time Allowed | B12: 2.2 | C12: 4.3 | E12: 5.2 | I12: 19 | P12: 2 | R12: 2 | W12: 3.12 | AD12: 2.6
A13: Job No# | C13: S-10594 | E13: S-10498 | R13: S-10628
A14: Time Allowed | C14: 5.2 | E14: 5.2 | R14: 2.6
A15: Job No# | C15: S-10527 | E15: S-10593 | R15: S-10629 | AD15: S-10790
A16: Time Allowed | C16: 2.4 | E16: 5.2 | R16: 1.9 | AD16: 2.9
A17: Job No# | R17: S-10165 | AD17: S-10797
A18: Time Allowed | R18: 1.6 | AD18: 0.5
A19: Job No#
A20: Time Allowed
A21: Job No#
A22: Time Allowed
A23: Job No#
A24: Time Allowed
A25: Job No#
A26: Time Allowed
A27: Job No#
A28: Time Allowed
A29: Job No#
A30: Time Allowed
... A32: Time Allowed
A33: Spare Hours | B33: =32.4-B4-B6-B8-B10-B12-B14-B16-B18-B20-B22-B24-B26-B28-B30-B32 -> 0.4 | C33: =32.4-C4-C6-C8-C10-C12-C14-C16-C18-C20-C22-C24-C26-C28-C30-C32 -> 7 | D33: =32.4-D4-D6-D8-D10-D12-D14-D16-D18-D20-D22-D24-D26-D28-D30-D32 -> 19.2 | E33: =32.4-E4-E6-E8-E10-E12-E14-E16-E18-E20-E22-E24-E26-E28-E30-E32 -> -0.4 | F33: =32.4-F4-F6-F8-F10-F12-F14-F16-F18-F20-F22-F24-F26-F28-F30-F32 -> 32.4 | G33: =32.4-G4-G6-G8-G10-G12-G14-G16-G18-G20-G22-G24-G26-G28-G30-G32 -> 32.4 | H33: =32.4-H4-H6-H8-H10-H12-H14-H16-H18-H20-H22-H24-H26-H28-H30-H32 -> 20.8 | I33: =32.4-I4-I6-I8-I10-I12-I14-I16-I18-I20-I22-I24-I26-I28-I30-I32 -> -0.1 | ... N33: =32.4-N4-N6-N8-N10-N12-N14-N16-N18-N20-N22-N24-N26-N28-N30-N32 -> 32.4 | O33: =24-O4-O6-O8-O10-O12-O14-O16-O18-O20-O22-O24-O26-O28-O30-O32 -> 0 | P33: =24-P4-P6-P8-P10-P12-P14-P16-P18-P20-P22-P24-P26-P28-P30-P32 -> 10.63 | Q33: =24-Q4-Q6-Q8-Q10-Q12-Q14-Q16-Q18-Q20-Q22-Q24-Q26-Q28-Q30-Q32 -> 14.1 | R33: =24-R4-R6-R8-R10-R12-R14-R16-R18-R20-R22-R24-R26-R28-R30-R32 -> 6.75 | S33: =27-S4-S6-S8-S10-S12-S14-S16-S18-S20-S22-S24-S26-S28-S30-S32 -> 27 | T33: =32.4-T4-T6-T8-T10-T12-T14-T16-T18-T20-T22-T24-T26-T28-T30-T32 -> 32.4 | U33: =32.4-U4-U6-U8-U10-U12-U14-U16-U18-U20-U22-U24-U26-U28-U30-U32 -> 32.4 | V33: =20.25-V4-V6-V8-V10-V12-V14-V16-V18-V20-V22-V24-V26-V28-V30-V32 -> 20.25 | W33: =18-W4-W6-W8-W10-W12-W14-W16-W18-W20-W22-W24-W26-W28-W30-W32 -> 9.88 | X33: =18-X4-X6-X8-X10-X12-X14-X16-X18-X20-X22-X24-X26-X28-X30-X32 -> -0.6 | Y33: =18-Y4-Y6-Y8-Y10-Y12-Y14-Y16-Y18-Y20-Y22-Y24-Y26-Y28-Y30-Y32 -> 2.45 | Z33: =20.25-Z4-Z6-Z8-Z10-Z12-Z14-Z16-Z18-Z20-Z22-Z24-Z26-Z28-Z30-Z32 -> 20.25 | AA33: =32.4-AA4-AA6-AA8-AA10-AA12-AA14-AA16-AA18-AA20-AA22-AA24-AA26-AA28-AA30-AA32 -> 32.4 | AB33: =32.4-AB4-AB6-AB8-AB10-AB12-AB14-AB16-AB18-AB20-AB22-AB24-AB26-AB28-AB30-AB32 -> 32.4 | AC33: =28.8-AC4-AC6-AC8-AC10-AC12-AC14-AC16-AC18-AC20-AC22-AC24-AC26-AC28-AC30-AC32 -> 8.8817842e-16 | AD33: =24.15-AD4-AD6-AD8-AD10-AD12-AD14-AD16-AD18-AD20-AD22-AD24-AD26-AD28-AD30-AD32 -> 3.35 | AE33: =24.15-AE4-AE6-AE8-AE10-AE12-AE14-AE16-AE18-AE20-AE22-AE24-AE26-AE28-AE30-AE32 -> 17.28
S34: Good | V34: Easter | Z34: Anzac Day
S35: Friday | V35: Monday
H36: Hours without Christoff

Sheet May
B1: 45778 | C1: 45779 | D1: 45780 | E1: 45781 | F1: 45782 | G1: 45783 | H1: 45784 | I1: 45785 | J1: 45786 | K1: 45787 | L1: 45788 | M1: 45789 | N1: 45790 | O1: 45791 | P1: 45792 | Q1: 45793 | R1: 45794 | S1: 45795 | T1: 45796 | U1: 45797 | V1: 45798 | W1: 45799 | X1: 45800 | Y1: 45801 | Z1: 45802 | AA1: 45803 | AB1: 45804 | AC1: 45805 | AD1: 45806 | AE1: 45807 | AF1: 45808
A2: Total Hrs Booked | B2: =B4+B6+B8+B10+B12+B14+B16+B18+B20+B22+B24+B26+B28+B30+B32 -> 24.1 | C2: =C4+C6+C8+C10+C12+C14+C16+C18+C20+C22+C24+C26+C28+C30+C32 -> 16.1 | D2: =D4+D6+D8+D10+D12+D14+D16+D18+D20+D22+D24+D26+D28+D30+D32 -> 0 | E2: =E4+E6+E8+E10+E12+E14+E16+E18+E20+E22+E24+E26+E28+E30+E32 -> 0 | F2: =F4+F6+F8+F10+F12+F14+F16+F18+F20+F22+F24+F26+F28+F30+F32 -> 25 | G2: =G4+G6+G8+G10+G12+G14+G16+G18+G20+G22+G24+G26+G28+G30+G32 -> 7.62 | H2: =H4+H6+H8+H10+H12+H14+H16+H18+H20+H22+H24+H26+H28+H30+H32 -> 13 | I2: =I4+I6+I8+I10+I12+I14+I16+I18+I20+I22+I24+I26+I28+I30+I32 -> 28.8 | ... AF2: =AF4+AF6+AF8+AF10+AF12+AF14+AF16+AF18+AF20+AF22+AF24+AF26+AF28+AF30+AF32 -> 0
A3: Job No# | B3: S-10358 | C3: 10577 bkd | F3: Kitsets | I3: S-10578 | J3: S-10301 | M3: Kitsets | O3: S-10824 | Q3: 10278 bkd | T3: Kitsets | U3: 10281 bkd | V3: S-10367 | X3: S-10053 | AA3: Kitsets | AC3: S-10588 | AD3: S-10382 | AE3: 10376 bkd
A4: Time Allowed | B4: 13 | C4: 0.5 | F4: 20 | I4: 17.1 | J4: 11 | O4: 2.9 | Q4: 9.3 | T4: 8 | U4: 23.94 | V4: 6.65 | X4: 32 | AA4: 20 | AC4: 17.1 | AD4: 14.4 | AE4: 4.2
A5: Job No# | B5: S-10344 | C5: S-10474 | F5: Kitset Pck | G5: S-10345 | H5: Move Timber | I5: S-10579 | J5: S-10302 | M5: Kitset Pck | P5: S-10064 | Q5: S-10279 | T5: Kitset Pck | U5: S-10850 | V5: S-10838 | W5: S-10886 | X5: 10924 bkd | AA5: Kitset Pck | AB5: S-10873 | AC5: 10375 bkd | AD5: 10376 bkd | AE5: 10924 bkd
A6: Time Allowed | B6: 2.6 | C6: 15.6 | F6: 5 | G6: 5.2 | H6: 6 | I6: 11.7 | J6: 9.4 | M6: 5 | P6: 20.8 | Q6: 12.9 | T6: 5 | U6: 2.6 | V6: 4 | W6: 2.6 | X6: 1 | AA6: 5 | AB6: 5.9 | AC6: 4.2 | AD6: 19.4 | AE6: 2.8
A7: Job No# | B7: S-10799 | H7: JSB Job | J7: 10579 bkd | P7: S-10278 | Q7: S-10280 | T7: 10280 bkd | U7: S-10859 | V7: S-10865 | W7: S-10858 | X7: S-1091 | AA7: S-10362 | AB7: S-10911 | AC7: S-10376 | AE7: S-10933
A8: Time Allowed | B8: 4 | H8: 7 | J8: 1.3 | P8: 8 | Q8: 11.6 | T8: 5.6 | U8: 2.5 | V8: 2.4 | W8: 3.35 | X8: 2.1 | AA8: 6.3 | AB8: 2.5 | AC8: 12.4 | AE8: 2.75
A9: Job No# | B9: S-10577 | G9: S-10831 | M9: S-10880 | T9: S-10281 | U9: S-10862 | V9: S-10839 | W9: 10862 bkd | AA9: 10910 bkd | AB9: S-10375 | AE9: S-10932
A10: Time Allowed | B10: 4.5 | G10: 2.42 | M10: 4 | T10: 1.8 | U10: 3.2 | V10: 4.5 | W10: 4.6 | AA10: 0.8 | AB10: 22 | AE10: 4.05
A11: Job No# | T11: S-10868 | V11: S-10866 | W11: S-10898 | AA11: 10924 bkd | AE11: S-10934
A12: Time Allowed | T12: 2.6 | V12: 2.6 | W12: 4 | AA12: 1.7 | AE12: 3.5
A13: Job No# | T13: hrs bkd | W13: S-10924 | AE13: S-10943
A14: Time Allowed | T14: 3.5 | W14: 5.7 | AE14: 4.6
A15: Job No# | T15: S-10937 | AE15: S-10955
A16: Time Allowed | T16: 2.4 | AE16: 5.7
A17: Job No# | AE17: S-10956
A18: Time Allowed | AE18: 3.12
A19: Job No# | AE19: S-10968
A20: Time Allowed | AE20: 1.5
A21: Job No# | AE21: S-10965
A22: Time Allowed | AE22: 1.5
A23: Job No#
A24: Time Allowed
A25: Job No#
A26: Time Allowed
A27: Job No#
A28: Time Allowed
A29: Job No#
A30: Time Allowed
A31: Job No#
A32: Time Allowed
A33: Spare Hours | B33: =24.15-B4-B6-B8-B10-B12-B14-B16-B18-B20-B22-B24-B26-B28-B30-B32 -> 0.05 | C33: =24.15-C4-C6-C8-C10-C12-C14-C16-C18-C20-C22-C24-C26-C28-C30-C32 -> 8.05 | D33: =40-D4-D6-D8-D10-D12-D14-D16-D18-D20-D22-D24-D26-D28-D30-D32 -> 40 | E33: =40-E4-E6-E8-E10-E12-E14-E16-E18-E20-E22-E24-E26-E28-E30-E32 -> 40 | F33: =28.2-F4-F6-F8-F10-F12-F14-F16-F18-F20-F22-F24-F26-F28-F30-F32 -> 3.2 | G33: =28.2-G4-G6-G8-G10-G12-G14-G16-G18-G20-G22-G24-G26-G28-G30-G32 -> 20.58 | H33: =28.2-H4-H6-H8-H10-H12-H14-H16-H18-H20-H22-H24-H26-H28-H30-H32 -> 15.2 | I33: =28.2-I4-I6-I8-I10-I12-I14-I16-I18-I20-I22-I24-I26-I28-I30-I32 -> -0.6 | J33: =28.2-J4-J6-J8-J10-J12-J14-J16-J18-J20-J22-J24-J26-J28-J30-J32 -> 6.5 | K33: =28.8-K4-K6-K8-K10-K12-K14-K16-K18-K20-K22-K24-K26-K28-K30-K32 -> 28.8 | L33: =28.8-L4-L6-L8-L10-L12-L14-L16-L18-L20-L22-L24-L26-L28-L30-L32 -> 28.8 | M33: =33.75-M4-M6-M8-M10-M12-M14-M16-M18-M20-M22-M24-M26-M28-M30-M32 -> 24.75 | N33: =33.75-N4-N6-N8-N10-N12-N14-N16-N18-N20-N22-N24-N26-N28-N30-N32 -> 33.75 | O33: =33.75-O4-O6-O8-O10-O12-O14-O16-O18-O20-O22-O24-O26-O28-O30-O32 -> 30.85 | P33: =33.75-P4-P6-P8-P10-P12-P14-P16-P18-P20-P22-P24-P26-P28-P30-P32 -> 4.95 | Q33: =33.75-Q4-Q6-Q8-Q10-Q12-Q14-Q16-Q18-Q20-Q22-Q24-Q26-Q28-Q30-Q32 -> -0.05 | R33: =28.8-R4-R6-R8-R10-R12-R14-R16-R18-R20-R22-R24-R26-R28-R30-R32 -> 28.8 | S33: =28.8-S4-S6-S8-S10-S12-S14-S16-S18-S20-S22-S24-S26-S28-S30-S32 -> 28.8 | T33: =32.4-T4-T6-T8-T10-T12-T14-T16-T18-T20-T22-T24-T26-T28-T30-T32 -> 3.5 | U33: =32.4-U4-U6-U8-U10-U12-U14-U16-U18-U20-U22-U24-U26-U28-U30-U32 -> 0.16 | V33: =35.1-V4-V6-V8-V10-V12-V14-V16-V18-V20-V22-V24-V26-V28-V30-V32 -> 14.95 | W33: =35.1-W4-W6-W8-W10-W12-W14-W16-W18-W20-W22-W24-W26-W28-W30-W32 -> 14.85 | X33: =35.1-X4-X6-X8-X10-X12-X14-X16-X18-X20-X22-X24-X26-X28-X30-X32 -> 1.3322676e-15 | Y33: =32.4-Y4-Y6-Y8-Y10-Y12-Y14-Y16-Y18-Y20-Y22-Y24-Y26-Y28-Y30-Y32 -> 32.4 | Z33: =32.4-Z4-Z6-Z8-Z10-Z12-Z14-Z16-Z18-Z20-Z22-Z24-Z26-Z28-Z30-Z32 -> 32.4 | AA33: =33.75-AA4-AA6-AA8-AA10-AA12-AA14-AA16-AA18-AA20-AA22-AA24-AA26-AA28-AA30-AA32 -> -0.05 | AB33: =33.75-AB4-AB6-AB8-AB10-AB12-AB14-AB16-AB18-AB20-AB22-AB24-AB26-AB28-AB30-AB32 -> 3.35 | AC33: =33.75-AC4-AC6-AC8-AC10-AC12-AC14-AC16-AC18-AC20-AC22-AC24-AC26-AC28-AC30-AC32 -> 0.05 | AD33: =33.75-AD4-AD6-AD8-AD10-AD12-AD14-AD16-AD18-AD20-AD22-AD24-AD26-AD28-AD30-AD32 -> -0.05 | AE33: =33.75-AE4-AE6-AE8-AE10-AE12-AE14-AE16-AE18-AE20-AE22-AE24-AE26-AE28-AE30-AE32 -> 0.03 | AF33: =33.75-AF4-AF6-AF8-AF10-AF12-AF14-AF16-AF18-AF20-AF22-AF24-AF26-AF28-AF30-AF32 -> 33.75
B35: Hours without Christoff | M35: 7am-5pm (Neil work 5 days) | T35: 7am-5pm (Neil work 4 days) | AA35: 7am-5pm (Neil work 5 days)

Sheet June
B1: 45809 | C1: 45810 | D1: 45811 | E1: 45812 | F1: 45813 | G1: 45814 | H1: 45815 | I1: 45816 | J1: 45817 | K1: 45818 | L1: 45819 | M1: 45820 | N1: 45821 | O1: 45822 | P1: 45823 | Q1: 45824 | R1: 45825 | S1: 45826 | T1: 45827 | U1: 45828 | V1: 45829 | W1: 45830 | X1: 45831 | Y1: 45832 | Z1: 45833 | AA1: 45834 | AB1: 45835 | AC1: 45836 | AD1: 45837 | AE1: 45838
A2: Total Hrs Booked | B2: =B4+B6+B8+B10+B12+B14+B16+B18+B20+B22+B24+B26+B28+B30+B32 -> 0 | C2: =C4+C6+C8+C10+C12+C14+C16+C18+C20+C22+C24+C26+C28+C30+C32 -> 0 | D2: =D4+D6+D8+D10+D12+D14+D16+D18+D20+D22+D24+D26+D28+D30+D32 -> 33.75 | E2: =E4+E6+E8+E10+E12+E14+E16+E18+E20+E22+E24+E26+E28+E30+E32 -> 33.8 | F2: =F4+F6+F8+F10+F12+F14+F16+F18+F20+F22+F24+F26+F28+F30+F32 -> 33.7 | G2: =G4+G6+G8+G10+G12+G14+G16+G18+G20+G22+G24+G26+G28+G30+G32 -> 33.7 | H2: =H4+H6+H8+H10+H12+H14+H16+H18+H20+H22+H24+H26+H28+H30+H32 -> 0 | I2: =I4+I6+I8+I10+I12+I14+I16+I18+I20+I22+I24+I26+I28+I30+I32 -> 0 | ... AE2: =AE4+AE6+AE8+AE10+AE12+AE14+AE16+AE18+AE20+AE22+AE24+AE26+AE28+AE30+AE32 -> 37.2
A3: Job No# | D3: Kitsets | E3: 10782 bkd | F3: 10783 bkd | G3: 10784 bkd | J3: Kitsets | K3: S-10953 | L3: S-10386 | M3: S-11046 | N3: S-10650 | Q3: Kitsets | R3: S-10648 | S3: S-10750 | T3: S-10749 | X3: Kitsets | Y3: 10753 bkd | Z3: S-11047 | AA3: S-10982 | AB3: S-11136 | AE3: Kitsets
A4: Time Allowed | D4: 20 | E4: 32.8 | F4: 21 | G4: 10.3 | J4: 17 | K4: 11 | L4: 2.77 | M4: 2.94 | N4: 23 | Q4: 3 | R4: 8.8 | S4: 29.9 | T4: 23.9 | X4: 20 | Y4: 9.2 | Z4: 5 | AA4: 6.35 | AB4: 5.5 | AE4: 5
A5: Job No# | D5: Kitset Pck | E5: S-10783 | F5: S-10784 | G5: S-10958 | J5: Kitset Pck | K5: S-10971 | L5: S-10393 | M5: S-11045 | N5: 10917 bkd | Q5: Kitset Pck | R5: 11037 bkd | T5: S-11124 | X5: Kitset Pck | Y5: S-11029 | AA5: S-10531 | AB5: S-11072 | AE5: Kitset Pck
A6: Time Allowed | D6: 5 | E6: 1 | F6: 12.7 | G6: 5 | J6: 5 | K6: 9.2 | L6: 2.77 | M6: 0.5 | N6: 2.7 | Q6: 5 | R6: 6.8 | T6: 2.77 | X6: 5 | Y6: 2.6 | AA6: 3.5 | AB6: 4.6 | AE6: 5
A7: Job No# | D7: S-10975 | E7: 11036 re-do | G7: S-10992 | J7: 9500 bkd | K7: S-10988 | L7: S-10114 | M7: S-11050 | N7: S-10918 | Q7: S-11037 | T7: S-11062 | X7: S-10753 | Y7: 11062 bkd | AA7: S-11122 | AB7: S-11138 | AE7: S-10236
A8: Time Allowed | D8: 1.5 | G8: 2.8 | J8: 4.4 | K8: 2.1 | L8: 2.6 | M8: 3.2 | N8: 6.7 | Q8: 8.8 | T8: 2.8 | X8: 7.4 | Y8: 1.4 | AA8: 2 | AB8: 22.3 | AE8: 4.5
A9: Job No# | D9: 10933 bkd | G9: S-9500 | J9: S-9674 | L9: S-11010 | M9: S-10500 | R9: S-10748 | Y9: S-11100 | AA9: S-11121 | AE9: 11138 bkd
A10: Time Allowed | D10: 3.25 | G10: 15.6 | J10: 2.95 | L10: 2.95 | M10: 2.6 | R10: 13.2 | Y10: 2.6 | AA10: 2.3 | AE10: 5.9
A11: Job No# | D11: S-10782 | J11: S-10980 | K11: S-10996 | L11: S-10998 | M11: 10946 bkd | Q11: S-10510 | Y11: S-11108 | AA11: S-10651 | AE11: S-11139
A12: Time Allowed | D12: 4 | J12: 3 | K12: 3.3 | L12: 2.4 | M12: 2.8 | Q12: 5 | Y12: 5.6 | AA12: 8.5 | AE12: 16.8
A13: Job No# | L13: S-10520 | Q13: 10918 bkd | Y13: S-10780 | Z13: S-11141
A14: Time Allowed | L14: 12.1 | Q14: 4.3 | Y14: 3.3 | Z14: 5.6
A15: Job No# | L15: S-11054 | M15: S-11068 | Q15: S-11097 | Y15: S-11123 | Z15: S-11142 | AA15: S-11137
A16: Time Allowed | L16: 5.2 | M16: 3.1 | Q16: 2.6 | Y16: 2.77 | Z16: 4.9 | AA16: 5.5
A17: Job No# | L17: S-10946 | M17: S-11069 | Y17: 10588 redo
A18: Time Allowed | L18: 1.6 | M18: 4.6 | Y18: 4.9
A19: Job No# | M19: S-11070
A20: Time Allowed | M20: 2.6
A21: Job No# | M21: S-11083
A22: Time Allowed | M22: 1.75
A23: Job No# | M23: S-10917
A24: Time Allowed | M24: 8.3
A25: Job No#
A26: Time Allowed
A27: Job No#
A28: Time Allowed
A29: Job No#
A30: Time Allowed
A31: Job No#
A32: Time Allowed
A33: Spare Hours | B33: =40-B4-B6-B8-B10-B12-B14-B16-B18-B20-B22-B24-B26-B28-B30-B32 -> 40 | C33: =27-C4-C6-C8-C10-C12-C14-C16-C18-C20-C22-C24-C26-C28-C30-C32 -> 27 | D33: =33.75-D4-D6-D8-D10-D12-D14-D16-D18-D20-D22-D24-D26-D28-D30-D32 -> 0 | E33: =33.75-E4-E6-E8-E10-E12-E14-E16-E18-E20-E22-E24-E26-E28-E30-E32 -> -0.05 | F33: =33.75-F4-F6-F8-F10-F12-F14-F16-F18-F20-F22-F24-F26-F28-F30-F32 -> 0.05 | G33: =33.75-G4-G6-G8-G10-G12-G14-G16-G18-G20-G22-G24-G26-G28-G30-G32 -> 0.05 | H33: =27-H4-H6-H8-H10-H12-H14-H16-H18-H20-H22-H24-H26-H28-H30-H32 -> 27 | I33: =27-I4-I6-I8-I10-I12-I14-I16-I18-I20-I22-I24-I26-I28-I30-I32 -> 27 | J33: =32.4-J4-J6-J8-J10-J12-J14-J16-J18-J20-J22-J24-J26-J28-J30-J32 -> 0.05 | K33: =32.4-K4-K6-K8-K10-K12-K14-K16-K18-K20-K22-K24-K26-K28-K30-K32 -> 6.8 | L33: =32.4-L4-L6-L8-L10-L12-L14-L16-L18-L20-L22-L24-L26-L28-L30-L32 -> 0.01 | M33: =32.4-M4-M6-M8-M10-M12-M14-M16-M18-M20-M22-M24-M26-M28-M30-M32 -> 0.01 | N33: =32.4-N4-N6-N8-N10-N12-N14-N16-N18-N20-N22-N24-N26-N28-N30-N32 -> -1.7763568e-15 | O33: =32.4-O4-O6-O8-O10-O12-O14-O16-O18-O20-O22-O24-O26-O28-O30-O32 -> 32.4 | P33: =32.4-P4-P6-P8-P10-P12-P14-P16-P18-P20-P22-P24-P26-P28-P30-P32 -> 32.4 | Q33: =33.75-Q4-Q6-Q8-Q10-Q12-Q14-Q16-Q18-Q20-Q22-Q24-Q26-Q28-Q30-Q32 -> 5.05 | R33: =33.75-R4-R6-R8-R10-R12-R14-R16-R18-R20-R22-R24-R26-R28-R30-R32 -> 4.95 | S33: =33.75-S4-S6-S8-S10-S12-S14-S16-S18-S20-S22-S24-S26-S28-S30-S32 -> 3.85 | T33: =33.75-T4-T6-T8-T10-T12-T14-T16-T18-T20-T22-T24-T26-T28-T30-T32 -> 4.28 | U33: =33.75-U4-U6-U8-U10-U12-U14-U16-U18-U20-U22-U24-U26-U28-U30-U32 -> 33.75 | V33: =27-V4-V6-V8-V10-V12-V14-V16-V18-V20-V22-V24-V26-V28-V30-V32 -> 27 | W33: =27-W4-W6-W8-W10-W12-W14-W16-W18-W20-W22-W24-W26-W28-W30-W32 -> 27 | X33: =32.4-X4-X6-X8-X10-X12-X14-X16-X18-X20-X22-X24-X26-X28-X30-X32 -> -1.7763568e-15 | Y33: =32.4-Y4-Y6-Y8-Y10-Y12-Y14-Y16-Y18-Y20-Y22-Y24-Y26-Y28-Y30-Y32 -> 0.03 | Z33: =32.4-Z4-Z6-Z8-Z10-Z12-Z14-Z16-Z18-Z20-Z22-Z24-Z26-Z28-Z30-Z32 -> 16.9 | AA33: =32.4-AA4-AA6-AA8-AA10-AA12-AA14-AA16-AA18-AA20-AA22-AA24-AA26-AA28-AA30-AA32 -> 4.25 | AB33: =32.4-AB4-AB6-AB8-AB10-AB12-AB14-AB16-AB18-AB20-AB22-AB24-AB26-AB28-AB30-AB32 -> -3.5527137e-15 | AC33: =32.4-AC4-AC6-AC8-AC10-AC12-AC14-AC16-AC18-AC20-AC22-AC24-AC26-AC28-AC30-AC32 -> 32.4 | AD33: =32.4-AD4-AD6-AD8-AD10-AD12-AD14-AD16-AD18-AD20-AD22-AD24-AD26-AD28-AD30-AD32 -> 32.4 | AE33: =37.2-AE4-AE6-AE8-AE10-AE12-AE14-AE16-AE18-AE20-AE22-AE24-AE26-AE28-AE30-AE32 -> 3.5527137e-15
C34: Kings | U34: Matariki
C35: B'day | D35: 7am-5pm (Neil work 3 days) | J35: 7am-5pm (Neil work 4 days) | Q35: 7am-5pm (Neil work 4 days) | X35: 7am-5pm (Neil work 4 days)
D36: didn’t adjust hours as ahead of schedule

Sheet July
B1: 45839 | C1: 45840 | D1: 45841 | E1: 45842 | F1: 45843 | G1: 45844 | H1: 45845 | I1: 45846 | J1: 45847 | K1: 45848 | L1: 45849 | M1: 45850 | N1: 45851 | O1: 45852 | P1: 45853 | Q1: 45854 | R1: 45855 | S1: 45856 | T1: 45857 | U1: 45858 | V1: 45859 | W1: 45860 | X1: 45861 | Y1: 45862 | Z1: 45863 | AA1: 45864 | AB1: 45865 | AC1: 45866 | AD1: 45867 | AE1: 45868 | AF1: 45869
A2: Total Hrs Booked | B2: =B4+B6+B8+B10+B12+B14+B16+B18+B20+B22+B24+B26+B28+B30+B32 -> 30.5 | C2: =C4+C6+C8+C10+C12+C14+C16+C18+C20+C22+C24+C26+C28+C30+C32 -> 0 | D2: =D4+D6+D8+D10+D12+D14+D16+D18+D20+D22+D24+D26+D28+D30+D32 -> 36.2 | E2: =E4+E6+E8+E10+E12+E14+E16+E18+E20+E22+E24+E26+E28+E30+E32 -> 37.2 | F2: =F4+F6+F8+F10+F12+F14+F16+F18+F20+F22+F24+F26+F28+F30+F32 -> 0 | G2: =G4+G6+G8+G10+G12+G14+G16+G18+G20+G22+G24+G26+G28+G30+G32 -> 0 | H2: =H4+H6+H8+H10+H12+H14+H16+H18+H20+H22+H24+H26+H28+H30+H32 -> 36.5 | I2: =I4+I6+I8+I10+I12+I14+I16+I18+I20+I22+I24+I26+I28+I30+I32 -> 34.8 | ... AF2: =AF4+AF6+AF8+AF10+AF12+AF14+AF16+AF18+AF20+AF22+AF24+AF26+AF28+AF30+AF32 -> 32.4
A3: Job No# | B3: S-10746 | D3: 11039 bkd | E3: 11039 bkd | H3: Kitsets | I3: S-10904 | J3: S-10548 | K3: S-10785 | L3: 10785 bkd | O3: Kitsets | P3: S-11285 | Q3: 10798 bkd | R3: S-10788 | V3: Kitsets | W3: S-10496 | X3: S-11159 | Y3: 10739 bkd | Z3: S-10747 | AC3: Kitsets | AD3: S-11155 | AE3: S-11282 | AF3: S-11135
A4: Time Allowed | B4: 13.2 | D4: 36.2 | E4: 13.8 | H4: 20 | I4: 11 | J4: 12.9 | K4: 37.2 | L4: 18 | O4: 5 | P4: 2.77 | Q4: 1.4 | R4: 2.77 | V4: 20 | W4: 23 | X4: 15.6 | Y4: 3 | Z4: 17.6 | AC4: 20 | AD4: 12 | AE4: 2.6 | AF4: 32.4
A5: Job No# | B5: 11139 bkd | E5: S-11168 | H5: Kitset Pck | I5: S-10585 | J5: S-10549 | L5: S-11074 | O5: Kitset Pck | Q5: S-10919 | R5: S-10789 | S5: 10720 bkd | V5: Kitset Pck | W5: S-11154 | X5: S-11274 | Z5: S-11107 | AC5: Kitset Pck | AD5: S-10752 | AE5: 10752 bkd
A6: Time Allowed | B6: 11.7 | E6: 4.1 | H6: 5 | I6: 5.2 | J6: 12.9 | L6: 2.6 | O6: 5 | Q6: 2.95 | R6: 2.77 | S6: 4.3 | V6: 5 | W6: 4.8 | X6: 3.8 | Z6: 4.3 | AC6: 5 | AD6: 20.4 | AE6: 9.5
A7: Job No# | B7: S-11119 | E7: S-11117 | H7: S-11203 | I7: S-10972 | J7: S-11160 | L7: S-11075 | O7: S-10914 | Q7: S-11016 | R7: S-11071 | S7: S-11140 | V7: 11158 bkd | W7: 11158 bkd | X7: S-10739 | Y7: S-11212 | Z7: 11324 bkd | AC7: S-11215
A8: Time Allowed | B8: 5.6 | E8: 3.5 | H8: 6 | I8: 5.2 | J8: 5.2 | L8: 5.6 | O8: 6.65 | Q8: 11.1 | R8: 13.8 | S8: 16.7 | V8: 7.4 | W8: 4.6 | X8: 12.5 | Y8: 2.6 | Z8: 0.5 | AC8: 2.9
A9: Job No# | E9: S-11177 | H9: S-11241 | I9: S-10973 | J9: S-11230 | L9: S-11190 | O9: S-1120 | Q9: S-11017 | R9: 10720 bkd | S9: S-11158 | X9: S-11324 | Y9: S-11253 | Z9: S-11348 | AC9: 11349 bkd | AE9: Mthd grp
A10: Time Allowed | E10: 5.2 | H10: 2.6 | I10: 2.6 | J10: 2.8 | L10: 4.6 | O10: 0.7 | Q10: 4.5 | R10: 13.1 | S10: 3.6 | X10: 0.5 | Y10: 3.2 | Z10: 2.8 | AC10: 2.4 | AE10: 6
A11: Job No# | E11: S-11174 | H11: S-11151 | I11: S-10974 | L11: S-1120 | O11: S-11231 | Q11: S-10720 | Y11: S-10967 | Z11: S-11347 | AE11: S-11349
A12: Time Allowed | E12: 2.5 | H12: 2.9 | I12: 2.6 | L12: 0.8 | O12: 15 | Q12: 9.9 | Y12: 5 | Z12: 2.4 | AE12: 8
A13: Job No# | E13: S-11171 | I13: S-10995 | L13: S-11207 | Q13: S-11315 | Y13: S-11310
A14: Time Allowed | E14: 1.5 | I14: 2.6 | L14: 5.6 | Q14: 2.6 | Y14: 3.1
A15: Job No# | E15: S-11085 | I15: S-11152 | Y15: S-11313
A16: Time Allowed | E16: 2.6 | I16: 5.6 | Y16: 3.7
A17: Job No# | E17: S-11206 | Y17: S-11323
A18: Time Allowed | E18: 4 | Y18: 2.4
A19: Job No# | Y19: S-11324
A20: Time Allowed | Y20: 1.4
A21: Job No#
A22: Time Allowed
A23: Job No#
A24: Time Allowed
A25: Job No#
A26: Time Allowed
A27: Job No#
A28: Time Allowed
A29: Job No#
A30: Time Allowed
A31: Job No#
A32: Time Allowed
A33: Spare Hours | B33: =37.2-B4-B6-B8-B10-B12-B14-B16-B18-B20-B22-B24-B26-B28-B30-B32 -> 6.7 | C33: =37.2-C4-C6-C8-C10-C12-C14-C16-C18-C20-C22-C24-C26-C28-C30-C32 -> 37.2 | D33: =37.2-D4-D6-D8-D10-D12-D14-D16-D18-D20-D22-D24-D26-D28-D30-D32 -> 1 | E33: =37.2-E4-E6-E8-E10-E12-E14-E16-E18-E20-E22-E24-E26-E28-E30-E32 -> 5.3290705e-15 | F33: =37.2-F4-F6-F8-F10-F12-F14-F16-F18-F20-F22-F24-F26-F28-F30-F32 -> 37.2 | G33: =37.2-G4-G6-G8-G10-G12-G14-G16-G18-G20-G22-G24-G26-G28-G30-G32 -> 37.2 | H33: =37.2-H4-H6-H8-H10-H12-H14-H16-H18-H20-H22-H24-H26-H28-H30-H32 -> 0.7 | I33: =37.2-I4-I6-I8-I10-I12-I14-I16-I18-I20-I22-I24-I26-I28-I30-I32 -> 2.4 | ... L33: =37.2-L4-L6-L8-L10-L12-L14-L16-L18-L20-L22-L24-L26-L28-L30-L32 -> 2.6645353e-15 | M33: =32.4-M4-M6-M8-M10-M12-M14-M16-M18-M20-M22-M24-M26-M28-M30-M32 -> 32.4 | N33: =32.4-N4-N6-N8-N10-N12-N14-N16-N18-N20-N22-N24-N26-N28-N30-N32 -> 32.4 | O33: =32.4-O4-O6-O8-O10-O12-O14-O16-O18-O20-O22-O24-O26-O28-O30-O32 -> 0.05 | P33: =32.4-P4-P6-P8-P10-P12-P14-P16-P18-P20-P22-P24-P26-P28-P30-P32 -> 29.63 | Q33: =32.4-Q4-Q6-Q8-Q10-Q12-Q14-Q16-Q18-Q20-Q22-Q24-Q26-Q28-Q30-Q32 -> -0.05 | R33: =32.4-R4-R6-R8-R10-R12-R14-R16-R18-R20-R22-R24-R26-R28-R30-R32 -> -0.04 | S33: =32.4-S4-S6-S8-S10-S12-S14-S16-S18-S20-S22-S24-S26-S28-S30-S32 -> 7.8 | T33: =32.4-T4-T6-T8-T10-T12-T14-T16-T18-T20-T22-T24-T26-T28-T30-T32 -> 32.4 | ... AF33: =32.4-AF4-AF6-AF8-AF10-AF12-AF14-AF16-AF18-AF20-AF22-AF24-AF26-AF28-AF30-AF32 -> 0

Sheet August
B1: 45870 | C1: 45871 | D1: 45872 | E1: 45873 | F1: 45874 | G1: 45875 | H1: 45876 | I1: 45877 | J1: 45878 | K1: 45879 | L1: 45880 | M1: 45881 | N1: 45882 | O1: 45883 | P1: 45884 | Q1: 45885 | R1: 45886 | S1: 45887 | T1: 45888 | U1: 45889 | V1: 45890 | W1: 45891 | X1: 45892 | Y1: 45893 | Z1: 45894 | AA1: 45895 | AB1: 45896 | AC1: 45897 | AD1: 45898 | AE1: 45899 | AF1: 45900
A2: Total Hrs Booked | B2: =B4+B6+B8+B10+B12+B14+B16+B18+B20+B22+B24+B26+B28+B30+B32 -> 32.37 | C2: =C4+C6+C8+C10+C12+C14+C16+C18+C20+C22+C24+C26+C28+C30+C32 -> 0 | D2: =D4+D6+D8+D10+D12+D14+D16+D18+D20+D22+D24+D26+D28+D30+D32 -> 0 | E2: =E4+E6+E8+E10+E12+E14+E16+E18+E20+E22+E24+E26+E28+E30+E32 -> 32.4 | F2: =F4+F6+F8+F10+F12+F14+F16+F18+F20+F22+F24+F26+F28+F30+F32 -> 31.6 | G2: =G4+G6+G8+G10+G12+G14+G16+G18+G20+G22+G24+G26+G28+G30+G32 -> 29.6 | H2: =H4+H6+H8+H10+H12+H14+H16+H18+H20+H22+H24+H26+H28+H30+H32 -> 28.4 | I2: =I4+I6+I8+I10+I12+I14+I16+I18+I20+I22+I24+I26+I28+I30+I32 -> 23.1 | ... AF2: =AF4+AF6+AF8+AF10+AF12+AF14+AF16+AF18+AF20+AF22+AF24+AF26+AF28+AF30+AF32 -> 0
A3: Job No# | B3: S-10949 | E3: Kitsets | F3: Kitsets | G3: 11371 bkd | H3: S-11394 | L3: Kitsets | M3: 10605 bkd | N3: S-10895 | O3: S-11370 | S3: Kitsets | T3: 11214 bkd | U3: S-10591 | V3: S-11088 | W3: S-11490 | Z3: Kitsets | AA3: S-11003 | AB3: S-11524 | AC3: S-11505 | AD3: S-11460
A4: Time Allowed | B4: 2.77 | E4: 0 | F4: 6 | G4: 2 | H4: 2.4 | L4: 20 | M4: 0.5 | N4: 2.6 | O4: 15.6 | S4: 20 | T4: 5.5 | U4: 14.8 | V4: 13.8 | W4: 8.2 | Z4: 20 | AA4: 18 | AB4: 6.2 | AC4: 3.17 | AD4: 5.2
A5: Job No# | B5: S-10503 | E5: Kitset Pck | F5: S-11189 | G5: S-11301 | I5: 10798 bkd | L5: Kitset Pck | N5: S-10604 | P5: S-11361 | S5: Kitset Pck | T5: S-11437 | U5: S-10592 | W5: S-11491 | Z5: Kitset Pck | AA5: S-11293 | AB5: S-11525 | AC5: S-11533 | AD5: S-11149
A6: Time Allowed | B6: 2.6 | E6: 5 | F6: 8 | G6: 2.6 | I6: 20 | L6: 5 | N6: 0.5 | P6: 3.3 | S6: 5 | T6: 5.6 | U6: 14.8 | W6: 13.8 | Z6: 5 | AA6: 6.3 | AB6: 3.7 | AC6: 3.6 | AD6: 5.5
A7: Job No# | B7: 11135 bkd | E7: S-11279 | F7: S-11048 | G7: S-11359 | H7: S-11418 | I7: S-11427 | L7: S-11423 | M7: S-10798 | N7: S-11350 | S7: S-11456 | T7: 11442 bkd | U7: S-11461 | Z7: S-10501 | AD7: S-11556
A8: Time Allowed | B8: 25.6 | E8: 2.9 | F8: 13.8 | G8: 5.6 | H8: 4.6 | I8: 3.1 | L8: 8 | M8: 23.8 | N8: 2.6 | S8: 3.1 | T8: 1.4 | U8: 5.6 | Z8: 5.2 | AD8: 2.6
A9: Job No# | B9: S-11279 | E9: S-11120 | F9: 11382 bkd | G9: S-11360 | H9: S-10786 | L9: S-10605 | M9: 11427 bkd | N9: S-10786 | P9: 11451 bkd | S9: S-11269 | T9: 11459 bkd | AC9: S-11550 | AD9: S-11534
A10: Time Allowed | B10: 1.4 | E10: 19.5 | F10: 1.6 | G10: 5.6 | H10: 21.4 | L10: 2.1 | M10: 2.5 | N10: 17.4 | P10: 2 | S10: 5.6 | T10: 0.3 | AC10: 2.4 | AD10: 3.3
A11: Job No# | E11: S-11267 | F11: S-11371 | G11: S-10185 | M11: S-11189 | N11: 11189 bkd | P11: S-11442 | S11: S-11214 | T11: S-11479 | AD11: S-9181
A12: Time Allowed | E12: 2.1 | F12: 2.2 | G12: 6 | M12: 4 | N12: 4.5 | P12: 3.9 | S12: 2.8 | T12: 4.6 | AD12: 5.6
A13: Job No# | E13: S-11382 | G13: S-11071 | M13: S-11472 | N13: S-11451 | S13: S-11459 | AD13: S-11407
A14: Time Allowed | E14: 2.9 | G14: 7.8 | M14: 4.3 | N14: 7.5 | S14: 1.3 | AD14: 9.34
A15: Job No#
A16: Time Allowed
A17: Job No# | T17: S-11476
A18: Time Allowed | T18: 4.7
A19: Job No# | T19: S-10502
A20: Time Allowed | T20: 2.6
A21: Job No#
A22: Time Allowed
A23: Job No#
A24: Time Allowed
A25: Job No#
A26: Time Allowed
A27: Job No#
A28: Time Allowed
A29: Job No#
A30: Time Allowed
A31: Job No#
A32: Time Allowed
A33: Spare Hours | B33: =32.4-B4-B6-B8-B10-B12-B14-B16-B18-B20-B22-B24-B26-B28-B30-B32 -> 0.03 | C33: =32.4-C4-C6-C8-C10-C12-C14-C16-C18-C20-C22-C24-C26-C28-C30-C32 -> 32.4 | D33: =32.4-D4-D6-D8-D10-D12-D14-D16-D18-D20-D22-D24-D26-D28-D30-D32 -> 32.4 | E33: =32.4-E4-E6-E8-E10-E12-E14-E16-E18-E20-E22-E24-E26-E28-E30-E32 -> 0 | F33: =32.4-F4-F6-F8-F10-F12-F14-F16-F18-F20-F22-F24-F26-F28-F30-F32 -> 0.8 | G33: =32.4-G4-G6-G8-G10-G12-G14-G16-G18-G20-G22-G24-G26-G28-G30-G32 -> 2.8 | H33: =32.4-H4-H6-H8-H10-H12-H14-H16-H18-H20-H22-H24-H26-H28-H30-H32 -> 4 | I33: =32.4-I4-I6-I8-I10-I12-I14-I16-I18-I20-I22-I24-I26-I28-I30-I32 -> 9.3 | ... K33: =32.4-K4-K6-K8-K10-K12-K14-K16-K18-K20-K22-K24-K26-K28-K30-K32 -> 32.4 | L33: =35.1-L4-L6-L8-L10-L12-L14-L16-L18-L20-L22-L24-L26-L28-L30-L32 -> 1.3322676e-15 | M33: =35.1-M4-M6-M8-M10-M12-M14-M16-M18-M20-M22-M24-M26-M28-M30-M32 -> 8.8817842e-16 | N33: =35.1-N4-N6-N8-N10-N12-N14-N16-N18-N20-N22-N24-N26-N28-N30-N32 -> 0 | O33: =35.1-O4-O6-O8-O10-O12-O14-O16-O18-O20-O22-O24-O26-O28-O30-O32 -> 19.5 | P33: =35.1-P4-P6-P8-P10-P12-P14-P16-P18-P20-P22-P24-P26-P28-P30-P32 -> 25.9 | Q33: =32.4-Q4-Q6-Q8-Q10-Q12-Q14-Q16-Q18-Q20-Q22-Q24-Q26-Q28-Q30-Q32 -> 32.4 | R33: =32.4-R4-R6-R8-R10-R12-R14-R16-R18-R20-R22-R24-R26-R28-R30-R32 -> 32.4 | S33: =37.8-S4-S6-S8-S10-S12-S14-S16-S18-S20-S22-S24-S26-S28-S30-S32 -> -1.9984014e-15 | T33: =37.8-T4-T6-T8-T10-T12-T14-T16-T18-T20-T22-T24-T26-T28-T30-T32 -> 13.1 | U33: =37.8-U4-U6-U8-U10-U12-U14-U16-U18-U20-U22-U24-U26-U28-U30-U32 -> 2.6 | V33: =37.8-V4-V6-V8-V10-V12-V14-V16-V18-V20-V22-V24-V26-V28-V30-V32 -> 24 | W33: =37.8-W4-W6-W8-W10-W12-W14-W16-W18-W20-W22-W24-W26-W28-W30-W32 -> 15.8 | X33: =37.8-X4-X6-X8-X10-X12-X14-X16-X18-X20-X22-X24-X26-X28-X30-X32 -> 37.8 | Y33: =37.8-Y4-Y6-Y8-Y10-Y12-Y14-Y16-Y18-Y20-Y22-Y24-Y26-Y28-Y30-Y32 -> 37.8 | Z33: =39.1-Z4-Z6-Z8-Z10-Z12-Z14-Z16-Z18-Z20-Z22-Z24-Z26-Z28-Z30-Z32 -> 8.9 | AA33: =39.1-AA4-AA6-AA8-AA10-AA12-AA14-AA16-AA18-AA20-AA22-AA24-AA26-AA28-AA30-AA32 -> 14.8 | AB33: =39.1-AB4-AB6-AB8-AB10-AB12-AB14-AB16-AB18-AB20-AB22-AB24-AB26-AB28-AB30-AB32 -> 29.2 | AC33: =39.1-AC4-AC6-AC8-AC10-AC12-AC14-AC16-AC18-AC20-AC22-AC24-AC26-AC28-AC30-AC32 -> 29.93 | AD33: =39.1-AD4-AD6-AD8-AD10-AD12-AD14-AD16-AD18-AD20-AD22-AD24-AD26-AD28-AD30-AD32 -> 7.56 | AE33: =39.1-AE4-AE6-AE8-AE10-AE12-AE14-AE16-AE18-AE20-AE22-AE24-AE26-AE28-AE30-AE32 -> 39.1 | AF33: =39.1-AF4-AF6-AF8-AF10-AF12-AF14-AF16-AF18-AF20-AF22-AF24-AF26-AF28-AF30-AF32 -> 39.1
S35: Hours changed to 37.8 per day | Z35: Hours changed to 39.1 per day

Sheet September
B1: 45901 | C1: 45902 | D1: 45903 | E1: 45904 | F1: 45905 | G1: 45906 | H1: 45907 | I1: 45908 | J1: 45909 | K1: 45910 | L1: 45911 | M1: 45912 | N1: 45913 | O1: 45914 | P1: 45915 | Q1: 45916 | R1: 45917 | S1: 45918 | T1: 45919 | U1: 45920 | V1: 45921 | W1: 45922 | X1: 45923 | Y1: 45924 | Z1: 45925 | AA1: 45926 | AB1: 45927 | AC1: 45928 | AD1: 45929 | AE1: 45930
A2: Total Hrs Booked | B2: =B4+B6+B8+B10+B12+B14+B16+B18+B20+B22+B24+B26+B28+B30+B32 -> 39.1 | C2: =C4+C6+C8+C10+C12+C14+C16+C18+C20+C22+C24+C26+C28+C30+C32 -> 35.56 | D2: =D4+D6+D8+D10+D12+D14+D16+D18+D20+D22+D24+D26+D28+D30+D32 -> 19.8 | E2: =E4+E6+E8+E10+E12+E14+E16+E18+E20+E22+E24+E26+E28+E30+E32 -> 35.44 | F2: =F4+F6+F8+F10+F12+F14+F16+F18+F20+F22+F24+F26+F28+F30+F32 -> 16.5 | G2: =G4+G6+G8+G10+G12+G14+G16+G18+G20+G22+G24+G26+G28+G30+G32 -> 0 | H2: =H4+H6+H8+H10+H12+H14+H16+H18+H20+H22+H24+H26+H28+H30+H32 -> 0 | I2: =I4+I6+I8+I10+I12+I14+I16+I18+I20+I22+I24+I26+I28+I30+I32 -> 37.9 | ... AE2: =AE4+AE6+AE8+AE10+AE12+AE14+AE16+AE18+AE20+AE22+AE24+AE26+AE28+AE30+AE32 -> 38.5
A3: Job No# | B3: Kitsets | C3: S-11268 | D3: S-11569 | E3: S-11494 | F3: S-11575 | I3: Kitsets | J3: S-11610 | K3: S-11630 | L3: S-11543 | M3: S-11325 | P3: Kitsets | Q3: S-10874 | R3: S-11055 | S3: S-11314 | T3: S-10897 | W3: Kitsets | X3: S-11674 | Y3: S-11356 | Z3: S-10197 | AA3: S-11735 | AD3: Kitsets | AE3: S-11453
A4: Time Allowed | B4: 20 | C4: 5.6 | D4: 3.5 | E4: 2.4 | F4: 3.2 | I4: 20 | J4: 4.6 | K4: 8.32 | L4: 7.28 | M4: 8.36 | Q4: 27 | R4: 19.4 | S4: 3.3 | T4: 28.2 | W4: 20 | X4: 2.77 | Y4: 8.6 | Z4: 15 | AA4: 2.6 | AD4: 0 | AE4: 20.8
A5: Job No# | B5: Kitset Pck | C5: S-10429 | D5: S-11578 | E5: S-11557 | F5: S-11181 | I5: Kitset Pck | J5: S-11614 | K5: S-11237 | L5: S-10768 | M5: S-11611 | P5: Kitset Pck | Q5: 11648 bkd | R5: S-11602 | S5: S-11655 | T5: 11602 Bkd | W5: Kitset Pck | X5: S-11240 | Y5: S-11357 | Z5: S-11184 | AA5: S-11703 | AD5: Kitset Pck | AE5: S-11454
A6: Time Allowed | B6: 5 | C6: 18.4 | D6: 9.8 | E6: 2.94 | F6: 4.1 | I6: 5 | J6: 2.6 | K6: 2.8 | L6: 4.62 | M6: 2.6 | P6: 5 | Q6: 11.5 | R6: 19.1 | S6: 1.5 | T6: 10.3 | W6: 5 | X6: 8.4 | Y6: 8.6 | Z6: 19 | AA6: 13.2 | AD6: 5 | AE6: 17.7
A7: Job No# | B7: S-11364 | C7: 11365 bkd | D7: S-11579 | E7: S-11562 | F7: S-11583 | I7: S-11411 | J7: S-11623 | K7: S-11238 | M7: S-11531 | P7: S-11617 | S7: S-10896 | W7: 11602 Bkd | X7: S-11607 | Y7: 11673 bkd | Z7: S-11559 | AA7: S-11689
A8: Time Allowed | B8: 7.4 | C8: 0.7 | D8: 1.5 | E8: 2.4 | F8: 4.9 | I8: 12.9 | J8: 2.2 | K8: 2.8 | M8: 4.1 | P8: 2.6 | S8: 33 | W8: 2.1 | X8: 3.3 | Y8: 10.3 | Z8: 2.83 | AA8: 8.4
A9: Job No# | B9: S-11365 | C9: S-10951 | D9: S-11584 | E9: S-11258 | F9: S-11587 | K9: S-11239 | L9: S-10818 | M9: S-11640 | P9: S-11648 | W9: S-11621 | X9: S-11672 | Y9: S-11693 | Z9: S-11714 | AA9: 11714 bkd | AD9: S-11705
A10: Time Allowed | B10: 6.7 | C10: 4.3 | D10: 2.4 | E10: 17.1 | F10: 2.1 | K10: 2.8 | L10: 18.4 | M10: 2.8 | P10: 16.1 | W10: 3.12 | X10: 9.8 | Y10: 5.6 | Z10: 1.2 | AA10: 4 | AD10: 2.8
A11: Job No# | C11: S-11565 | D11: S-11532 | E11: S-11566 | F11: S-11606 | L11: S-11658 | M11: S-11633 | P11: S-11659 | W11: S-11624 | X11: S-11673 | Y11: S-11692 | AA11: S-9228
A12: Time Allowed | C12: 4.16 | D12: 2.6 | E12: 5.6 | F12: 2.2 | L12: 4.3 | M12: 1.5 | P12: 1.9 | W12: 2.4 | X12: 14.3 | Y12: 3.3 | AA12: 2.6
A13: Job No# | C13: bkd hrs | E13: S-11587 | Y13: S-11712 | Z13: 11712 bkd | AA13: S-11257
A14: Time Allowed | C14: 2.4 | E14: 2.1 | Y14: 2.1 | Z14: 0.5 | AA14: 2.6
A15: Job No# | E15: S-11599 | W15: S-11707
A16: Time Allowed | E16: 2.9 | W16: 1.5
A17: Job No#
A18: Time Allowed
A19: Job No#
A20: Time Allowed
A21: Job No#
A22: Time Allowed
A23: Job No#
A24: Time Allowed
A25: Job No#
A26: Time Allowed
A27: Job No#
A28: Time Allowed
... A32: Time Allowed
A33: Spare Hours | B33: =39.1-B4-B6-B8-B10-B12-B14-B16-B18-B20-B22-B24-B26-B28-B30-B32 -> 8.8817842e-16 | C33: =38.55-C4-C6-C8-C10-C12-C14-C16-C18-C20-C22-C24-C26-C28-C30-C32 -> 2.99 | D33: =38.55-D4-D6-D8-D10-D12-D14-D16-D18-D20-D22-D24-D26-D28-D30-D32 -> 18.75 | E33: =38.55-E4-E6-E8-E10-E12-E14-E16-E18-E20-E22-E24-E26-E28-E30-E32 -> 3.11 | F33: =38.55-F4-F6-F8-F10-F12-F14-F16-F18-F20-F22-F24-F26-F28-F30-F32 -> 22.05 | G33: =38.55-G4-G6-G8-G10-G12-G14-G16-G18-G20-G22-G24-G26-G28-G30-G32 -> 38.55 | H33: =38.55-H4-H6-H8-H10-H12-H14-H16-H18-H20-H22-H24-H26-H28-H30-H32 -> 38.55 | I33: =38.55-I4-I6-I8-I10-I12-I14-I16-I18-I20-I22-I24-I26-I28-I30-I32 -> 0.65 | J33: =38.55-J4-J6-J8-J10-J12-J14-J16-J18-J20-J22-J24-J26-J28-J30-J32 -> 29.15 | ... AE33: =38.55-AE4-AE6-AE8-AE10-AE12-AE14-AE16-AE18-AE20-AE22-AE24-AE26-AE28-AE30-AE32 -> 0.05

Sheet October
B1: 45931 | C1: 45932 | D1: 45933 | E1: 45934 | F1: 45935 | G1: 45936 | H1: 45937 | I1: 45938 | J1: 45939 | K1: 45940 | L1: 45941 | M1: 45942 | N1: 45943 | O1: 45944 | P1: 45945 | Q1: 45946 | R1: 45947 | S1: 45948 | T1: 45949 | U1: 45950 | V1: 45951 | W1: 45952 | X1: 45953 | Y1: 45954 | Z1: 45955 | AA1: 45956 | AB1: 45957 | AC1: 45958 | AD1: 45959 | AE1: 45960 | AF1: 45961
A2: Total Hrs Booked | B2: =B4+B6+B8+B10+B12+B14+B16+B18+B20+B22+B24+B26+B28+B30+B32 -> 23.3 | C2: =C4+C6+C8+C10+C12+C14+C16+C18+C20+C22+C24+C26+C28+C30+C32 -> 31.8 | D2: =D4+D6+D8+D10+D12+D14+D16+D18+D20+D22+D24+D26+D28+D30+D32 -> 30.77 | E2: =E4+E6+E8+E10+E12+E14+E16+E18+E20+E22+E24+E26+E28+E30+E32 -> 0 | F2: =F4+F6+F8+F10+F12+F14+F16+F18+F20+F22+F24+F26+F28+F30+F32 -> 0 | G2: =G4+G6+G8+G10+G12+G14+G16+G18+G20+G22+G24+G26+G28+G30+G32 -> 31.8 | H2: =H4+H6+H8+H10+H12+H14+H16+H18+H20+H22+H24+H26+H28+H30+H32 -> 31.8 | I2: =I4+I6+I8+I10+I12+I14+I16+I18+I20+I22+I24+I26+I28+I30+I32 -> 31.8 | ... AF2: =AF4+AF6+AF8+AF10+AF12+AF14+AF16+AF18+AF20+AF22+AF24+AF26+AF28+AF30+AF32 -> 35.2
A3: Job No# | C3: S-11335 | D3: S-11643 | G3: Kitsets | H3: 11749 bkd | I3: S-11196 | J3: S-11682 | K3: S-11343 | N3: Kitsets | O3: S-11717 | P3: S-11839 | Q3: 11718 bkd | R3: S-11815 | U3: Kitsets | V3: S-11632 | W3: S-11742 | X3: S-11789 | Y3: S-11719 | AC3: Kitsets | AE3: 11912 bkd | AF3: S-11906
A4: Time Allowed | C4: 14.4 | D4: 5.1 | G4: 16 | H4: 13.1 | I4: 11.2 | J4: 4.5 | K4: 9.1 | N4: 9.6 | O4: 12.1 | P4: 5.2 | Q4: 21.1 | R4: 3.3 | U4: 0 | V4: 11.4 | W4: 5.2 | X4: 5.3 | Y4: 10.4 | AC4: 0 | AE4: 8 | AF4: 4
A5: Job No# | C5: 11455 bkd | D5: S-10428 | G5: Kitset Pck | H5: S-11748 | I5: S-11197 | J5: S-11722 | K5: S-11344 | N5: Kitset Pck | O5: S-11846 | P5: 11717 bkd | Q5: S-11843 | R5: S-11656 | U5: Kitset Pck | V5: S-11764 | W5: S-11835 | X5: S-11709 | Y5: S-11888 | AC5: Kitset Pck | AD5: S-11912 | AE5: Iline Land | AF5: S-11930
A6: Time Allowed | C6: 4.9 | D6: 18.4 | G6: 5 | H6: 18.7 | I6: 13.8 | J6: 2.8 | K6: 16.2 | N6: 5 | O6: 2.77 | P6: 1.7 | Q6: 1.56 | R6: 15.6 | U6: 5 | V6: 2.95 | W6: 6 | X6: 3.3 | Y6: 2.77 | AC6: 5 | AD6: 12.1 | AE6: 6.6 | AF6: 2.4
A7: Job No# | B7: S-11706 | C7: S-11076 | D7: 11076 bkd | G7: S-11749 | I7: 11748 bkd | J7: S-11588 | N7: S-11567 | O7: S-11847 | P7: S-11718 | Q7: S-11849 | R7: S-11831 | U7: S-11021 | V7: S-11812 | X7: S-11877 | Y7: S-11892 | AC7: S-11541 | AE7: S-11914
A8: Time Allowed | B8: 4.3 | C8: 12.5 | D8: 4.5 | G8: 6.8 | I8: 2.2 | J8: 7.3 | N8: 17.2 | O8: 5.54 | P8: 24.9 | Q8: 4.9 | R8: 3 | U8: 3.5 | V8: 1.7 | X8: 2.42 | Y8: 2.3 | AC8: 1.5 | AE8: 5.2
A9: Job No# | B9: 11454 Bkd | D9: S-11778 | G9: S-11790 | I9: S-11751 | J9: 11751 bkd | O9: S-11848 | Q9: S-11775 | R9: S-11832 | U9: S-11020 | W9: S-11567 | Y9: S-11893 | AE9: S-11913 | AF9: S-11923
A10: Time Allowed | B10: 3.1 | D10: 2.77 | G10: 4 | I10: 4.6 | J10: 15 | O10: 5.54 | Q10: 1.56 | R10: 2.6 | U10: 3.6 | W10: 11.9 | Y10: 2.7 | AE10: 5.2 | AF10: 6.9
A11: Job No# | B11: S-11455 | J11: S-11547 | K11: 11547 bkd | O11: S-11841 | Q11: S-11776 | R11: S-11834 | U11: S-11011 | W11: S-11879 | X11: S-11833 | Y11: S-11895 | AF11: S-11940
A12: Time Allowed | B12: 15.9 | J12: 2.2 | K12: 5.1 | O12: 3 | Q12: 1.62 | R12: 2.6 | U12: 19.7 | W12: 2.77 | X12: 4.6 | Y12: 2 | AF12: 21.9
A13: Job No# | K13: 11791 | O13: S-11858 | R13: 11791 bkd | W13: S-11905 | X13: S-11503 | Y13: 11503 bkd
A14: Time Allowed | K14: 1.4 | O14: 2 | R14: 1.2 | W14: 2.3 | X14: 12.8 | Y14: 2.2
A15: Job No# | O15: S-11689 | Q15: 11689 bkd | R15: S-11850 | V15: 11850 bkd | Y15: S-11880
A16: Time Allowed | O16: 0.9 | Q16: 1.1 | R16: 3.5 | V16: 0.8 | Y16: 5.6
A17: Job No#
A18: Time Allowed
A19: Job No#
A20: Time Allowed
A21: Job No#
A22: Time Allowed
A23: Job No#
A24: Time Allowed
A25: Job No#
A26: Time Allowed
A27: Job No#
A28: Time Allowed
... A32: Time Allowed
A33: Spare Hours | B33: =31.8-B4-B6-B8-B10-B12-B14-B16-B18-B20-B22-B24-B26-B28-B30-B32 -> 8.5 | C33: =31.8-C4-C6-C8-C10-C12-C14-C16-C18-C20-C22-C24-C26-C28-C30-C32 -> -1.7763568e-15 | D33: =31.8-D4-D6-D8-D10-D12-D14-D16-D18-D20-D22-D24-D26-D28-D30-D32 -> 1.03 | E33: =31.8-E4-E6-E8-E10-E12-E14-E16-E18-E20-E22-E24-E26-E28-E30-E32 -> 31.8 | F33: =31.8-F4-F6-F8-F10-F12-F14-F16-F18-F20-F22-F24-F26-F28-F30-F32 -> 31.8 | G33: =31.8-G4-G6-G8-G10-G12-G14-G16-G18-G20-G22-G24-G26-G28-G30-G32 -> 8.8817842e-16 | H33: =31.8-H4-H6-H8-H10-H12-H14-H16-H18-H20-H22-H24-H26-H28-H30-H32 -> 3.5527137e-15 | I33: =31.8-I4-I6-I8-I10-I12-I14-I16-I18-I20-I22-I24-I26-I28-I30-I32 -> 8.8817842e-16 | ... AA33: =31.8-AA4-AA6-AA8-AA10-AA12-AA14-AA16-AA18-AA20-AA22-AA24-AA26-AA28-AA30-AA32 -> 31.8 | AB33: =39.15-AB4-AB6-AB8-AB10-AB12-AB14-AB16-AB18-AB20-AB22-AB24-AB26-AB28-AB30-AB32 -> 39.15 | AC33: =39.15-AC4-AC6-AC8-AC10-AC12-AC14-AC16-AC18-AC20-AC22-AC24-AC26-AC28-AC30-AC32 -> 32.65 | AD33: =39.15-AD4-AD6-AD8-AD10-AD12-AD14-AD16-AD18-AD20-AD22-AD24-AD26-AD28-AD30-AD32 -> 27.05 | AE33: =39.15-AE4-AE6-AE8-AE10-AE12-AE14-AE16-AE18-AE20-AE22-AE24-AE26-AE28-AE30-AE32 -> 14.15 | AF33: =39.15-AF4-AF6-AF8-AF10-AF12-AF14-AF16-AF18-AF20-AF22-AF24-AF26-AF28-AF30-AF32 -> 3.95
AB34: Labour
B35: Gary away on Holiday | AB35: Day

Sheet November
B1: 45962 | C1: 45963 | D1: 45964 | E1: 45965 | F1: 45966 | G1: 45967 | H1: 45968 | I1: 45969 | J1: 45970 | K1: 45971 | L1: 45972 | M1: 45973 | N1: 45974 | O1: 45975 | P1: 45976 | Q1: 45977 | R1: 45978 | S1: 45979 | T1: 45980 | U1: 45981 | V1: 45982 | W1: 45983 | X1: 45984 | Y1: 45985 | Z1: 45986 | AA1: 45987 | AB1: 45988 | AC1: 45989 | AD1: 45990 | AE1: 45991
A2: Total Hrs Booked | B2: =B4+B6+B8+B10+B12+B14+B16+B18+B20+B22+B24+B26+B28+B30+B32 -> 0 | C2: =C4+C6+C8+C10+C12+C14+C16+C18+C20+C22+C24+C26+C28+C30+C32 -> 0 | D2: =D4+D6+D8+D10+D12+D14+D16+D18+D20+D22+D24+D26+D28+D30+D32 -> 38.5 | E2: =E4+E6+E8+E10+E12+E14+E16+E18+E20+E22+E24+E26+E28+E30+E32 -> 5.37 | F2: =F4+F6+F8+F10+F12+F14+F16+F18+F20+F22+F24+F26+F28+F30+F32 -> 24.01 | G2: =G4+G6+G8+G10+G12+G14+G16+G18+G20+G22+G24+G26+G28+G30+G32 -> 21.2 | H2: =H4+H6+H8+H10+H12+H14+H16+H18+H20+H22+H24+H26+H28+H30+H32 -> 13.12 | I2: =I4+I6+I8+I10+I12+I14+I16+I18+I20+I22+I24+I26+I28+I30+I32 -> 0 | ... AE2: =AE4+AE6+AE8+AE10+AE12+AE14+AE16+AE18+AE20+AE22+AE24+AE26+AE28+AE30+AE32 -> 0
A3: Job No# | D3: Kitsets | E3: S-11890 | F3: S-11702 | G3: S-11884 | H3: S-11914 | K3: Kitsets | L3: S-11761 | M3: S-11752 | N3: S-11452 | O3: S-11528 | R3: Kitsets | S3: S-11249 | T3: 11251 bkd | U3: S-11552 | V3: 11552 bkd | Y3: Kitsets | Z3: S-11907
A4: Time Allowed | D4: 20 | E4: 2.77 | F4: 2.6 | G4: 8.53 | H4: 5.52 | K4: 20 | L4: 21.5 | M4: 2.8 | N4: 5.8 | O4: 17.1 | R4: 20 | S4: 18.4 | T4: 6.8 | U4: 39.2 | V4: 20.6 | Y4: 20 | Z4: 30
A5: Job No# | D5: Kitset Pck | E5: S-11941 | F5: S-11946 | G5: S-11913 | K5: Kitset Pck | L5: 11915 bkd | M5: 11935 bkd | N5: S-11942 | O5: S-11809 | R5: Kitset Pck | S5: S-11250 | T5: S-11252 | V5: S-11891 | Y5: Kitset Pck | Z5: S-11990 | AB5: S-11837
A6: Time Allowed | D6: 4.2 | E6: 2.6 | F6: 5.6 | G6: 5.52 | K6: 5 | L6: 10.4 | M6: 14.4 | N6: 2.6 | O6: 2.77 | R6: 5 | S6: 13.8 | T6: 11.2 | V6: 2.77 | Y6: 5 | Z6: 2.6 | AB6: 2.6
A7: Job No# | D7: S-11787 | E7: S-11937 | F7: S-11947 | G7: S-11862 | H7: S-11999 | K7: S-11788 | L7: S-11935 | M7: S-11960 | O7: S-11862 | S7: S-11251 | T7: bkd hrs | V7: S-11690 | Y7: S-11697
A8: Time Allowed | D8: 2.6 | F8: 2.77 | G8: 3.35 | H8: 5.2 | K8: 2.95 | L8: 6.6 | M8: 2.93 | O8: 3.35 | S8: 7 | T8: 1.4 | V8: 5.2 | Y8: 11.2
A9: Job No# | D9: 11940 bkd | F9: S-11955 | G9: S-11998 | H9: S-11952 | K9: S-11915 | M9: S-11403 | O9: S-11916 | R9: S-11589 | T9: S-11836
A10: Time Allowed | D10: 11.7 | F10: 2.2 | G10: 2.6 | H10: 2.4 | K10: 10.6 | M10: 10.4 | O10: 5.2 | R10: 5.8 | T10: 2.6
A11: Job No# | F11: S-11972 | G11: S-12018
A12: Time Allowed | F12: 3.12 | G12: 1.2
A13: Job No# | F13: S-11976
A14: Time Allowed | F14: 4.6
A15: Job No# | F15: S-11991
A16: Time Allowed | F16: 3.12
A17: Job No#
A18: Time Allowed
A19: Job No#
A20: Time Allowed
A21: Job No#
A22: Time Allowed
A23: Job No#
A24: Time Allowed
A25: Job No#
A26: Time Allowed
A27: Job No#
A28: Time Allowed
... A32: Time Allowed
A33: Spare Hours | B33: =38.55-B4-B6-B8-B10-B12-B14-B16-B18-B20-B22-B24-B26-B28-B30-B32 -> 38.55 | C33: =38.55-C4-C6-C8-C10-C12-C14-C16-C18-C20-C22-C24-C26-C28-C30-C32 -> 38.55 | D33: =38.55-D4-D6-D8-D10-D12-D14-D16-D18-D20-D22-D24-D26-D28-D30-D32 -> 0.05 | E33: =38.55-E4-E6-E8-E10-E12-E14-E16-E18-E20-E22-E24-E26-E28-E30-E32 -> 33.18 | F33: =38.55-F4-F6-F8-F10-F12-F14-F16-F18-F20-F22-F24-F26-F28-F30-F32 -> 14.54 | G33: =38.55-G4-G6-G8-G10-G12-G14-G16-G18-G20-G22-G24-G26-G28-G30-G32 -> 17.35 | H33: =38.55-H4-H6-H8-H10-H12-H14-H16-H18-H20-H22-H24-H26-H28-H30-H32 -> 25.43 | I33: =38.55-I4-I6-I8-I10-I12-I14-I16-I18-I20-I22-I24-I26-I28-I30-I32 -> 38.55 | ... AE33: =38.55-AE4-AE6-AE8-AE10-AE12-AE14-AE16-AE18-AE20-AE22-AE24-AE26-AE28-AE30-AE32 -> 38.55

Sheet December
