Workbook

Sheet CALCULATOR (Hudson)
B1: GP CALCULATOR | K1: Stair 1 | L1: Handrail | M1: Brackets | O1: Stair 2 | P1: Handrail | Q1: Brackets
C2: Type | D2: Tread | E2: Size | F2: COST | K2: Length 1 | O2: Length 1
F3: Quantity | G3: Unit Cost | H3: Total | K3: Length 2 | O3: Length 2
B4: Stair 1 | C4: PINE/MDF (Cut-under 300x40) | D4: Up to 300mm | E4: 1.1m | F4: 18 | G4: =SUMIFS(MASTER!D3:D338,MASTER!A3:A338,'CALCULATOR (Hudson)'!$C$4,MASTER!B3:B338,'CALCULATOR (Hudson)'!$D$4,MASTER!C3:C338,'CALCULATOR (Hudson)'!$E$4) -> 27.862916 | H4: =(F4*G4) -> 501.53249 | K4: Length 3 | O4: Length 3
B5: Winders | G5: =SUMIFS(MASTER!D3:D338,MASTER!A3:A338,'CALCULATOR (Hudson)'!$C$5,MASTER!B3:B338,'CALCULATOR (Hudson)'!$D$5,MASTER!C3:C338,'CALCULATOR (Hudson)'!$E$5) -> 0 | H5: =(F5*G5) -> 0 | K5: Length 4 | O5: Length 4
B6: Landings | C6: LANDING | D6: MDF | E6: 1.0m2 | F6: 1 | G6: =SUMIFS(MASTER!D3:D338,MASTER!A3:A338,'CALCULATOR (Hudson)'!$C$6,MASTER!B3:B338,'CALCULATOR (Hudson)'!$D$6,MASTER!C3:C338,'CALCULATOR (Hudson)'!$E$6) -> 123.7381 | H6: =(F6*G6) -> 123.7381 | K6: Length 5 | O6: Length 5
B7: Custom | G7: 0 | H7: =(F7*G7) -> 0 | K7: Length 6 | O7: Length 6
B8: Stair 2 | G8: =SUMIFS(MASTER!D3:D338,MASTER!A3:A338,'CALCULATOR (Hudson)'!$C$8,MASTER!B3:B338,'CALCULATOR (Hudson)'!$D$8,MASTER!C3:C338,'CALCULATOR (Hudson)'!$E$8) -> 0 | H8: =(F8*G8) -> 0 | K8: Total | L8: =SUM(L2:L7) -> 0 | M8: =SUM(M2:M7) -> 0 | O8: Total | P8: =SUM(P2:P7) -> 0 | Q8: =SUM(Q2:Q7) -> 0
B9: Winders | G9: =SUMIFS(MASTER!D3:D338,MASTER!A3:A338,'CALCULATOR (Hudson)'!$C$9,MASTER!B3:B338,'CALCULATOR (Hudson)'!$D$9,MASTER!C3:C338,'CALCULATOR (Hudson)'!$E$9) -> 0 | H9: =(F9*G9) -> 0 | K9: No. of Units | O9: No. of Units
B10: Landings | G10: =SUMIFS(MASTER!D3:D338,MASTER!A3:A338,'CALCULATOR (Hudson)'!$C$10,MASTER!B3:B338,'CALCULATOR (Hudson)'!$D$10,MASTER!C3:C338,'CALCULATOR (Hudson)'!$E$10) -> 0 | H10: =(F10*G10) -> 0 | K10: Total | L10: =L8*L9 -> 0 | M10: =M8*M9 -> 0 | O10: Total | P10: =P8*P9 -> 0 | Q10: =Q8*Q9 -> 0
B11: Custom | G11: 0 | H11: =(F11*G11) -> 0
B12: Pallet | F12: 1 | G12: 18 | H12: =(F12*G12) -> 18
B13: Site Measure-up | C13: Region | D13: Contact | E13: Rate | G13: =E14 -> 85 | H13: =(F13*G13) -> 0
C14: =F28 -> CANTERBURY | D14: =VLOOKUP(C14,'MEASURE UP''S'!$A$1:$B$31,2,FALSE) -> DKNZ | E14: =VLOOKUP(D14,'MEASURE UP''S'!$B$1:$C$30,2,FALSE) -> 85
B15: Drawings | F15: 10 | G15: 1.58 | H15: =(F15*G15) -> 15.8
B17: Freight | C17: Total Cube (m²) | D17: Total Weight (kg) | E17: Total Freight Cost | F17: No. of Units | H17: =(E18/F18) -> 1170.36
C18: 3.498 | D18: 200 | E18: 1170.36 | F18: 1
B20: TOTAL COST | H20: =SUM(H4:H18) -> 1829.4306
B23: GP% BY REGION | C23: (for new customers and those that don't from Top Flyte Stairs currently) | E23: Top Flyte Take Off Sheet: CONFIDENTIAL
B24: GP% | C24: =VLOOKUP(F28,REGIONS!$A:$B,2,FALSE) -> 0.4 | E24: Date: | F24: 45964
B25: Sell Price | C25: =(H20/(1-C24)) -> 3049.051 | E25: Wholesaler
E26: Onsite Builder: | F26: Keenan Construction
B27: CUSTOM - SELL | E27: Site Address: | F27: 4456 Christchurch Akaroa Road, Little River
B28: GP% | C28: 0.4 | E28: Region * | F28: CANTERBURY
B29: Sell Price | C29: =(H20/(1-C28)) -> 3049.051 | E29: Stair Type: | F29: Internal
E30: Classify | F30: Main
E32: Job Number (s): | F32: Lang Residence
E33: Job Number (s): | F33: With landing
E34: Job Number (s):
E35: Job Number (s):
E36: Job Number (s):

Sheet CALCULATOR (Jude)
B1: GP CALCULATOR | K1: Stair 1 | L1: Handrail | M1: Brackets | O1: Stair 2 | P1: Handrail | Q1: Brackets
C2: Type | D2: Tread | E2: Size | F2: COST | K2: Length 1 | O2: Length 1
F3: Quantity | G3: Unit Cost | H3: Total | K3: Length 2 | O3: Length 2
B4: Stair 1 | C4: PINE/MDF (250x40) | D4: Up to 300mm | E4: 1.0m | F4: 15 | G4: =SUMIFS(MASTER!D3:D338,MASTER!A3:A338,'CALCULATOR (Jude)'!$C$4,MASTER!B3:B338,'CALCULATOR (Jude)'!$D$4,MASTER!C3:C338,'CALCULATOR (Jude)'!$E$4) -> 24.353986 | H4: =(F4*G4) -> 365.30978 | K4: Length 3 | O4: Length 3
B5: Winders | G5: =SUMIFS(MASTER!D3:D338,MASTER!A3:A338,'CALCULATOR (Jude)'!$C$5,MASTER!B3:B338,'CALCULATOR (Jude)'!$D$5,MASTER!C3:C338,'CALCULATOR (Jude)'!$E$5) -> 0 | H5: =(F5*G5) -> 0 | K5: Length 4 | O5: Length 4
B6: Landings | G6: =SUMIFS(MASTER!D3:D338,MASTER!A3:A338,'CALCULATOR (Jude)'!$C$6,MASTER!B3:B338,'CALCULATOR (Jude)'!$D$6,MASTER!C3:C338,'CALCULATOR (Jude)'!$E$6) -> 0 | H6: =(F6*G6) -> 0 | K6: Length 5 | O6: Length 5
B7: Custom | G7: 0 | H7: =(F7*G7) -> 0 | K7: Length 6 | O7: Length 6
B8: Stair 2 | G8: =SUMIFS(MASTER!D3:D338,MASTER!A3:A338,'CALCULATOR (Jude)'!$C$8,MASTER!B3:B338,'CALCULATOR (Jude)'!$D$8,MASTER!C3:C338,'CALCULATOR (Jude)'!$E$8) -> 0 | H8: =(F8*G8) -> 0 | K8: Total | L8: =SUM(L2:L7) -> 0 | M8: =SUM(M2:M7) -> 0 | O8: Total | P8: =SUM(P2:P7) -> 0 | Q8: =SUM(Q2:Q7) -> 0
B9: Winders | G9: =SUMIFS(MASTER!D3:D338,MASTER!A3:A338,'CALCULATOR (Jude)'!$C$9,MASTER!B3:B338,'CALCULATOR (Jude)'!$D$9,MASTER!C3:C338,'CALCULATOR (Jude)'!$E$9) -> 0 | H9: =(F9*G9) -> 0 | K9: No. of Units | O9: No. of Units
B10: Landings | G10: =SUMIFS(MASTER!D3:D338,MASTER!A3:A338,'CALCULATOR (Jude)'!$C$10,MASTER!B3:B338,'CALCULATOR (Jude)'!$D$10,MASTER!C3:C338,'CALCULATOR (Jude)'!$E$10) -> 0 | H10: =(F10*G10) -> 0 | K10: Total | L10: =L8*L9 -> 0 | M10: =M8*M9 -> 0 | O10: Total | P10: =P8*P9 -> 0 | Q10: =Q8*Q9 -> 0
B11: Custom | G11: 0 | H11: =(F11*G11) -> 0
B12: Pallet | F12: 1 | G12: 18 | H12: =(F12*G12) -> 18
B13: Site Measure-up | C13: Region | D13: Contact | E13: Rate | F13: 1.5 | G13: =E14 -> 95 | H13: =(F13*G13) -> 142.5
C14: =F28 -> AUCKLAND | D14: =VLOOKUP(C14,'MEASURE UP''S'!$A$1:$B$31,2,FALSE) -> TOP FLYTE STAIRS | E14: =VLOOKUP(D14,'MEASURE UP''S'!$B$1:$C$30,2,FALSE) -> 95
B15: Drawings | F15: 10 | G15: 1.58 | H15: =(F15*G15) -> 15.8
B17: Freight | C17: Total Cube (m²) | D17: Total Weight (kg) | E17: Total Freight Cost | F17: No. of Units | H17: =(E18/F18) -> 436.03
C18: 4.62 | D18: 380 | E18: 872.06 | F18: 2
B20: TOTAL COST | H20: =SUM(H4:H18) -> 977.63978
B23: GP% BY REGION | C23: (for new customers and those that don't from Top Flyte Stairs currently) | E23: Top Flyte Take Off Sheet: CONFIDENTIAL
B24: GP% | C24: =VLOOKUP(F28,REGIONS!$A:$B,2,FALSE) -> 0.35 | E24: Date: | F24: 45776
B25: Sell Price | C25: =(H20/(1-C24)) -> 1504.0612 | E25: Wholesaler | F25: Carters Madras Street
E26: Onsite Builder:
B27: CUSTOM - SELL | E27: Site Address: | F27: 157 Milton Street, Somerfield, Christchurch 8024
B28: GP% | C28: 0.5 | E28: Region * | F28: AUCKLAND
B29: Sell Price | C29: =(H20/(1-C28)) -> 1955.2796 | E29: Stair Type: | F29: Internal
E30: Classify | F30: Secondary
E32: Job Number (s): | F32: CH1431566E1 - Unit 1-2
E33: Job Number (s):
E34: Job Number (s):
E35: Job Number (s):
E36: Job Number (s):
E37: Job Number (s):

Sheet CALCULATOR (Courtney)
A1: {=J16A1:J33} -> #NAME? | B1: GP CALCULATOR | K1: Stair 1 | L1: Handrail | M1: Brackets | O1: Stair 2 | P1: Handrail | Q1: Brackets
C2: Type | D2: Tread | E2: Size | F2: COST | K2: Length 1 | O2: Length 1
F3: Quantity | G3: Unit Cost | H3: Total | K3: Length 2 | O3: Length 2
B4: Stair 1 | C4: PINE/MDF (250x40) | D4: Up to 300mm | E4: 1.4m | F4: 17 | G4: =SUMIFS(MASTER!D3:D338,MASTER!A3:A338,'CALCULATOR (Courtney)'!$C$4,MASTER!B3:B338,'CALCULATOR (Courtney)'!$D$4,MASTER!C3:C338,'CALCULATOR (Courtney)'!$E$4) -> 32.983582 | H4: =(F4*G4) -> 560.72089 | K4: Length 3 | O4: Length 3
B5: Winders | G5: =SUMIFS(MASTER!D3:D338,MASTER!A3:A338,'CALCULATOR (Courtney)'!$C$5,MASTER!B3:B338,'CALCULATOR (Courtney)'!$D$5,MASTER!C3:C338,'CALCULATOR (Courtney)'!$E$5) -> 0 | H5: =(F5*G5) -> 0 | K5: Length 4 | O5: Length 4
B6: Landings | G6: =SUMIFS(MASTER!D3:D338,MASTER!A3:A338,'CALCULATOR (Courtney)'!$C$6,MASTER!B3:B338,'CALCULATOR (Courtney)'!$D$6,MASTER!C3:C338,'CALCULATOR (Courtney)'!$E$6) -> 0 | H6: =(F6*G6) -> 0 | K6: Length 5 | O6: Length 5
B7: Custom | G7: 0 | H7: =(F7*G7) -> 0 | K7: Length 6 | O7: Length 6
B8: Stair 2 | C8: PINE/MDF (250x40) | D8: Up to 300mm | E8: 1.0m | F8: 5 | G8: =SUMIFS(MASTER!D3:D338,MASTER!A3:A338,'CALCULATOR (Courtney)'!$C$8,MASTER!B3:B338,'CALCULATOR (Courtney)'!$D$8,MASTER!C3:C338,'CALCULATOR (Courtney)'!$E$8) -> 24.353986 | H8: =(F8*G8) -> 121.76993 | K8: Total | L8: =SUM(L2:L7) -> 0 | M8: =SUM(M2:M7) -> 0 | O8: Total | P8: =SUM(P2:P7) -> 0 | Q8: =SUM(Q2:Q7) -> 0
B9: Winders | G9: =SUMIFS(MASTER!D3:D338,MASTER!A3:A338,'CALCULATOR (Courtney)'!$C$9,MASTER!B3:B338,'CALCULATOR (Courtney)'!$D$9,MASTER!C3:C338,'CALCULATOR (Courtney)'!$E$9) -> 0 | H9: =(F9*G9) -> 0 | K9: No. of Units | O9: No. of Units
B10: Landings | G10: =SUMIFS(MASTER!D3:D338,MASTER!A3:A338,'CALCULATOR (Courtney)'!$C$10,MASTER!B3:B338,'CALCULATOR (Courtney)'!$D$10,MASTER!C3:C338,'CALCULATOR (Courtney)'!$E$10) -> 0 | H10: =(F10*G10) -> 0 | K10: Total | L10: =L8*L9 -> 0 | M10: =M8*M9 -> 0 | O10: Total | P10: =P8*P9 -> 0 | Q10: =Q8*Q9 -> 0
B11: Custom | G11: 0 | H11: =(F11*G11) -> 0
B12: Pallet | F12: 1 | G12: 18 | H12: =(F12*G12) -> 18
B13: Site Measure-up | C13: Region | D13: Contact | E13: Rate | F13: 2 | G13: =E14 -> 95 | H13: =(F13*G13) -> 190
C14: =F28 -> BAY OF PLENTY | D14: =VLOOKUP(C14,'MEASURE UP''S'!$A$1:$B$31,2,FALSE) -> TOP FLYTE STAIRS | E14: =VLOOKUP(D14,'MEASURE UP''S'!$B$1:$C$30,2,FALSE) -> 95
B15: Drawings | F15: 10 | G15: 1.58 | H15: =(F15*G15) -> 15.8
B17: Freight | C17: Total Cube (m²) | D17: Weight (kg) | E17: Total Freight Cost | F17: No. of Units | H17: =(E18/F18) -> 84.22
C18: 3.5 | D18: 220 | E18: 84.22 | F18: 1
B20: TOTAL COST | H20: =SUM(H4:H18) -> 990.51082
B23: GP% BY REGION | C23: (for new customers and those that don't from Top Flyte Stairs currently) | E23: Top Flyte Take Off Sheet: CONFIDENTIAL
B24: GP% | C24: =VLOOKUP(F28,REGIONS!$A:$B,2,FALSE) -> 0.6 | E24: Date: | F24: 45965 | S24: QF | T24: 19
B25: Sell Price | C25: =(H20/(1-C24)) -> 2476.277 | E25: Wholesaler | S25: Q | T25: 4
E26: Onsite Builder: | F26: Belco Homes | S26: Orders Processed | T26: 2
B27: CUSTOM - SELL | E27: Site Address: | F27: 24 Rutherford Street, Otumoetai | S27: Kitset Processed | T27: 2
B28: GP% | C28: 0.4 | E28: Region * | F28: BAY OF PLENTY
B29: Sell Price | C29: =(H20/(1-C28)) -> 1650.8514 | E29: Stair Type: | F29: Internal
E30: Classify | F30: Main
E32: Job Number (s): | F32: Strong Residence
E33: Job Number (s):
E34: Job Number (s):
E35: Job Number (s):
E36: Job Number (s):

Sheet MASTER
A1: TYPE | B1: SIZE | C1: WIDTH | D1: TOTAL COST (divided by 10 Risers) | E1: WHOLESALE | F1: RETAIL
A3: PINE/MDF (250x40) | B3: Up to 300mm | C3: 0.9m | D3: ='BPSC. (+ Ply)'!G6 -> 23.084652 | E3: ='BPSC (+ Ply)'!D6 -> 73.553683 | F3: ='BPSC (+ Ply)'!F6 -> 81.726315
A4: PINE/MDF (250x40) | B4: Up to 300mm | C4: 1.0m | D4: ='BPSC. (+ Ply)'!G7 -> 24.353986 | E4: ='BPSC (+ Ply)'!D7 -> 76.841959 | F4: ='BPSC (+ Ply)'!F7 -> 85.379955
A5: PINE/MDF (250x40) | B5: Up to 300mm | C5: 1.1m | D5: ='BPSC. (+ Ply)'!G8 -> 24.683986 | E5: ='BPSC (+ Ply)'!D8 -> 79.246377 | F5: ='BPSC (+ Ply)'!F8 -> 88.05153
A6: PINE/MDF (250x40) | B6: Up to 300mm | C6: 1.2m | D6: ='BPSC. (+ Ply)'!G9 -> 24.683986 | E6: ='BPSC (+ Ply)'!D9 -> 81.523186 | F6: ='BPSC (+ Ply)'!F9 -> 90.581317
A7: PINE/MDF (250x40) | B7: Up to 300mm | C7: 1.4m | D7: ='BPSC. (+ Ply)'!G10 -> 32.983582 | E7: ='BPSC (+ Ply)'!D10 -> 89.073594 | F7: ='BPSC (+ Ply)'!F10 -> 98.97066
A8: PINE/MDF (250x40) | B8: Up to 300mm | C8: 1.6m | D8: ='BPSC. (+ Ply)'!G11 -> 38.290242 | E8: ='BPSC (+ Ply)'!D11 -> 92.826634 | F8: ='BPSC (+ Ply)'!F11 -> 103.1407
A9: PINE/MDF (250x40) | B9: Up to 300mm | C9: 2.0m | D9: ='BPSC. (+ Ply)'!G12 -> 45.041568 | E9: ='BPSC (+ Ply)'!D12 -> 117.92041 | F9: ='BPSC (+ Ply)'!F12 -> 131.02267
A11: PINE/MDF (250x40) | B11: Over 300mm | C11: 0.9m | D11: ='BPSC. (+ Ply)'!G17 -> 25.249986 | E11: ='BPSC (+ Ply)'!D17 -> 79.163095 | F11: ='BPSC (+ Ply)'!F17 -> 87.958995
A12: PINE/MDF (250x40) | B12: Over 300mm | C12: 1.0m | D12: ='BPSC. (+ Ply)'!G18 -> 25.249986 | E12: ='BPSC (+ Ply)'!D18 -> 79.295697 | F12: ='BPSC (+ Ply)'!F18 -> 88.10633
A13: PINE/MDF (250x40) | B13: Over 300mm | C13: 1.1m | D13: ='BPSC. (+ Ply)'!G19 -> 25.579986 | E13: ='BPSC (+ Ply)'!D19 -> 81.567513 | F13: ='BPSC (+ Ply)'!F19 -> 90.63057
A14: PINE/MDF (250x40) | B14: Over 300mm | C14: 1.2m | D14: ='BPSC. (+ Ply)'!G20 -> 25.579986 | E14: ='BPSC (+ Ply)'!D20 -> 83.844322 | F14: ='BPSC (+ Ply)'!F20 -> 93.160358
A15: PINE/MDF (250x40) | B15: Over 300mm | C15: 1.4m | D15: ='BPSC. (+ Ply)'!G21 -> 35.447582 | E15: ='BPSC (+ Ply)'!D21 -> 95.456718 | F15: ='BPSC (+ Ply)'!F21 -> 106.06302
A16: PINE/MDF (250x40) | B16: Over 300mm | C16: 1.6m | D16: ='BPSC. (+ Ply)'!G22 -> 41.099575 | E16: ='BPSC (+ Ply)'!D22 -> 100.10436 | F16: ='BPSC (+ Ply)'!F22 -> 111.22707
A17: PINE/MDF (250x40) | B17: Over 300mm | C17: 2.0m | D17: ='BPSC. (+ Ply)'!G23 -> 48.550902 | E17: ='BPSC (+ Ply)'!D23 -> 127.51405 | F17: ='BPSC (+ Ply)'!F23 -> 141.68227
A19: PINE/PLY (250x40) | B19: Up to 300mm | C19: 0.9m | D19: ='BPSC. (+ Ply)'!O6 -> 26.930652 | E19: ='BPSC (+ Ply)'!P6 -> 79.881795 | F19: ='BPSC (+ Ply)'!R6 -> 88.75755
A20: PINE/PLY (250x40) | B20: Up to 300mm | C20: 1.0m | D20: ='BPSC. (+ Ply)'!O7 -> 28.769319 | E20: ='BPSC (+ Ply)'!P7 -> 85.94289 | F20: ='BPSC (+ Ply)'!R7 -> 95.4921
A21: PINE/PLY (250x40) | B21: Up to 300mm | C21: 1.1m | D21: ='BPSC. (+ Ply)'!O8 -> 29.359319 | E21: ='BPSC (+ Ply)'!P8 -> 87.392115 | F21: ='BPSC (+ Ply)'!R8 -> 97.10235
A22: PINE/PLY (250x40) | B22: Up to 300mm | C22: 1.2m | D22: ='BPSC. (+ Ply)'!O9 -> 29.359319 | E22: ='BPSC (+ Ply)'!P9 -> 89.565952 | F22: ='BPSC (+ Ply)'!R9 -> 99.517725
A23: PINE/PLY (250x40) | B23: Up to 300mm | C23: 1.4m | D23: ='BPSC. (+ Ply)'!O10 -> 38.434248 | E23: ='BPSC (+ Ply)'!P10 -> 98.719155 | F23: ='BPSC (+ Ply)'!R10 -> 109.68795
A24: PINE/PLY (250x40) | B24: Up to 300mm | C24: 1.6m | D24: ='BPSC. (+ Ply)'!O11 -> 44.526908 | E24: ='BPSC (+ Ply)'!P11 -> 104.27495 | F24: ='BPSC (+ Ply)'!R11 -> 115.86105
A25: PINE/PLY (250x40) | B25: Up to 300mm | C25: 2.0m | D25: ='BPSC. (+ Ply)'!O12 -> 52.830235 | E25: ='BPSC (+ Ply)'!P12 -> 126.23006 | F25: ='BPSC (+ Ply)'!R12 -> 140.25563
A27: PINE/PLY (250x40) | B27: Over 300mm | C27: 0.9m | D27: ='BPSC. (+ Ply)'!O17 -> 30.075986 | E27: ='BPSC (+ Ply)'!P17 -> 87.66144 | F27: ='BPSC (+ Ply)'!R17 -> 97.4016
A28: PINE/PLY (250x40) | B28: Over 300mm | C28: 1.0m | D28: ='BPSC. (+ Ply)'!O18 -> 30.075986 | E28: ='BPSC (+ Ply)'!P18 -> 89.17479 | F28: ='BPSC (+ Ply)'!R18 -> 99.0831
A29: PINE/PLY (250x40) | B29: Over 300mm | C29: 1.1m | D29: ='BPSC. (+ Ply)'!O19 -> 30.665986 | E29: ='BPSC (+ Ply)'!P19 -> 90.624015 | F29: ='BPSC (+ Ply)'!R19 -> 100.69335
A30: PINE/PLY (250x40) | B30: Over 300mm | C30: 1.2m | D30: ='BPSC. (+ Ply)'!O20 -> 30.665986 | E30: ='BPSC (+ Ply)'!P20 -> 92.797853 | F30: ='BPSC (+ Ply)'!R20 -> 103.10873
A31: PINE/PLY (250x40) | B31: Over 300mm | C31: 1.4m | D31: ='BPSC. (+ Ply)'!O21 -> 41.999582 | E31: ='BPSC (+ Ply)'!P21 -> 107.53762 | F31: ='BPSC (+ Ply)'!R21 -> 119.48625
A32: PINE/PLY (250x40) | B32: Over 300mm | C32: 1.6m | D32: ='BPSC. (+ Ply)'!O22 -> 48.605575 | E32: ='BPSC (+ Ply)'!P22 -> 114.36309 | F32: ='BPSC (+ Ply)'!R22 -> 127.0701
A33: PINE/PLY (250x40) | B33: Over 300mm | C33: 2.0m | D33: ='BPSC. (+ Ply)'!O23 -> 57.926235 | E33: ='BPSC (+ Ply)'!P23 -> 138.83447 | F33: ='BPSC (+ Ply)'!R23 -> 154.26053
A35: PINE/MDF (300x40) | B35: Up to 300mm | C35: 0.9m | D35: ='BPSC. (+ Ply)'!G31 -> 24.650252 | E35: ='BPSC (+ Ply)'!D31 -> 77.844627 | F35: ='BPSC (+ Ply)'!F31 -> 86.49403
A36: PINE/MDF (300x40) | B36: Up to 300mm | C36: 1.0m | D36: ='BPSC. (+ Ply)'!G32 -> 25.919586 | E36: ='BPSC (+ Ply)'!D32 -> 81.132985 | F36: ='BPSC (+ Ply)'!F32 -> 90.147761
A37: PINE/MDF (300x40) | B37: Up to 300mm | C37: 1.1m | D37: ='BPSC. (+ Ply)'!G33 -> 26.249586 | E37: ='BPSC (+ Ply)'!D33 -> 83.537463 | F37: ='BPSC (+ Ply)'!F33 -> 92.819403
A38: PINE/MDF (300x40) | B38: Up to 300mm | C38: 1.2m | D38: ='BPSC. (+ Ply)'!G34 -> 26.249586 | E38: ='BPSC (+ Ply)'!D34 -> 85.814328 | F38: ='BPSC (+ Ply)'!F34 -> 95.349254
A39: PINE/MDF (300x40) | B39: Up to 300mm | C39: 1.4m | D39: ='BPSC. (+ Ply)'!G35 -> 34.549182 | E39: ='BPSC (+ Ply)'!D35 -> 93.364925 | F39: ='BPSC (+ Ply)'!F35 -> 103.73881
A40: PINE/MDF (300x40) | B40: Up to 300mm | C40: 1.6m | D40: ='BPSC. (+ Ply)'!G36 -> 39.855842 | E40: ='BPSC (+ Ply)'!D36 -> 97.11806 | F40: ='BPSC (+ Ply)'!F36 -> 107.90896
A41: PINE/MDF (300x40) | B41: Up to 300mm | C41: 2.0m | D41: ='BPSC. (+ Ply)'!G37 -> 46.607168 | E41: ='BPSC (+ Ply)'!D37 -> 116.03552 | F41: ='BPSC (+ Ply)'!F37 -> 128.92836
A43: PINE/MDF (300x40) | B43: Over 300mm | C43: 0.9m | D43: ='BPSC. (+ Ply)'!G42 -> 26.815586 | E43: ='BPSC (+ Ply)'!D42 -> 83.454179 | F43: ='BPSC (+ Ply)'!F42 -> 92.726866
A44: PINE/MDF (300x40) | B44: Over 300mm | C44: 1.0m | D44: ='BPSC. (+ Ply)'!G43 -> 26.815586 | E44: ='BPSC (+ Ply)'!D43 -> 83.454179 | F44: ='BPSC (+ Ply)'!F43 -> 92.726866
A45: PINE/MDF (300x40) | B45: Over 300mm | C45: 1.1m | D45: ='BPSC. (+ Ply)'!G44 -> 27.145586 | E45: ='BPSC (+ Ply)'!D44 -> 85.858657 | F45: ='BPSC (+ Ply)'!F44 -> 95.398507
A46: PINE/MDF (300x40) | B46: Over 300mm | C46: 1.2m | D46: ='BPSC. (+ Ply)'!G45 -> 27.145586 | E46: ='BPSC (+ Ply)'!D45 -> 88.135522 | F46: ='BPSC (+ Ply)'!F45 -> 97.928358
...

Sheet NDL FREIGHT CALCULATOR
A1: Top Flyte Rates
B3: Base rate | C3: M3 rate | D3: Total M3 | E3: Cost | F3: FAF | G3: Cost plus FAF
A4: Tauranga /Mount | B4: 25 | C4: 12.5 | D4: =F18 -> 4.29 | E4: =SUM(B4 + (D4*C4)) -> 78.625 | F4: 1.225 | G4: =SUM(E4*F4) -> 96.315625
A6: Papamoa/Omokoroa | B6: 30 | C6: 14 | D6: =F18 -> 4.29 | E6: =SUM(B6 + (D6*C6)) -> 90.06 | F6: 1.225 | G6: =SUM(E6*F6) -> 110.3235
A8: Katikati/TePuke | B8: 35 | C8: 15.5 | D8: =F18 -> 4.29 | E8: =SUM(B8 + (D8*C8)) -> 101.495 | F8: 1.225 | G8: =SUM(E8*F8) -> 124.33138
A12: Cube Calculator | B12: Quantity | C12: Length | D12: Width | E12: Height | F12: Cube M3 | G12: Weight KG
A13: Line 1 | B13: 1 | C13: 5.5 | D13: 1.3 | E13: 0.6 | F13: =(C13*D13*E13)*B13 -> 4.29 | G13: 170
A14: Line 2 | B14: 1 | F14: =(C14*D14*E14)*B14 -> 0
A15: Line 3 | B15: 1 | F15: =(C15*D15*E15)*B15 -> 0
A16: Line 4 | B16: 1 | F16: =(C16*D16*E16)*B16 -> 0
A17: Line 5 | F17: =(C17*D17*E17)*B17 -> 0
A18: Total | F18: =SUM(F13:F17) -> 4.29 | G18: =SUM(G13*B13)+(G14*B14)+(G15*B15)+(G16*B16)+(G17*B17) -> 170

Sheet REGIONS
A1: Region | B1: Desired GP%
A2: NORTHLAND | B2: 0.5
A3: NORTHLAND - Private Cust. | B3: =B2+5% -> 0.55
A4: AUCKLAND | B4: 0.35
A5: AUCKLAND - Private Cust. | B5: =B4+5% -> 0.4
A6: WAIKATO | B6: 0.4
A7: WAIKATO - Private Cust. | B7: =B6+5% -> 0.45
A8: BAY OF PLENTY | B8: 0.6
A9: BAY OF PLENTY - Private Cust. | B9: =B8+5% -> 0.65
A10: GISBORNE | B10: 0.55
A11: GISBORNE - Private Cust. | B11: =B10+5% -> 0.6
A12: HAWKES BAY | B12: 0.45
A13: HAWKES BAY - Private Cust. | B13: =B12+5% -> 0.5
A14: TARANAKI | B14: 0.5
A15: TARANAKI - Private Cust. | B15: =B14+5% -> 0.55
A16: MANAWATU-WANGANUI | B16: 0.5
A17: MANAWATU-WANGANUI - Private Cust. | B17: =B16+5% -> 0.55
A18: WELLINGTON | B18: 0.4
A19: WELLINGTON - Private Cust. | B19: =B18+5% -> 0.45
A20: TASMAN - NELSON | B20: 0.5
A21: TASMAN - NELSON - Private Cust. | B21: =B20+5% -> 0.55
A22: MARLBOROUGH | B22: 0.5
A23: MARLBOROUGH - Private Cust. | B23: =B22+5% -> 0.55
A24: WEST COAST | B24: 0.5
A25: WEST COAST - Private Cust. | B25: =B24+5% -> 0.55
A26: CANTERBURY | B26: 0.4
A27: CANTERBURY - Private Cust. | B27: =B26+5% -> 0.45
A28: OTAGO | B28: 0.4
A29: OTAGO - Private Cust. | B29: =B28+5% -> 0.45
A30: SOUTHLAND | B30: 0.4
A31: SOUTHLAND - Private Cust. | B31: =B30+5% -> 0.45

Sheet MEASURE UP'S
A1: Region | B1: CONTACT | C1: RATE
A2: NORTHLAND | B2: N/A | C2: 0
A3: NORTHLAND - Private Cust. | B3: N/A | C3: 0
A4: AUCKLAND | B4: TOP FLYTE STAIRS | C4: 95
A5: AUCKLAND - Private Cust. | B5: TOP FLYTE STAIRS | C5: 95
A6: WAIKATO | B6: TOP FLYTE STAIRS | C6: 95
A7: WAIKATO - Private Cust. | B7: TOP FLYTE STAIRS | C7: 95
A8: BAY OF PLENTY | B8: TOP FLYTE STAIRS | C8: 95
A9: BAY OF PLENTY - Private Cust. | B9: TOP FLYTE STAIRS | C9: 95
A10: GISBORNE | B10: N/A | C10: -
A11: GISBORNE - Private Cust. | B11: N/A | C11: -
A12: HAWKES BAY | B12: HAWKES BAY DOORS | C12: 95
A13: HAWKES BAY - Private Cust. | B13: HAWKES BAY DOORS | C13: 95
A14: TARANAKI | B14: RHYS POWELL JOINERY | C14: 95
A15: TARANAKI - Private Cust. | B15: RHYS POWELL JOINERY | C15: 95
A16: MANAWATU-WANGANUI | B16: N/A | C16: -
A17: MANAWATU-WANGANUI - Private Cust. | B17: N/A | C17: -
A18: WELLINGTON | B18: KOSHA HOMES | C18: 85
A19: WELLINGTON - Private Cust. | B19: KOSHA HOMES | C19: 85
A20: TASMAN - NELSON | B20: N/A | C20: -
A21: TASMAN - NELSON - Private Cust. | B21: N/A | C21: -
A22: MARLBOROUGH | B22: N/A | C22: -
A23: MARLBOROUGH - Private Cust. | B23: N/A | C23: -
A24: WEST COAST | B24: N/A | C24: -
A25: WEST COAST - Private Cust. | B25: N/A | C25: -
A26: CANTERBURY | B26: DKNZ | C26: 85
A27: CANTERBURY - Private Cust. | B27: DKNZ | C27: 85
A28: OTAGO | B28: ORAN KINNING | C28: 85
A29: OTAGO - Private Cust. | B29: ORAN KINNING | C29: 85
A30: SOUTHLAND | B30: N/A | C30: -
A31: SOUTHLAND - Private Cust. | B31: N/A | C31: -

Sheet (TYPES)
A1: STAIRS | C1: WINDERS | E1: LANDINGS
A3: PINE/MDF (250x40) | C3: WINDERS - Cut-under | E3: LANDING
A4: PINE/PLY (250x40) | C4: WINDERS
A5: PINE/MDF (300x40)
A6: PINE/PLY (300x40)
A7: PINE/MDF (300x50)
A8: PINE/PLY (300x50)
A9: PINE/MDF (Cut-under 300x40)
A10: PINE/PLY (Cut-under 300x40)
A11: PINE/MDF (Cut-under 300x50)
A12: PINE/PLY (Cut-under 300x50)
A13: KO - SPEC
A14: KO - (300x50/Ply)
A15: SOLID PINE - (250x40) - 40Tx25R
A16: SOLID PINE - (300x50) - 40Tx25R
... A22: WINDERS

Sheet Labour Rate
A1: LABOUR RATE BREAKDOWN
A2: Hourly Rate (averaged) | C2: =B15 -> 33.65
A3: Efficiency | B3: 0.75 | C3: =(C2/B3)-C2 -> 11.216667
A4: ACC | B4: 0.015 | C4: =C2*B4 -> 0.50475
A5: Holiday Pay | B5: 0.08 | C5: =C2*B5 -> 2.692
A6: Benefits | B6: 0.01 | C6: =C2*B6 -> 0.3365
A7: True Labour Cost | C7: =(C2+C3+C4+C5+C6) -> 48.399917
A10: Chriag | B10: 32
A11: Gary | B11: 32
A12: Deane | B12: 33.5
A13: Neil | B13: 31
A14: Freddy | B14: 39.75
A15: Total averaged | B15: =(B10+B11+B12+B13+B14)/5 -> 33.65

Sheet BPSC (+ Ply)
A1: 250 x 40 - Sell Prices (June 2022) | J1: Freight | M1: 250 x 40 in PLY - Sell Prices (June 2022) | V1: Freight
A3: Pine Stringer - MDF Treads/Risers - (Up to 300mm) | M3: Pine Stringer - PLY Treads/Risers - (Up to 300mm)
A4: ITEM | B4: WIDTH | C4: COST | D4: W/SALE PRICE | E4: GP% | F4: RETAIL PRICE | G4: GP% | H4: Desired GP% | J4: W/SALE FREIGHT | K4: RETAIL FREIGHT | M4: ITEM | N4: WIDTH | O4: COST | P4: W/SALE PRICE | Q4: GP% | R4: RETAIL PRICE | S4: GP% | T4: Desired GP% | V4: W/SALE FREIGHT | W4: RETAIL FREIGHT
D5: (less 10%) | H5: 0.665 | J5: 0.06 | K5: 0.06 | P5: (less 10%) | T5: 0.649 | V5: 0.06 | W5: 0.06
A6: BPSC Stair | B6: 0.9m | C6: ='BPSC. (+ Ply)'!G6 -> 23.084652 | D6: =F6-(F6*10%) -> 73.553683 | E6: =(D6-C6)/D6 -> 0.68615233 | F6: 81.726315 | G6: =(F6-C6)/F6 -> 0.7175371 | H6: =C6/(1-$H$5) -> 68.90941 | J6: =(D6*$J$5) -> 4.413221 | K6: =(F6*$K$5) -> 4.9035789 | M6: BPSC Stair | N6: 0.9m | O6: ='BPSC. (+ Ply)'!O6 -> 26.930652 | P6: =R6-(R6*10%) -> 79.881795 | Q6: =(P6-O6)/P6 -> 0.66286871 | R6: 88.75755 | S6: =(R6-O6)/R6 -> 0.69658184 | T6: =O6/(1-$T$5) -> 76.725505 | V6: =(P6*$J$5) -> 4.7929077 | W6: =(R6*$K$5) -> 5.325453
A7: BPSC Stair | B7: 1.0m | C7: ='BPSC. (+ Ply)'!G7 -> 24.353986 | D7: =F7-(F7*10%) -> 76.841959 | E7: =(D7-C7)/D7 -> 0.68306397 | F7: 85.379955 | G7: =(F7-C7)/F7 -> 0.71475757 | H7: =C7/(1-$H$5) -> 72.698464 | J7: =(D7*$J$5) -> 4.6105176 | K7: =(F7*$K$5) -> 5.1227973 | M7: BPSC Stair | N7: 1.0m | O7: ='BPSC. (+ Ply)'!O7 -> 28.769319 | P7: =R7-(R7*10%) -> 85.94289 | Q7: =(P7-O7)/P7 -> 0.66525074 | R7: 95.4921 | S7: =(R7-O7)/R7 -> 0.69872567 | T7: =O7/(1-$T$5) -> 81.963871 | V7: =(P7*$J$5) -> 5.1565734 | W7: =(R7*$K$5) -> 5.729526
A8: BPSC Stair | B8: 1.1m | C8: ='BPSC. (+ Ply)'!G8 -> 24.683986 | D8: =F8-(F8*10%) -> 79.246377 | E8: =(D8-C8)/D8 -> 0.68851591 | F8: 88.05153 | G8: =(F8-C8)/F8 -> 0.71966432 | H8: =C8/(1-$H$5) -> 73.683539 | J8: =(D8*$J$5) -> 4.7547826 | K8: =(F8*$K$5) -> 5.2830918 | M8: BPSC Stair | N8: 1.1m | O8: ='BPSC. (+ Ply)'!O8 -> 29.359319 | P8: =R8-(R8*10%) -> 87.392115 | Q8: =(P8-O8)/P8 -> 0.66405071 | R8: 97.10235 | S8: =(R8-O8)/R8 -> 0.69764564 | T8: =O8/(1-$T$5) -> 83.644783 | V8: =(P8*$J$5) -> 5.2435269 | W8: =(R8*$K$5) -> 5.826141
A9: BPSC Stair | B9: 1.2m | C9: ='BPSC. (+ Ply)'!G9 -> 24.683986 | D9: =F9-(F9*10%) -> 81.523186 | E9: =(D9-C9)/D9 -> 0.69721515 | F9: 90.581317 | G9: =(F9-C9)/F9 -> 0.72749364 | H9: =C9/(1-$H$5) -> 73.683539 | J9: =(D9*$J$5) -> 4.8913911 | K9: =(F9*$K$5) -> 5.434879 | M9: BPSC Stair | N9: 1.2m | O9: ='BPSC. (+ Ply)'!O9 -> 29.359319 | P9: =R9-(R9*10%) -> 89.565952 | Q9: =(P9-O9)/P9 -> 0.67220447 | R9: 99.517725 | S9: =(R9-O9)/R9 -> 0.70498402 | T9: =O9/(1-$T$5) -> 83.644783 | V9: =(P9*$J$5) -> 5.3739571 | W9: =(R9*$K$5) -> 5.9710635
A10: BPSC Stair | B10: 1.4m | C10: ='BPSC. (+ Ply)'!G10 -> 32.983582 | D10: =F10-(F10*10%) -> 89.073594 | E10: =(D10-C10)/D10 -> 0.62970416 | F10: 98.97066 | G10: =(F10-C10)/F10 -> 0.66673374 | H10: =C10/(1-$H$5) -> 98.458453 | J10: =(D10*$J$5) -> 5.3444156 | K10: =(F10*$K$5) -> 5.9382396 | M10: BPSC Stair | N10: 1.4m | O10: ='BPSC. (+ Ply)'!O10 -> 38.434248 | P10: =R10-(R10*10%) -> 98.719155 | Q10: =(P10-O10)/P10 -> 0.61067081 | R10: 109.68795 | S10: =(R10-O10)/R10 -> 0.64960373 | T10: =O10/(1-$T$5) -> 109.49928 | V10: =(P10*$J$5) -> 5.9231493 | W10: =(R10*$K$5) -> 6.581277
A11: BPSC Stair | B11: 1.6m | C11: ='BPSC. (+ Ply)'!G11 -> 38.290242 | D11: =F11-(F11*10%) -> 92.826634 | E11: =(D11-C11)/D11 -> 0.58750803 | F11: 103.1407 | G11: =(F11-C11)/F11 -> 0.62875722 | H11: =C11/(1-$H$5) -> 114.29923 | J11: =(D11*$J$5) -> 5.5695981 | K11: =(F11*$K$5) -> 6.1884423 | M11: BPSC Stair | N11: 1.6m | O11: ='BPSC. (+ Ply)'!O11 -> 44.526908 | P11: =R11-(R11*10%) -> 104.27495 | Q11: =(P11-O11)/P11 -> 0.57298555 | R11: 115.86105 | S11: =(R11-O11)/R11 -> 0.61568699 | T11: =O11/(1-$T$5) -> 126.85729 | V11: =(P11*$J$5) -> 6.2564967 | W11: =(R11*$K$5) -> 6.951663
A12: BPSC Stair | B12: 2.0m | C12: ='BPSC. (+ Ply)'!G12 -> 45.041568 | D12: =F12-(F12*10%) -> 117.92041 | E12: =(D12-C12)/D12 -> 0.61803415 | F12: 131.02267 | G12: =(F12-C12)/F12 -> 0.65623074 | H12: =C12/(1-$H$5) -> 134.45244 | J12: =(D12*$J$5) -> 7.0752244 | K12: =(F12*$K$5) -> 7.8613605 | M12: BPSC Stair | N12: 2.0m | O12: ='BPSC. (+ Ply)'!O12 -> 52.830235 | P12: =R12-(R12*10%) -> 126.23006 | Q12: =(P12-O12)/P12 -> 0.5814766 | R12: 140.25563 | S12: =(R12-O12)/R12 -> 0.62332894 | T12: =O12/(1-$T$5) -> 150.51349 | V12: =(P12*$J$5) -> 7.5738037 | W12: =(R12*$K$5) -> 8.4153375
A14: Pine Stringer - MDF Treads/Risers - (300mm +) | M14: Pine Stringer - PLY Treads/Risers - (300mm +)
A15: ITEM | B15: WIDTH | C15: COST | D15: W/SALE PRICE | E15: GP% | F15: RETAIL PRICE | G15: GP% | H15: Desired GP% | J15: W/SALE FREIGHT | K15: RETAIL FREIGHT | M15: ITEM | N15: WIDTH | O15: COST | P15: W/SALE PRICE | Q15: GP% | R15: RETAIL PRICE | S15: GP% | T15: Desired GP% | V15: W/SALE FREIGHT | W15: RETAIL FREIGHT
D16: (less 10%) | H16: 0.665 | J16: 0.06 | K16: 0.06 | P16: (less 10%) | T16: 0.649 | V16: 0.06 | W16: 0.06
A17: BPSC Stair | B17: 0.9m | C17: ='BPSC. (+ Ply)'!G17 -> 25.249986 | D17: =F17-(F17*10%) -> 79.163095 | E17: =(D17-C17)/D17 -> 0.68103843 | F17: 87.958995 | G17: =(F17-C17)/F17 -> 0.71293458 | H17: =C17/(1-$H$16) -> 75.373091 | J17: =(D17*$J$5) -> 4.7497857 | K17: =(F17*$K$5) -> 5.2775397 | M17: BPSC Stair | N17: 0.9m | O17: ='BPSC. (+ Ply)'!O17 -> 30.075986 | P17: =R17-(R17*10%) -> 87.66144 | Q17: =(P17-O17)/P17 -> 0.65690747 | R17: 97.4016 | S17: =(R17-O17)/R17 -> 0.69121672 | T17: =O17/(1-$T$16) -> 85.686569 | V17: =(P17*$J$5) -> 5.2596864 | W17: =(R17*$K$5) -> 5.844096
A18: BPSC Stair | B18: 1.0m | C18: ='BPSC. (+ Ply)'!G18 -> 25.249986 | D18: =F18-(F18*10%) -> 79.295697 | E18: =(D18-C18)/D18 -> 0.68157181 | F18: 88.10633 | G18: =(F18-C18)/F18 -> 0.71341463 | H18: =C18/(1-$H$16) -> 75.373091 | J18: =(D18*$J$5) -> 4.7577418 | K18: =(F18*$K$5) -> 5.2863798 | M18: BPSC Stair | N18: 1.0m | O18: ='BPSC. (+ Ply)'!O18 -> 30.075986 | P18: =R18-(R18*10%) -> 89.17479 | Q18: =(P18-O18)/P18 -> 0.66272995 | R18: 99.0831 | S18: =(R18-O18)/R18 -> 0.69645696 | T18: =O18/(1-$T$16) -> 85.686569 | V18: =(P18*$J$5) -> 5.3504874 | W18: =(R18*$K$5) -> 5.944986
A19: BPSC Stair | B19: 1.1m | C19: ='BPSC. (+ Ply)'!G19 -> 25.579986 | D19: =F19-(F19*10%) -> 81.567513 | E19: =(D19-C19)/D19 -> 0.68639493 | F19: 90.63057 | G19: =(F19-C19)/F19 -> 0.71775544 | H19: =C19/(1-$H$16) -> 76.358166 | J19: =(D19*$J$5) -> 4.8940508 | K19: =(F19*$K$5) -> 5.4378342 | M19: BPSC Stair | N19: 1.1m | O19: ='BPSC. (+ Ply)'!O19 -> 30.665986 | P19: =R19-(R19*10%) -> 90.624015 | Q19: =(P19-O19)/P19 -> 0.66161303 | R19: 100.69335 | S19: =(R19-O19)/R19 -> 0.69545173 | T19: =O19/(1-$T$16) -> 87.36748 | V19: =(P19*$J$5) -> 5.4374409 | W19: =(R19*$K$5) -> 6.041601
A20: BPSC Stair | B20: 1.2m | C20: ='BPSC. (+ Ply)'!G20 -> 25.579986 | D20: =F20-(F20*10%) -> 83.844322 | E20: =(D20-C20)/D20 -> 0.69491094 | F20: 93.160358 | G20: =(F20-C20)/F20 -> 0.72541984 | H20: =C20/(1-$H$16) -> 76.358166 | J20: =(D20*$J$5) -> 5.0306593 | K20: =(F20*$K$5) -> 5.5896215 | M20: BPSC Stair | N20: 1.2m | O20: ='BPSC. (+ Ply)'!O20 -> 30.665986 | P20: =R20-(R20*10%) -> 92.797853 | Q20: =(P20-O20)/P20 -> 0.66953992 | R20: 103.10873 | S20: =(R20-O20)/R20 -> 0.70258593 | T20: =O20/(1-$T$16) -> 87.36748 | V20: =(P20*$J$5) -> 5.5678712 | W20: =(R20*$K$5) -> 6.1865235
A21: BPSC Stair | B21: 1.4m | C21: ='BPSC. (+ Ply)'!G21 -> 35.447582 | D21: =F21-(F21*10%) -> 95.456718 | E21: =(D21-C21)/D21 -> 0.62865283 | F21: 106.06302 | G21: =(F21-C21)/F21 -> 0.66578755 | H21: =C21/(1-$H$16) -> 105.81368 | J21: =(D21*$J$5) -> 5.7274031 | K21: =(F21*$K$5) -> 6.3637812 | M21: BPSC Stair | N21: 1.4m | O21: ='BPSC. (+ Ply)'!O21 -> 41.999582 | P21: =R21-(R21*10%) -> 107.53762 | Q21: =(P21-O21)/P21 -> 0.60944291 | R21: 119.48625 | S21: =(R21-O21)/R21 -> 0.64849862 | T21: =O21/(1-$T$16) -> 119.65693 | V21: =(P21*$J$5) -> 6.4522575 | W21: =(R21*$K$5) -> 7.169175
A22: BPSC Stair | B22: 1.6m | C22: ='BPSC. (+ Ply)'!G22 -> 41.099575 | D22: =F22-(F22*10%) -> 100.10436 | E22: =(D22-C22)/D22 -> 0.58943273 | F22: 111.22707 | G22: =(F22-C22)/F22 -> 0.63048946 | H22: =C22/(1-$H$16) -> 122.6853 | J22: =(D22*$J$5) -> 6.0062618 | K22: =(F22*$K$5) -> 6.6736242 | M22: BPSC Stair | N22: 1.6m | O22: ='BPSC. (+ Ply)'!O22 -> 48.605575 | P22: =R22-(R22*10%) -> 114.36309 | Q22: =(P22-O22)/P22 -> 0.57498897 | R22: 127.0701 | S22: =(R22-O22)/R22 -> 0.61749007 | T22: =O22/(1-$T$16) -> 138.47742 | V22: =(P22*$J$5) -> 6.8617854 | W22: =(R22*$K$5) -> 7.624206
A23: BPSC Stair | B23: 2.0m | C23: ='BPSC. (+ Ply)'!G23 -> 48.550902 | D23: =F23-(F23*10%) -> 127.51405 | E23: =(D23-C23)/D23 -> 0.61925056 | F23: 141.68227 | G23: =(F23-C23)/F23 -> 0.65732551 | H23: =C23/(1-$H$16) -> 144.92806 | J23: =(D23*$J$5) -> 7.6508428 | K23: =(F23*$K$5) -> 8.5009365 | M23: BPSC Stair | N23: 2.0m | O23: ='BPSC. (+ Ply)'!O23 -> 57.926235 | P23: =R23-(R23*10%) -> 138.83447 | Q23: =(P23-O23)/P23 -> 0.58276764 | R23: 154.26053 | S23: =(R23-O23)/R23 -> 0.62449087 | T23: =O23/(1-$T$16) -> 165.03201 | V23: =(P23*$J$5) -> 8.3300683 | W23: =(R23*$K$5) -> 9.2556315
A26: 300 x 40 - Sell Prices (June 2022) | J26: Freight | M26: 300 x 40 in PLY - Sell Prices (June 2022) | V26: Freight
A28: Pine Stringer - MDF Treads/Risers - (Up to 300mm) | M28: Pine Stringer - PLY Treads/Risers - (Up to 300mm)
A29: ITEM | B29: WIDTH | C29: COST | D29: W/SALE PRICE | E29: GP% | F29: RETAIL PRICE | G29: GP% | H29: Desired GP% | J29: W/SALE FREIGHT | K29: RETAIL FREIGHT | M29: ITEM | N29: WIDTH | O29: COST | P29: W/SALE PRICE | Q29: GP% | R29: RETAIL PRICE | S29: GP% | T29: Desired GP% | V29: W/SALE FREIGHT | W29: RETAIL FREIGHT
D30: (less 10%) | H30: 0.665 | J30: 0.06 | K30: 0.06 | P30: (less 10%) | T30: 0.649 | V30: 0.06 | W30: 0.06
A31: BPSC Stair | B31: 0.9m | C31: ='BPSC. (+ Ply)'!G31 -> 24.650252 | D31: =F31-(F31*10%) -> 77.844627 | E31: =(D31-C31)/D31 -> 0.68334035 | F31: 86.49403 | G31: =(F31-C31)/F31 -> 0.71500632 | H31: =C31/(1-$H$30) -> 73.582842 | J31: =(D31*$J$5) -> 4.6706776 | K31: =(F31*$K$5) -> 5.1896418 | M31: BPSC Stair | N31: 0.9m | O31: ='BPSC. (+ Ply)'!O31 -> 28.496252 | P31: =R31-(R31*10%) -> 83.947436 | Q31: =(P31-O31)/P31 -> 0.66054648 | R31: 93.274929 | S31: =(R31-O31)/R31 -> 0.69449184 | T31: =O31/(1-$T$30) -> 81.185904 | V31: =(P31*$J$5) -> 5.0368462 | W31: =(R31*$K$5) -> 5.5964957
A32: BPSC Stair | B32: 1.0m | C32: ='BPSC. (+ Ply)'!G32 -> 25.919586 | D32: =F32-(F32*10%) -> 81.132985 | E32: =(D32-C32)/D32 -> 0.68052962 | F32: 90.147761 | G32: =(F32-C32)/F32 -> 0.71247666 | H32: =C32/(1-$H$30) -> 77.371897 | J32: =(D32*$J$5) -> 4.8679791 | K32: =(F32*$K$5) -> 5.4088657 | M32: BPSC Stair | N32: 1.0m | O32: ='BPSC. (+ Ply)'!O32 -> 30.334919 | P32: =R32-(R32*10%) -> 90.00641 | Q32: =(P32-O32)/P32 -> 0.66296935 | R32: 100.00712 | S32: =(R32-O32)/R32 -> 0.69667242 | T32: =O32/(1-$T$30) -> 86.42427 | V32: =(P32*$J$5) -> 5.4003846 | W32: =(R32*$K$5) -> 6.0004274
A33: BPSC Stair | B33: 1.1m | C33: ='BPSC. (+ Ply)'!G33 -> 26.249586 | D33: =F33-(F33*10%) -> 83.537463 | E33: =(D33-C33)/D33 -> 0.68577468 | F33: 92.819403 | G33: =(F33-C33)/F33 -> 0.71719722 | H33: =C33/(1-$H$30) -> 78.356972 | J33: =(D33*$J$5) -> 5.0122478 | K33: =(F33*$K$5) -> 5.5691642 | M33: BPSC Stair | N33: 1.1m | O33: ='BPSC. (+ Ply)'!O33 -> 30.924919 | P33: =R33-(R33*10%) -> 91.455128 | Q33: =(P33-O33)/P33 -> 0.66185692 | R33: 101.61681 | S33: =(R33-O33)/R33 -> 0.69567123 | T33: =O33/(1-$T$30) -> 88.105182 | V33: =(P33*$J$5) -> 5.4873077 | W33: =(R33*$K$5) -> 6.0970085
A34: BPSC Stair | B34: 1.2m | C34: ='BPSC. (+ Ply)'!G34 -> 26.249586 | D34: =F34-(F34*10%) -> 85.814328 | E34: =(D34-C34)/D34 -> 0.69411186 | F34: 95.349254 | G34: =(F34-C34)/F34 -> 0.72470067 | H34: =C34/(1-$H$30) -> 78.356972 | J34: =(D34*$J$5) -> 5.1488597 | K34: =(F34*$K$5) -> 5.7209552 | M34: BPSC Stair | N34: 1.2m | O34: ='BPSC. (+ Ply)'!O34 -> 30.924919 | P34: =R34-(R34*10%) -> 93.628205 | Q34: =(P34-O34)/P34 -> 0.6697051 | R34: 104.03134 | S34: =(R34-O34)/R34 -> 0.70273459 | T34: =O34/(1-$T$30) -> 88.105182 | V34: =(P34*$J$5) -> 5.6176923 | W34: =(R34*$K$5) -> 6.2418803
A35: BPSC Stair | B35: 1.4m | C35: ='BPSC. (+ Ply)'!G35 -> 34.549182 | D35: =F35-(F35*10%) -> 93.364925 | E35: =(D35-C35)/D35 -> 0.62995545 | F35: 103.73881 | G35: =(F35-C35)/F35 -> 0.66695991 | H35: =C35/(1-$H$30) -> 103.13189 | J35: =(D35*$J$5) -> 5.6018955 | K35: =(F35*$K$5) -> 6.2243284 | M35: BPSC Stair | N35: 1.4m | O35: ='BPSC. (+ Ply)'!O35 -> 39.999848 | P35: =R35-(R35*10%) -> 102.77821 | Q35: =(P35-O35)/P35 -> 0.6108139 | R35: 114.19801 | S35: =(R35-O35)/R35 -> 0.64973251 | T35: =O35/(1-$T$30) -> 113.95968 | V35: =(P35*$J$5) -> 6.1666923 | W35: =(R35*$K$5) -> 6.8518803
A36: BPSC Stair | B36: 1.6m | C36: ='BPSC. (+ Ply)'!G36 -> 39.855842 | D36: =F36-(F36*10%) -> 97.11806 | E36: =(D36-C36)/D36 -> 0.58961452 | F36: 107.90896 | G36: =(F36-C36)/F36 -> 0.63065307 | H36: =C36/(1-$H$30) -> 118.97266 | J36: =(D36*$J$5) -> 5.8270836 | K36: =(F36*$K$5) -> 6.4745373 | M36: BPSC Stair | N36: 1.6m | O36: ='BPSC. (+ Ply)'!O36 -> 46.092508 | P36: =R36-(R36*10%) -> 108.33205 | Q36: =(P36-O36)/P36 -> 0.57452566 | R36: 120.36895 | S36: =(R36-O36)/R36 -> 0.61707309 | T36: =O36/(1-$T$30) -> 131.31769 | V36: =(P36*$J$5) -> 6.4999231 | W36: =(R36*$K$5) -> 7.2221368
A37: BPSC Stair | B37: 2.0m | C37: ='BPSC. (+ Ply)'!G37 -> 46.607168 | D37: =F37-(F37*10%) -> 116.03552 | E37: =(D37-C37)/D37 -> 0.59833707 | F37: 128.92836 | G37: =(F37-C37)/F37 -> 0.63850336 | H37: =C37/(1-$H$30) -> 139.12588 | J37: =(D37*$J$5) -> 6.9621313 | K37: =(F37*$K$5) -> 7.7357015 | M37: BPSC Stair | N37: 2.0m | O37: ='BPSC. (+ Ply)'!O37 -> 54.395835 | P37: =R37-(R37*10%) -> 130.27949 | Q37: =(P37-O37)/P37 -> 0.58246815 | R37: 144.75499 | S37: =(R37-O37)/R37 -> 0.62422134 | T37: =O37/(1-$T$30) -> 154.97389 | V37: =(P37*$J$5) -> 7.8167692 | W37: =(R37*$K$5) -> 8.6852991
A39: Pine Stringer - MDF Treads/Risers - (300mm +) | M39: Pine Stringer - PLY Treads/Risers - (300mm +)
A40: ITEM | B40: WIDTH | C40: COST | D40: W/SALE PRICE | E40: GP% | F40: RETAIL PRICE | G40: GP% | H40: Desired GP% | J40: W/SALE FREIGHT | K40: RETAIL FREIGHT | M40: ITEM | N40: WIDTH | O40: COST | P40: W/SALE PRICE | Q40: GP% | R40: RETAIL PRICE | S40: GP% | T40: Desired GP% | V40: W/SALE FREIGHT | W40: RETAIL FREIGHT
D41: (less 10%) | H41: 0.665 | J41: 0.06 | K41: 0.06 | P41: (less 10%) | T41: 0.649 | V41: 0.06 | W41: 0.06
A42: BPSC Stair | B42: 0.9m | C42: ='BPSC. (+ Ply)'!G42 -> 26.815586 | D42: =F42-(F42*10%) -> 83.454179 | E42: =(D42-C42)/D42 -> 0.67867894 | F42: 92.726866 | G42: =(F42-C42)/F42 -> 0.71081104 | H42: =C42/(1-$H$41) -> 80.046524 | J42: =(D42*$J$5) -> 5.0072507 | K42: =(F42*$K$5) -> 5.5636119 | M42: BPSC Stair | N42: 0.9m | O42: ='BPSC. (+ Ply)'!O42 -> 31.641586 | P42: =R42-(R42*10%) -> 91.724359 | Q42: =(P42-O42)/P42 -> 0.65503618 | R42: 101.91595 | S42: =(R42-O42)/R42 -> 0.68953256 | T42: =O42/(1-$T$41) -> 90.146967 | V42: =(P42*$J$5) -> 5.5034615 | W42: =(R42*$K$5) -> 6.1149573
A43: BPSC Stair | B43: 1.0m | C43: ='BPSC. (+ Ply)'!G43 -> 26.815586 | D43: =F43-(F43*10%) -> 83.454179 | E43: =(D43-C43)/D43 -> 0.67867894 | F43: 92.726866 | G43: =(F43-C43)/F43 -> 0.71081104 | H43: =C43/(1-$H$41) -> 80.046524 | J43: =(D43*$J$5) -> 5.0072507 | K43: =(F43*$K$5) -> 5.5636119 | M43: BPSC Stair | N43: 1.0m | O43: ='BPSC. (+ Ply)'!O43 -> 31.641586 | P43: =R43-(R43*10%) -> 93.237179 | Q43: =(P43-O43)/P43 -> 0.66063339 | R43: 103.59687 | S43: =(R43-O43)/R43 -> 0.69457005 | T43: =O43/(1-$T$41) -> 90.146967 | V43: =(P43*$J$5) -> 5.5942308 | W43: =(R43*$K$5) -> 6.215812
A44: BPSC Stair | B44: 1.1m | C44: ='BPSC. (+ Ply)'!G44 -> 27.145586 | D44: =F44-(F44*10%) -> 85.858657 | E44: =(D44-C44)/D44 -> 0.68383403 | F44: 95.398507 | G44: =(F44-C44)/F44 -> 0.71545063 | H44: =C44/(1-$H$41) -> 81.031599 | J44: =(D44*$J$5) -> 5.1515194 | K44: =(F44*$K$5) -> 5.7239104 | M44: BPSC Stair | N44: 1.1m | O44: ='BPSC. (+ Ply)'!O44 -> 32.231586 | P44: =R44-(R44*10%) -> 94.685897 | Q44: =(P44-O44)/P44 -> 0.65959466 | R44: 105.20655 | S44: =(R44-O44)/R44 -> 0.69363519 | T44: =O44/(1-$T$41) -> 91.827879 | V44: =(P44*$J$5) -> 5.6811538 | W44: =(R44*$K$5) -> 6.3123932
A45: BPSC Stair | B45: 1.2m | C45: ='BPSC. (+ Ply)'!G45 -> 27.145586 | D45: =F45-(F45*10%) -> 88.135522 | E45: =(D45-C45)/D45 -> 0.69200176 | F45: 97.928358 | G45: =(F45-C45)/F45 -> 0.72280159 | H45: =C45/(1-$H$41) -> 81.031599 | J45: =(D45*$J$5) -> 5.2881313 | K45: =(F45*$K$5) -> 5.8757015 | M45: BPSC Stair | N45: 1.2m | O45: ='BPSC. (+ Ply)'!O45 -> 32.231586 | P45: =R45-(R45*10%) -> 96.858974 | Q45: =(P45-O45)/P45 -> 0.66723181 | R45: 107.62108 | S45: =(R45-O45)/R45 -> 0.70050863 | T45: =O45/(1-$T$41) -> 91.827879 | V45: =(P45*$J$5) -> 5.8115385 | W45: =(R45*$K$5) -> 6.457265
A46: BPSC Stair | B46: 1.4m | C46: ='BPSC. (+ Ply)'!G46 -> 37.013182 | D46: =F46-(F46*10%) -> 99.748209 | E46: =(D46-C46)/D46 -> 0.62893387 | F46: 110.83134 | G46: =(F46-C46)/F46 -> 0.66604048 | H46: =C46/(1-$H$41) -> 110.48711 | J46: =(D46*$J$5) -> 5.9848925 | K46: =(F46*$K$5) -> 6.6498806 | M46: BPSC Stair | N46: 1.4m | O46: ='BPSC. (+ Ply)'!O46 -> 43.565182 | P46: =R46-(R46*10%) -> 111.59359 | Q46: =(P46-O46)/P46 -> 0.60960856 | R46: 123.99288 | S46: =(R46-O46)/R46 -> 0.64864771 | T46: =O46/(1-$T$41) -> 124.11733 | V46: =(P46*$J$5) -> 6.6956154 | W46: =(R46*$K$5) -> 7.4395726
...

Sheet KO Spec
A1: Sell Prices as at June 2022 | J1: Freight
A4: Pine H1.2 Stringer - H3.2 Plywood Treads/Risers - (Up to 300mm)
A5: ITEM | B5: WIDTH | C5: COST | D5: W/SALE PRICE | E5: GP% | F5: RETAIL PRICE | G5: GP% | H5: Desired GP% | J5: W/SALE FREIGHT | K5: RETAIL FREIGHT
D6: (less 10%) | H6: 0.65 | J6: 0.06 | K6: 0.06
A7: KO Spec Stair | B7: 0.9m | C7: ='KO Spec.'!G6 -> 30.396652 | D7: =F7-(F7*10%) -> 88.605 | E7: =(D7-C7)/D7 -> 0.65694202 | F7: 98.45 | G7: =(F7-C7)/F7 -> 0.69124782 | H7: =C7/(1-$H$6) -> 86.847578 | J7: =(D7*$J$6) -> 5.3163 | K7: =(F7*$K$6) -> 5.907
A8: KO Spec Stair | B8: 1.0m | C8: ='KO Spec.'!G7 -> 32.785986 | D8: =F8-(F8*10%) -> 94.518 | E8: =(D8-C8)/D8 -> 0.65312443 | F8: 105.02 | G8: =(F8-C8)/F8 -> 0.68781198 | H8: =C8/(1-$H$6) -> 93.674244 | J8: =(D8*$J$6) -> 5.67108 | K8: =(F8*$K$6) -> 6.3012
A9: KO Spec Stair | B9: 1.1m | C9: ='KO Spec.'!G8 -> 33.475986 | D9: =F9-(F9*10%) -> 97.731 | E9: =(D9-C9)/D9 -> 0.6574681 | F9: 108.59 | G9: =(F9-C9)/F9 -> 0.69172129 | H9: =C9/(1-$H$6) -> 95.645673 | J9: =(D9*$J$6) -> 5.86386 | K9: =(F9*$K$6) -> 6.5154
A10: KO Spec Stair | B10: 1.2m | C10: ='KO Spec.'!G9 -> 33.475986 | D10: =F10-(F10*10%) -> 99.909 | E10: =(D10-C10)/D10 -> 0.66493524 | F10: 111.01 | G10: =(F10-C10)/F10 -> 0.69844171 | H10: =C10/(1-$H$6) -> 95.645673 | J10: =(D10*$J$6) -> 5.99454 | K10: =(F10*$K$6) -> 6.6606
A11: KO Spec Stair | B11: 1.4m | C11: ='KO Spec.'!G10 -> 44.923248 | D11: =F11-(F11*10%) -> 110.475 | E11: =(D11-C11)/D11 -> 0.59336277 | F11: 122.75 | G11: =(F11-C11)/F11 -> 0.63402649 | H11: =C11/(1-$H$6) -> 128.35214 | J11: =(D11*$J$6) -> 6.6285 | K11: =(F11*$K$6) -> 7.365
A12: KO Spec Stair | B12: 1.6m | C12: ='KO Spec.'!G11 -> 51.592575 | D12: =F12-(F12*10%) -> 117.468 | E12: =(D12-C12)/D12 -> 0.56079464 | F12: 130.52 | G12: =(F12-C12)/F12 -> 0.60471518 | H12: =C12/(1-$H$6) -> 147.40736 | J12: =(D12*$J$6) -> 7.04808 | K12: =(F12*$K$6) -> 7.8312
A13: KO Spec Stair | B13: 2.0m | C13: ='KO Spec.'!G12 -> 61.030568 | D13: =F13-(F13*10%) -> 142.245 | E13: =(D13-C13)/D13 -> 0.57094753 | F13: 158.05 | G13: =(F13-C13)/F13 -> 0.61385278 | H13: =C13/(1-$H$6) -> 174.37305 | J13: =(D13*$J$6) -> 8.5347 | K13: =(F13*$K$6) -> 9.483
A15: Pine H1.2 Stringer - H3.2 Treads/Risers - (300mm +)
A16: ITEM | B16: WIDTH | C16: COST | D16: W/SALE PRICE | E16: GP% | F16: RETAIL PRICE | G16: GP% | H16: Desired GP% | J16: W/SALE FREIGHT | K16: RETAIL FREIGHT
D17: (less 10%) | H17: 0.65 | J17: 0.06 | K17: 0.06
A18: KO Spec Stair | B18: 0.9m | C18: ='KO Spec.'!G17 -> 34.493986 | D18: =F18-(F18*10%) -> 98.738393 | E18: =(D18-C18)/D18 -> 0.65065275 | F18: 109.70933 | G18: =(F18-C18)/F18 -> 0.68558748 | H18: =C18/(1-$H$17) -> 98.554244 | J18: =(D18*$J$6) -> 5.9243036 | K18: =(F18*$K$6) -> 6.5825595
A19: KO Spec Stair | B19: 1.0m | C19: ='KO Spec.'!G18 -> 34.493986 | D19: =F19-(F19*10%) -> 98.738393 | E19: =(D19-C19)/D19 -> 0.65065275 | F19: 109.70933 | G19: =(F19-C19)/F19 -> 0.68558748 | H19: =C19/(1-$H$6) -> 98.554244 | J19: =(D19*$J$6) -> 5.9243036 | K19: =(F19*$K$6) -> 6.5825595
A20: KO Spec Stair | B20: 1.1m | C20: ='KO Spec.'!G19 -> 35.183986 | D20: =F20-(F20*10%) -> 101.95747 | E20: =(D20-C20)/D20 -> 0.65491507 | F20: 113.28608 | G20: =(F20-C20)/F20 -> 0.68942356 | H20: =C20/(1-$H$6) -> 100.52567 | J20: =(D20*$J$6) -> 6.1174481 | K20: =(F20*$K$6) -> 6.7971645
A21: KO Spec Stair | B21: 1.2m | C21: ='KO Spec.'!G20 -> 35.183986 | D21: =F21-(F21*10%) -> 104.13131 | E21: =(D21-C21)/D21 -> 0.66211904 | F21: 115.70145 | G21: =(F21-C21)/F21 -> 0.69590713 | H21: =C21/(1-$H$6) -> 100.52567 | J21: =(D21*$J$6) -> 6.2478783 | K21: =(F21*$K$6) -> 6.942087
A22: KO Spec Stair | B22: 1.4m | C22: ='KO Spec.'!G21 -> 49.571248 | D22: =F22-(F22*10%) -> 121.9696 | E22: =(D22-C22)/D22 -> 0.59357701 | F22: 135.52177 | G22: =(F22-C22)/F22 -> 0.63421931 | H22: =C22/(1-$H$6) -> 141.63214 | J22: =(D22*$J$6) -> 7.3181758 | K22: =(F22*$K$6) -> 8.1313065
A23: KO Spec Stair | B23: 1.6m | C23: ='KO Spec.'!G22 -> 56.903242 | D23: =F23-(F23*10%) -> 130.60082 | E23: =(D23-C23)/D23 -> 0.56429645 | F23: 145.11203 | G23: =(F23-C23)/F23 -> 0.60786681 | H23: =C23/(1-$H$6) -> 162.58069 | J23: =(D23*$J$6) -> 7.8360494 | K23: =(F23*$K$6) -> 8.7067215
A24: KO Spec Stair | B24: 2.0m | C24: ='KO Spec.'!G23 -> 67.666568 | D24: =F24-(F24*10%) -> 158.66064 | E24: =(D24-C24)/D24 -> 0.57351383 | F24: 176.2896 | G24: =(F24-C24)/F24 -> 0.61616245 | H24: =C24/(1-$H$6) -> 193.33305 | J24: =(D24*$J$6) -> 9.5196384 | K24: =(F24*$K$6) -> 10.577376
A27: 300 x 50 - Sell Prices (August 2024) | J27: Freight
A30: Pine H3.2 300x50 Stringer - H3.2 Plywood Treads/Risers - (Up to 300mm)
A31: ITEM | B31: WIDTH | C31: COST | D31: W/SALE PRICE | E31: GP% | F31: RETAIL PRICE | G31: GP% | H31: Desired GP% | J31: W/SALE FREIGHT | K31: RETAIL FREIGHT
D32: (less 10%) | H32: 0.65 | J32: 0.06 | K32: 0.06
A33: KO Spec Stair | B33: 0.9m | C33: ='KO Spec.'!G30 -> 34.857852 | D33: =F33-(F33*10%) -> 103.83236 | E33: =(D33-C33)/D33 -> 0.66428719 | F33: 115.36929 | G33: =(F33-C33)/F33 -> 0.69785847 | H33: =C33/(1-$H$32) -> 99.593863 | J33: =(D33*$J$6) -> 6.2299414 | K33: =(F33*$K$6) -> 6.9221571
A34: KO Spec Stair | B34: 1.0m | C34: ='KO Spec.'!G31 -> 37.247186 | D34: =F34-(F34*10%) -> 109.75693 | E34: =(D34-C34)/D34 -> 0.66063932 | F34: 121.95214 | G34: =(F34-C34)/F34 -> 0.69457539 | H34: =C34/(1-$H$32) -> 106.42053 | J34: =(D34*$J$6) -> 6.5854157 | K34: =(F34*$K$6) -> 7.3171286
A35: KO Spec Stair | B35: 1.1m | C35: ='KO Spec.'!G32 -> 37.937186 | D35: =F35-(F35*10%) -> 112.98407 | E35: =(D35-C35)/D35 -> 0.66422536 | F35: 125.53786 | G35: =(F35-C35)/F35 -> 0.69780283 | H35: =C35/(1-$H$32) -> 108.39196 | J35: =(D35*$J$6) -> 6.7790443 | K35: =(F35*$K$6) -> 7.5322714
A36: KO Spec Stair | B36: 1.2m | C36: ='KO Spec.'!G33 -> 37.937186 | D36: =F36-(F36*10%) -> 115.16336 | E36: =(D36-C36)/D36 -> 0.67057937 | F36: 127.95929 | G36: =(F36-C36)/F36 -> 0.70352143 | H36: =C36/(1-$H$32) -> 108.39196 | J36: =(D36*$J$6) -> 6.9098014 | K36: =(F36*$K$6) -> 7.6775571
A37: KO Spec Stair | B37: 1.4m | C37: ='KO Spec.'!G34 -> 49.384448 | D37: =F37-(F37*10%) -> 125.75636 | E37: =(D37-C37)/D37 -> 0.60730058 | F37: 139.72929 | G37: =(F37-C37)/F37 -> 0.64657052 | H37: =C37/(1-$H$32) -> 141.09842 | J37: =(D37*$J$6) -> 7.5453814 | K37: =(F37*$K$6) -> 8.3837571
A38: KO Spec Stair | B38: 1.6m | C38: ='KO Spec.'!G35 -> 56.053775 | D38: =F38-(F38*10%) -> 132.76607 | E38: =(D38-C38)/D38 -> 0.57780045 | F38: 147.51786 | G38: =(F38-C38)/F38 -> 0.62002041 | H38: =C38/(1-$H$32) -> 160.15364 | J38: =(D38*$J$6) -> 7.9659643 | K38: =(F38*$K$6) -> 8.8510714
A39: KO Spec Stair | B39: 2.0m | C39: ='KO Spec.'!G36 -> 65.491768 | D39: =F39-(F39*10%) -> 157.60993 | E39: =(D39-C39)/D39 -> 0.58446927 | F39: 175.12214 | G39: =(F39-C39)/F39 -> 0.62602234 | H39: =C39/(1-$H$32) -> 187.11934 | J39: =(D39*$J$6) -> 9.4565957 | K39: =(F39*$K$6) -> 10.507329
A41: Pine H3.2 300x50 Stringer - H3.2 Plywood Treads/Risers - (300mm +)
A42: ITEM | B42: WIDTH | C42: COST | D42: W/SALE PRICE | E42: GP% | F42: RETAIL PRICE | G42: GP% | H42: Desired GP% | J42: W/SALE FREIGHT | K42: RETAIL FREIGHT
D43: (less 10%) | H43: 0.65 | J43: 0.06 | K43: 0.06
A44: KO Spec Stair | B44: 0.9m | C44: ='KO Spec.'!G41 -> 38.955186 | D44: =F44-(F44*10%) -> 113.99207 | E44: =(D44-C44)/D44 -> 0.65826408 | F44: 126.65786 | G44: =(F44-C44)/F44 -> 0.69243767 | H44: =C44/(1-$H$43) -> 111.30053 | J44: =(D44*$J$6) -> 6.8395243 | K44: =(F44*$K$6) -> 7.5994714
A45: KO Spec Stair | B45: 1.0m | C45: ='KO Spec.'!G42 -> 38.955186 | D45: =F45-(F45*10%) -> 113.99207 | E45: =(D45-C45)/D45 -> 0.65826408 | F45: 126.65786 | G45: =(F45-C45)/F45 -> 0.69243767 | H45: =C45/(1-$H$43) -> 111.30053 | J45: =(D45*$J$6) -> 6.8395243 | K45: =(F45*$K$6) -> 7.5994714
A46: KO Spec Stair | B46: 1.1m | C46: ='KO Spec.'!G43 -> 39.645186 | D46: =F46-(F46*10%) -> 117.21921 | E46: =(D46-C46)/D46 -> 0.66178595 | F46: 130.24357 | G46: =(F46-C46)/F46 -> 0.69560735 | H46: =C46/(1-$H$43) -> 113.27196 | J46: =(D46*$J$6) -> 7.0331529 | K46: =(F46*$K$6) -> 7.8146143
A47: KO Spec Stair | B47: 1.2m | C47: ='KO Spec.'!G44 -> 39.645186 | D47: =F47-(F47*10%) -> 119.3985 | E47: =(D47-C47)/D47 -> 0.6679591 | F47: 132.665 | G47: =(F47-C47)/F47 -> 0.70116319 | H47: =C47/(1-$H$43) -> 113.27196 | J47: =(D47*$J$6) -> 7.16391 | K47: =(F47*$K$6) -> 7.9599
A48: KO Spec Stair | B48: 1.4m | C48: ='KO Spec.'!G45 -> 54.032448 | D48: =F48-(F48*10%) -> 137.2815 | E48: =(D48-C48)/D48 -> 0.60641129 | F48: 152.535 | G48: =(F48-C48)/F48 -> 0.64577016 | H48: =C48/(1-$H$43) -> 154.37842 | J48: =(D48*$J$6) -> 8.23689 | K48: =(F48*$K$6) -> 9.1521
...

Sheet Solid Pine
A1: Sell Prices as at June 2022 | J1: Freight | M1: Sell Prices as at June 2022 | V1: Freight
A4: Solid Pine Stringer (250mm x 40mm) with Solid Treads/Risers - (Up to 300mm) | M4: Solid Pine Stringer (300mm x 40mm) with Solid Treads/Risers - (Up to 300mm)
A5: ITEM | B5: WIDTH | C5: COST | D5: W/SALE PRICE | E5: GP% | F5: RETAIL PRICE | G5: GP% | H5: Desired GP% | J5: W/SALE FREIGHT | K5: RETAIL FREIGHT | M5: ITEM | N5: WIDTH | O5: COST | P5: W/SALE PRICE | Q5: GP% | R5: RETAIL PRICE | S5: GP% | T5: Desired GP% | V5: W/SALE FREIGHT | W5: RETAIL FREIGHT
D6: (less 10%) | H6: 0.65 | J6: 0.06 | K6: 0.06 | P6: (less 10%) | T6: 0.65 | V6: 0.06 | W6: 0.06
A7: Solid Pine | B7: 0.9m | C7: ='Solid Pine.'!G6 -> 41.021884 | D7: =F7-(F7*10%) -> 108.08478 | E7: =(D7-C7)/D7 -> 0.62046568 | F7: 120.0942 | G7: =(F7-C7)/F7 -> 0.65841911 | H7: =C7/(1-$H$6) -> 117.20538 | J7: =(D7*$J$6) -> 6.4850868 | K7: =(F7*$K$6) -> 7.205652 | M7: Solid Pine | N7: 0.9m | O7: ='Solid Pine.'!O6 -> 44.852284 | P7: =R7-(R7*10%) -> 118.50742 | Q7: =(P7-O7)/P7 -> 0.62152342 | R7: 131.67491 | S7: =(R7-O7)/R7 -> 0.65937108 | T7: =O7/(1-$T$6) -> 128.14938 | V7: =(P7*$J$6) -> 7.1104454 | W7: =(R7*$K$6) -> 7.9004949
A8: Solid Pine | B8: 1.0m | C8: ='Solid Pine.'!G7 -> 42.826837 | D8: =F8-(F8*10%) -> 112.61134 | E8: =(D8-C8)/D8 -> 0.6196934 | F8: 125.12371 | G8: =(F8-C8)/F8 -> 0.65772406 | H8: =C8/(1-$H$6) -> 122.36239 | J8: =(D8*$J$6) -> 6.7566806 | K8: =(F8*$K$6) -> 7.5074229 | M8: Solid Pine | N8: 1.0m | O8: ='Solid Pine.'!O7 -> 46.657237 | P8: =R8-(R8*10%) -> 123.03399 | Q8: =(P8-O8)/P8 -> 0.62077765 | R8: 136.70443 | S8: =(R8-O8)/R8 -> 0.65869988 | T8: =O8/(1-$T$6) -> 133.30639 | V8: =(P8*$J$6) -> 7.3820391 | W8: =(R8*$K$6) -> 8.2022657
A9: Solid Pine | B9: 1.1m | C9: ='Solid Pine.'!G8 -> 44.631791 | D9: =F9-(F9*10%) -> 118.59076 | E9: =(D9-C9)/D9 -> 0.62364868 | F9: 131.76751 | G9: =(F9-C9)/F9 -> 0.66128381 | H9: =C9/(1-$H$6) -> 127.5194 | J9: =(D9*$J$6) -> 7.1154458 | K9: =(F9*$K$6) -> 7.9060509 | M9: Solid Pine | N9: 1.1m | O9: ='Solid Pine.'!O8 -> 48.462191 | P9: =R9-(R9*10%) -> 129.01341 | Q9: =(P9-O9)/P9 -> 0.62436314 | R9: 143.34823 | S9: =(R9-O9)/R9 -> 0.66192683 | T9: =O9/(1-$T$6) -> 138.4634 | V9: =(P9*$J$6) -> 7.7408043 | W9: =(R9*$K$6) -> 8.6008937
A10: Solid Pine | B10: 1.2m | C10: ='Solid Pine.'!G9 -> 46.436744 | D10: =F10-(F10*10%) -> 125.29661 | E10: =(D10-C10)/D10 -> 0.62938548 | F10: 139.21846 | G10: =(F10-C10)/F10 -> 0.66644693 | H10: =C10/(1-$H$6) -> 132.67641 | J10: =(D10*$J$6) -> 7.5177967 | K10: =(F10*$K$6) -> 8.3531074 | M10: Solid Pine | N10: 1.2m | O10: ='Solid Pine.'!O9 -> 50.267144 | P10: =R10-(R10*10%) -> 135.71925 | Q10: =(P10-O10)/P10 -> 0.62962408 | R10: 150.79917 | S10: =(R10-O10)/R10 -> 0.66666167 | T10: =O10/(1-$T$6) -> 143.62041 | V10: =(P10*$J$6) -> 8.1431553 | W10: =(R10*$K$6) -> 9.0479503
A11: Solid Pine | B11: 1.4m | C11: ='Solid Pine.'!G10 -> 56.926113 | D11: =F11-(F11*10%) -> 137.98188 | E11: =(D11-C11)/D11 -> 0.58743776 | F11: 153.3132 | G11: =(F11-C11)/F11 -> 0.62869399 | H11: =C11/(1-$H$6) -> 162.64604 | J11: =(D11*$J$6) -> 8.2789128 | K11: =(F11*$K$6) -> 9.198792 | M11: Solid Pine | N11: 1.4m | O11: ='Solid Pine.'!O10 -> 61.888913 | P11: =R11-(R11*10%) -> 148.40452 | Q11: =(P11-O11)/P11 -> 0.58297152 | R11: 164.89391 | S11: =(R11-O11)/R11 -> 0.62467436 | T11: =O11/(1-$T$6) -> 176.82547 | V11: =(P11*$J$6) -> 8.9042714 | W11: =(R11*$K$6) -> 9.8936349
A12: Solid Pine | B12: 1.6m | C12: ='Solid Pine.'!G11 -> 62.149351 | D12: =F12-(F12*10%) -> 147.03501 | E12: =(D12-C12)/D12 -> 0.57731596 | F12: 163.37223 | G12: =(F12-C12)/F12 -> 0.61958436 | H12: =C12/(1-$H$6) -> 177.56957 | J12: =(D12*$J$6) -> 8.8221003 | K12: =(F12*$K$6) -> 9.8023337 | M12: Solid Pine | N12: 1.6m | O12: ='Solid Pine.'!O11 -> 67.112151 | P12: =R12-(R12*10%) -> 157.45765 | Q12: =(P12-O12)/P12 -> 0.5737765 | R12: 174.95294 | S12: =(R12-O12)/R12 -> 0.61639885 | T12: =O12/(1-$T$6) -> 191.749 | V12: =(P12*$J$6) -> 9.4474589 | W12: =(R12*$K$6) -> 10.497177
A13: Solid Pine | B13: 2.0m | C13: ='Solid Pine.'!G12 -> 71.305161 | D13: =F13-(F13*10%) -> 176.03769 | E13: =(D13-C13)/D13 -> 0.59494377 | F13: 195.59743 | G13: =(F13-C13)/F13 -> 0.6354494 | H13: =C13/(1-$H$6) -> 203.72903 | J13: =(D13*$J$6) -> 10.562261 | K13: =(F13*$K$6) -> 11.735846 | M13: Solid Pine | N13: 2.0m | O13: ='Solid Pine.'!O12 -> 76.267961 | P13: =R13-(R13*10%) -> 186.46033 | Q13: =(P13-O13)/P13 -> 0.5909695 | R13: 207.17814 | S13: =(R13-O13)/R13 -> 0.63187255 | T13: =O13/(1-$T$6) -> 217.90846 | V13: =(P13*$J$6) -> 11.18762 | W13: =(R13*$K$6) -> 12.430689
A15: Solid Pine Stringer (250mm x 40mm) with Solid Treads/Risers - (Over 300mm) | M15: Solid Pine Stringer (300mm x 40mm) with Solid Treads/Risers - (Over 300mm)
A16: ITEM | B16: WIDTH | C16: COST | D16: W/SALE PRICE | E16: GP% | F16: RETAIL PRICE | G16: GP% | H16: Desired GP% | J16: W/SALE FREIGHT | K16: RETAIL FREIGHT | M16: ITEM | N16: WIDTH | O16: COST | P16: W/SALE PRICE | Q16: GP% | R16: RETAIL PRICE | S16: GP% | T16: Desired GP% | V16: W/SALE FREIGHT | W16: RETAIL FREIGHT
D17: (less 10%) | H17: 0.65 | J17: 0.06 | K17: 0.06 | P17: (less 10%) | T17: 0.65 | V17: 0.06 | W17: 0.06
A18: Solid Pine | B18: 0.9m | C18: ='Solid Pine.'!G17 -> 42.842164 | D18: =F18-(F18*10%) -> 123.67805 | E18: =(D18-C18)/D18 -> 0.6535993 | F18: 137.42006 | G18: =(F18-C18)/F18 -> 0.68823937 | H18: =C18/(1-$H$17) -> 122.40618 | J18: =(D18*$J$6) -> 7.4206831 | K18: =(F18*$K$6) -> 8.2452034 | M18: Solid Pine | N18: 0.9m | O18: ='Solid Pine.'!O17 -> 46.672564 | P18: =R18-(R18*10%) -> 134.10069 | Q18: =(P18-O18)/P18 -> 0.65195882 | R18: 149.00077 | S18: =(R18-O18)/R18 -> 0.68676294 | T18: =O18/(1-$T$17) -> 133.35018 | V18: =(P18*$J$6) -> 8.0460417 | W18: =(R18*$K$6) -> 8.9400463
A19: Solid Pine | B19: 1.0m | C19: ='Solid Pine.'!G18 -> 44.849371 | D19: =F19-(F19*10%) -> 128.72649 | E19: =(D19-C19)/D19 -> 0.65159174 | F19: 143.02943 | G19: =(F19-C19)/F19 -> 0.68643257 | H19: =C19/(1-$H$17) -> 128.14106 | J19: =(D19*$J$6) -> 7.7235891 | K19: =(F19*$K$6) -> 8.5817657 | M19: Solid Pine | N19: 1.0m | O19: ='Solid Pine.'!O18 -> 48.679771 | P19: =R19-(R19*10%) -> 139.14913 | Q19: =(P19-O19)/P19 -> 0.65016115 | R19: 154.61014 | S19: =(R19-O19)/R19 -> 0.68514504 | T19: =O19/(1-$T$17) -> 139.08506 | V19: =(P19*$J$6) -> 8.3489477 | W19: =(R19*$K$6) -> 9.2766086
A20: Solid Pine | B20: 1.1m | C20: ='Solid Pine.'!G19 -> 46.856577 | D20: =F20-(F20*10%) -> 135.22778 | E20: =(D20-C20)/D20 -> 0.65349887 | F20: 150.25309 | G20: =(F20-C20)/F20 -> 0.68814899 | H20: =C20/(1-$H$17) -> 133.87593 | J20: =(D20*$J$6) -> 8.1136666 | K20: =(F20*$K$6) -> 9.0151851 | M20: Solid Pine | N20: 1.1m | O20: ='Solid Pine.'!O19 -> 50.686977 | P20: =R20-(R20*10%) -> 145.65042 | Q20: =(P20-O20)/P20 -> 0.65199567 | R20: 161.8338 | S20: =(R20-O20)/R20 -> 0.6867961 | T20: =O20/(1-$T$17) -> 144.81993 | V20: =(P20*$J$6) -> 8.7390252 | W20: =(R20*$K$6) -> 9.710028
A21: Solid Pine | B21: 1.2m | C21: ='Solid Pine.'!G20 -> 48.863784 | D21: =F21-(F21*10%) -> 142.4555 | E21: =(D21-C21)/D21 -> 0.65698913 | F21: 158.28389 | G21: =(F21-C21)/F21 -> 0.69129022 | H21: =C21/(1-$H$17) -> 139.61081 | J21: =(D21*$J$6) -> 8.5473298 | K21: =(F21*$K$6) -> 9.4970331 | M21: Solid Pine | N21: 1.2m | O21: ='Solid Pine.'!O20 -> 52.694184 | P21: =R21-(R21*10%) -> 152.87814 | Q21: =(P21-O21)/P21 -> 0.65531904 | R21: 169.8646 | S21: =(R21-O21)/R21 -> 0.68978714 | T21: =O21/(1-$T$17) -> 150.55481 | V21: =(P21*$J$6) -> 9.1726884 | W21: =(R21*$K$6) -> 10.191876
A22: Solid Pine | B22: 1.4m | C22: ='Solid Pine.'!G21 -> 59.75766 | D22: =F22-(F22*10%) -> 152.55237 | E22: =(D22-C22)/D22 -> 0.608281 | F22: 169.50263 | G22: =(F22-C22)/F22 -> 0.6474529 | H22: =C22/(1-$H$17) -> 170.73617 | J22: =(D22*$J$6) -> 9.1531419 | K22: =(F22*$K$6) -> 10.170158 | M22: Solid Pine | N22: 1.4m | O22: ='Solid Pine.'!O21 -> 64.72046 | P22: =R22-(R22*10%) -> 162.97501 | Q22: =(P22-O22)/P22 -> 0.60288108 | R22: 181.08334 | S22: =(R22-O22)/R22 -> 0.64259297 | T22: =O22/(1-$T$17) -> 184.9156 | V22: =(P22*$J$6) -> 9.7785005 | W22: =(R22*$K$6) -> 10.865001
A23: Solid Pine | B23: 1.6m | C23: ='Solid Pine.'!G22 -> 65.385404 | D23: =F23-(F23*10%) -> 166.28138 | E23: =(D23-C23)/D23 -> 0.60677855 | F23: 184.75709 | G23: =(F23-C23)/F23 -> 0.6461007 | H23: =C23/(1-$H$17) -> 186.81544 | J23: =(D23*$J$6) -> 9.9768826 | K23: =(F23*$K$6) -> 11.085425 | M23: Solid Pine | N23: 1.6m | O23: ='Solid Pine.'!O22 -> 70.348204 | P23: =R23-(R23*10%) -> 176.70402 | Q23: =(P23-O23)/P23 -> 0.60188679 | R23: 196.3378 | S23: =(R23-O23)/R23 -> 0.64169811 | T23: =O23/(1-$T$17) -> 200.99487 | V23: =(P23*$J$6) -> 10.602241 | W23: =(R23*$K$6) -> 11.780268
A24: Solid Pine | B24: 2.0m | C24: ='Solid Pine.'!G23 -> 75.350227 | D24: =F24-(F24*10%) -> 201.00369 | E24: =(D24-C24)/D24 -> 0.62513012 | F24: 223.33743 | G24: =(F24-C24)/F24 -> 0.66261711 | H24: =C24/(1-$H$17) -> 215.28636 | J24: =(D24*$J$6) -> 12.060221 | K24: =(F24*$K$6) -> 13.400246 | M24: Solid Pine | N24: 2.0m | O24: ='Solid Pine.'!O23 -> 80.313027 | P24: =R24-(R24*10%) -> 211.42633 | Q24: =(P24-O24)/P24 -> 0.62013706 | R24: 234.91814 | S24: =(R24-O24)/R24 -> 0.65812335 | T24: =O24/(1-$T$17) -> 229.46579 | V24: =(P24*$J$6) -> 12.68558 | W24: =(R24*$K$6) -> 14.095089
M27: Solid Pine Stringer (300mm x 50mm) with Solid Treads/Risers - (Up to 300mm)
M28: ITEM | N28: WIDTH | O28: COST | P28: W/SALE PRICE | Q28: GP% | R28: RETAIL PRICE | S28: GP% | T28: Desired GP% | V28: W/SALE FREIGHT | W28: RETAIL FREIGHT
P29: (less 10%) | T29: 0.65 | V29: 0.06 | W29: 0.06
M30: Solid Pine | N30: 0.9m | O30: ='Solid Pine.'!O28 -> 47.596564 | P30: =R30-(R30*10%) -> 125.31212 | Q30: =(P30-O30)/P30 -> 0.62017589 | R30: 139.23569 | S30: =(R30-O30)/R30 -> 0.6581583 | T30: =O30/(1-$T$29) -> 135.99018 | V30: =(P30*$J$6) -> 7.518727 | W30: =(R30*$K$6) -> 8.3541411
M31: Solid Pine | N31: 1.0m | O31: ='Solid Pine.'!O29 -> 49.706437 | P31: =R31-(R31*10%) -> 130.59476 | Q31: =(P31-O31)/P31 -> 0.61938413 | R31: 145.10529 | S31: =(R31-O31)/R31 -> 0.65744572 | T31: =O31/(1-$T$29) -> 142.01839 | V31: =(P31*$J$6) -> 7.8356854 | W31: =(R31*$K$6) -> 8.7063171
M32: Solid Pine | N32: 1.1m | O32: ='Solid Pine.'!O30 -> 51.816311 | P32: =R32-(R32*10%) -> 137.33025 | Q32: =(P32-O32)/P32 -> 0.62268831 | R32: 152.58917 | S32: =(R32-O32)/R32 -> 0.66041948 | T32: =O32/(1-$T$29) -> 148.0466 | V32: =(P32*$J$6) -> 8.2398153 | W32: =(R32*$K$6) -> 9.1553503
M33: Solid Pine | N33: 1.2m | O33: ='Solid Pine.'!O31 -> 53.926184 | P33: =R33-(R33*10%) -> 144.79218 | Q33: =(P33-O33)/P33 -> 0.62756149 | R33: 160.8802 | S33: =(R33-O33)/R33 -> 0.66480534 | T33: =O33/(1-$T$29) -> 154.07481 | V33: =(P33*$J$6) -> 8.6875308 | W33: =(R33*$K$6) -> 9.652812
M34: Solid Pine | N34: 1.4m | O34: ='Solid Pine.'!O32 -> 66.157793 | P34: =R34-(R34*10%) -> 158.9896 | Q34: =(P34-O34)/P34 -> 0.58388604 | R34: 176.65511 | S34: =(R34-O34)/R34 -> 0.62549744 | T34: =O34/(1-$T$29) -> 189.02227 | V34: =(P34*$J$6) -> 9.5393762 | W34: =(R34*$K$6) -> 10.599307
M35: Solid Pine | N35: 1.6m | O35: ='Solid Pine.'!O33 -> 71.990871 | P35: =R35-(R35*10%) -> 169.55488 | Q35: =(P35-O35)/P35 -> 0.57541258 | R35: 188.39431 | S35: =(R35-O35)/R35 -> 0.61787132 | T35: =O35/(1-$T$29) -> 205.6882 | V35: =(P35*$J$6) -> 10.173293 | W35: =(R35*$K$6) -> 11.303659
M36: Solid Pine | N36: 2.0m | O36: ='Solid Pine.'!O34 -> 82.366361 | P36: =R36-(R36*10%) -> 201.58187 | Q36: =(P36-O36)/P36 -> 0.59139996 | R36: 223.97986 | S36: =(R36-O36)/R36 -> 0.63225996 | T36: =O36/(1-$T$29) -> 235.33246 | V36: =(P36*$J$6) -> 12.094912 | W36: =(R36*$K$6) -> 13.438791
M38: Solid Pine Stringer (300mm x 50mm) with Solid Treads/Risers - (Over 300mm)
M39: ITEM | N39: WIDTH | O39: COST | P39: W/SALE PRICE | Q39: GP% | R39: RETAIL PRICE | S39: GP% | T39: Desired GP% | V39: W/SALE FREIGHT | W39: RETAIL FREIGHT
P40: (less 10%) | T40: 0.65 | V40: 0.06 | W40: 0.06
